Workbook

Sheet Petunjuk
A1: PETUNJUK PENGGUNAAN FILE LATIHAN AKUNTANSI
A3: Bagian | B3: Keterangan | C3: Status
A4: Soal_dan_Jurnal | B4: Berisi 50 soal baru dan area latihan jurnal. Isi kolom Akun, Debit, dan Kredit di area kanan. | C4: Siap dipakai
A5: 1. Kerjakan Soal_dan_Jurnal pada area latihan jurnal umum. | B5: Berisi kunci jurnal umum untuk 50 soal. Total debit dan kredit sudah seimbang. | C5: Terkunci konsep
A6: 2. Sheet Kunci_Jurnal adalah kunci jawaban jurnal umum dan sumber Neraca Saldo sebelum penyesuaian. | B6: Daftar akun lengkap 64 akun sesuai permintaan Anda. Nama akun diseragamkan agar rumus SUMIF tidak salah baca. | C6: Acuan utama
A7: 3. Kerjakan Jurnal_Penyesuaian pada area latihan penyesuaian akhir periode. | B7: Sheet kosong opsional. Soal nomor 34-39 sudah bertipe penyesuaian; jika ada penyesuaian tambahan, input di sini. | C7: Opsional
A8: 4. Sheet Kunci_Penyesuaian adalah kunci jawaban dan sumber perhitungan setelah penyesuaian. | B8: Merangkum mutasi debit dan kredit dari Kunci_Jurnal dan Jurnal_Penyesuaian. | C8: Otomatis
A9: 5. Buku_Besar, Neraca_Saldo, NS_Setelah_Penyesuaian, Laporan_Keuangan, Jurnal_Penutup, dan NS_Setelah_Penutupan sudah disesuaikan dengan kunci jurnal umum + kunci penyesuaian. | B9: Mengambil saldo dari Kunci_Jurnal sebelum penyesuaian tambahan. | C9: Otomatis
A10: 6. Jangan mengubah nama akun di COA agar rumus SUMIF tetap terbaca. | B10: Mengambil saldo dari Kunci_Jurnal + Jurnal_Penyesuaian. | C10: Otomatis
A11: Laporan_Keuangan | B11: Menghitung laba rugi dan neraca dari Neraca Saldo Setelah Penyesuaian. | C11: Otomatis
A12: Jurnal_Penutup | B12: Menutup pendapatan, beban, dan prive secara otomatis. | C12: Otomatis
A13: NS_Setelah_Penutupan | B13: Mengecek saldo setelah jurnal penutup. Pendapatan, beban, dan prive harus menjadi nol. | C13: Otomatis
A14: Catatan penting | B14: Jangan mengubah nama akun secara manual. Jika ingin tambah akun, tambahkan juga di COA dan sesuaikan rumus range. | C14: Penting

Sheet COA
A1: CHART OF ACCOUNTS - 64 AKUN
A3: Kode Akun | B3: Nama Akun | C3: Kategori | D3: Saldo Normal | E3: Kelompok Laporan | F3: Catatan
A4: 1-001 | B4: Kas | C4: Aset | D4: Debit | E4: Neraca - Aset | F4: Dipakai dalam kunci jurnal | H4: 50 Transaksi
A5: 1-002 | B5: Bank | C5: Aset | D5: Debit | E5: Neraca - Aset | F5: Dipakai dalam kunci jurnal | H5: ↓
A6: 1-003 | B6: Piutang Usaha | C6: Aset | D6: Debit | E6: Neraca - Aset | F6: Dipakai dalam kunci jurnal | H6: Jurnal Umum
A7: 1-004 | B7: Piutang Karyawan | C7: Aset | D7: Debit | E7: Neraca - Aset | F7: Dipakai dalam kunci jurnal | H7: (Catat)
A8: 1-005 | B8: Piutang Lain-lain | C8: Aset | D8: Debit | E8: Neraca - Aset | F8: Dipakai dalam kunci jurnal | H8: ↓
A9: 1-006 | B9: Persediaan | C9: Aset | D9: Debit | E9: Neraca - Aset | F9: Dipakai dalam kunci jurnal | H9: Buku Besar
A10: 1-007 | B10: Perlengkapan | C10: Aset | D10: Debit | E10: Neraca - Aset | F10: Dipakai dalam kunci jurnal | H10: (Kelompokkan)
A11: 1-008 | B11: Sewa Dibayar di Muka | C11: Aset | D11: Debit | E11: Neraca - Aset | F11: Dipakai dalam kunci jurnal | H11: ↓
A12: 1-009 | B12: Asuransi Dibayar di Muka | C12: Aset | D12: Debit | E12: Neraca - Aset | F12: Dipakai dalam kunci jurnal | H12: Neraca Saldo
A13: 1-010 | B13: Iklan Dibayar di Muka | C13: Aset | D13: Debit | E13: Neraca - Aset | F13: Dipakai dalam kunci jurnal | H13: (Cek saldo)
A14: 1-011 | B14: Uang Muka Pembelian | C14: Aset | D14: Debit | E14: Neraca - Aset | F14: Dipakai dalam kunci jurnal | H14: ↓
A15: 1-012 | B15: Peralatan | C15: Aset | D15: Debit | E15: Neraca - Aset | F15: Dipakai dalam kunci jurnal | H15: Penyesuaian
... A28: 2-006 | B28: Utang BPJS | C28: Liabilitas | D28: Kredit | E28: Neraca - Liabilitas | F28: Dipakai dalam kunci jurnal | H28: (Siap periode baru)
A29: 2-007 | B29: Utang Sewa | C29: Liabilitas | D29: Kredit | E29: Neraca - Liabilitas | F29: Dipakai dalam kunci jurnal
A30: 2-008 | B30: Utang Bunga | C30: Liabilitas | D30: Kredit | E30: Neraca - Liabilitas | F30: Dipakai dalam kunci jurnal
A31: 2-009 | B31: Utang Bank | C31: Liabilitas | D31: Kredit | E31: Neraca - Liabilitas | F31: Dipakai dalam kunci jurnal
A32: 2-010 | B32: Utang Jangka Pendek | C32: Liabilitas | D32: Kredit | E32: Neraca - Liabilitas | F32: Dipakai dalam kunci jurnal
A33: 2-011 | B33: Utang Jangka Panjang | C33: Liabilitas | D33: Kredit | E33: Neraca - Liabilitas | F33: Dipakai dalam kunci jurnal
A34: 2-012 | B34: Pendapatan Diterima di Muka | C34: Liabilitas | D34: Kredit | E34: Neraca - Liabilitas | F34: Dipakai dalam kunci jurnal
A35: 3-001 | B35: Modal | C35: Ekuitas | D35: Kredit | E35: Neraca - Ekuitas | F35: Dipakai dalam kunci jurnal
A36: 3-002 | B36: Modal Saham | C36: Ekuitas | D36: Kredit | E36: Neraca - Ekuitas | F36: Dipakai dalam kunci jurnal
A37: 3-003 | B37: Tambahan Modal Disetor | C37: Ekuitas | D37: Kredit | E37: Neraca - Ekuitas | F37: Dipakai dalam kunci jurnal
A38: 3-004 | B38: Laba Ditahan | C38: Ekuitas | D38: Kredit | E38: Neraca - Ekuitas | F38: Dipakai dalam kunci jurnal
A39: 3-005 | B39: Prive | C39: Prive / Kontra Ekuitas | D39: Debit | E39: Neraca - Ekuitas | F39: Dipakai dalam kunci jurnal
A40: 3-006 | B40: Saldo Laba | C40: Ekuitas | D40: Kredit | E40: Neraca - Ekuitas | F40: Dipakai dalam kunci jurnal
... A67: 5-020 | B67: Beban Lain-lain | C67: Beban | D67: Debit | E67: Laba Rugi - Beban | F67: Dipakai dalam kunci jurnal

Sheet Soal_dan_Jurnal
A1: LATIHAN 50 SOAL AKUNTANSI PEMULA, JURNAL UMUM BERFUNGSI TEMPAT MENCATAT TRANSAKSI PERTAMA KALI. | I1: JURNAL UMUM - AREA LATIHAN
A2: Bagian kiri berisi 50 soal. Bagian kanan disediakan untuk Anda isi sendiri. | I2: Isi kolom Akun, Debit, dan Kredit. Kolom Cek membandingkan jawaban dengan Kunci_Jurnal.
A3: No | B3: Tanggal | C3: Jenis Transaksi | D3: Soal | E3: Tambahan | F3: Nominal (Rp) | G3: Petunjuk | I3: No | J3: Tanggal | K3: Akun | L3: Debit (Rp) | M3: Kredit (Rp) | N3: Cek
A4: 1 | B4: 46600 | C4: Setoran modal tunai | D4: Pemilik menyetor modal awal ke kas perusahaan. | E4: 1 | F4: 80000000 | G4: Kas bertambah dan modal pemilik bertambah. | I4: 1 | J4: 46600 | K4: Kas | L4: =Tabel2[[#This Row],[Nominal (Rp)]] -> 80000000 | N4: =IF($K4="","",IF(AND($K4=Kunci_Jurnal!$C4,IF($L4="",0,$L4)=IF(Kunci_Jurnal!$D4="",0,Kunci_Jurnal!$D4),IF($M4="",0,$M4)=IF(Kunci_Jurnal!$E4="",0,Kunci_Jurnal!$E4)),"Benar","Cek lagi")) -> Benar
I5: 1 | J5: 46600 | K5: Modal | L5: =Tabel2[[#This Row],[Nominal (Rp)]] -> 0 | M5: =L4 -> 80000000 | N5: =IF($K5="","",IF(AND($K5=Kunci_Jurnal!$C5,IF($L5="",0,$L5)=IF(Kunci_Jurnal!$D5="",0,Kunci_Jurnal!$D5),IF($M5="",0,$M5)=IF(Kunci_Jurnal!$E5="",0,Kunci_Jurnal!$E5)),"Benar","Cek lagi")) -> Benar
A6: 2 | B6: 46601 | C6: Setor kas ke bank | D6: Perusahaan menyetorkan sebagian kas tunai ke rekening bank perusahaan. | E6: 2 | F6: 50000000 | G6: Bank bertambah, kas berkurang. | I6: 2 | J6: 46601 | K6: Bank | L6: =Tabel2[[#This Row],[Nominal (Rp)]] -> 50000000 | N6: =IF($K6="","",IF(AND($K6=Kunci_Jurnal!$C6,IF($L6="",0,$L6)=IF(Kunci_Jurnal!$D6="",0,Kunci_Jurnal!$D6),IF($M6="",0,$M6)=IF(Kunci_Jurnal!$E6="",0,Kunci_Jurnal!$E6)),"Benar","Cek lagi")) -> Benar
I7: 2 | J7: 46601 | K7: Kas | L7: =Tabel2[[#This Row],[Nominal (Rp)]] -> 0 | M7: =L6 -> 50000000 | N7: =IF($K7="","",IF(AND($K7=Kunci_Jurnal!$C7,IF($L7="",0,$L7)=IF(Kunci_Jurnal!$D7="",0,Kunci_Jurnal!$D7),IF($M7="",0,$M7)=IF(Kunci_Jurnal!$E7="",0,Kunci_Jurnal!$E7)),"Benar","Cek lagi")) -> Benar
A8: 3 | B8: 46602 | C8: Penerbitan modal saham | D8: Perusahaan menerbitkan saham dan menerima dana ke rekening bank. | E8: 3 | F8: 120000000 | G8: Bank bertambah, modal saham bertambah. | I8: 3 | J8: 46602 | K8: Bank | L8: =Tabel2[[#This Row],[Nominal (Rp)]] -> 120000000 | N8: =IF($K8="","",IF(AND($K8=Kunci_Jurnal!$C8,IF($L8="",0,$L8)=IF(Kunci_Jurnal!$D8="",0,Kunci_Jurnal!$D8),IF($M8="",0,$M8)=IF(Kunci_Jurnal!$E8="",0,Kunci_Jurnal!$E8)),"Benar","Cek lagi")) -> Benar
I9: 3 | J9: 46602 | K9: Modal Saham | L9: =Tabel2[[#This Row],[Nominal (Rp)]] -> 0 | M9: =L8 -> 120000000 | N9: =IF($K9="","",IF(AND($K9=Kunci_Jurnal!$C9,IF($L9="",0,$L9)=IF(Kunci_Jurnal!$D9="",0,Kunci_Jurnal!$D9),IF($M9="",0,$M9)=IF(Kunci_Jurnal!$E9="",0,Kunci_Jurnal!$E9)),"Benar","Cek lagi")) -> Benar
A10: 4 | B10: 46603 | C10: Tambahan modal disetor | D10: Pemegang saham menyetor tambahan modal di atas nilai nominal saham ke rekening bank. | E10: 4 | F10: 25000000 | G10: Bank bertambah, tambahan modal disetor bertambah. | I10: 4 | J10: 46603 | K10: Bank | L10: =Tabel2[[#This Row],[Nominal (Rp)]] -> 25000000 | N10: =IF($K10="","",IF(AND($K10=Kunci_Jurnal!$C10,IF($L10="",0,$L10)=IF(Kunci_Jurnal!$D10="",0,Kunci_Jurnal!$D10),IF($M10="",0,$M10)=IF(Kunci_Jurnal!$E10="",0,Kunci_Jurnal!$E10)),"Benar","Cek lagi")) -> Benar
I11: 4 | J11: 46603 | K11: Tambahan Modal Disetor | L11: =Tabel2[[#This Row],[Nominal (Rp)]] -> 0 | M11: =L10 -> 25000000 | N11: =IF($K11="","",IF(AND($K11=Kunci_Jurnal!$C11,IF($L11="",0,$L11)=IF(Kunci_Jurnal!$D11="",0,Kunci_Jurnal!$D11),IF($M11="",0,$M11)=IF(Kunci_Jurnal!$E11="",0,Kunci_Jurnal!$E11)),"Benar","Cek lagi")) -> Benar
A12: 5 | B12: 46604 | C12: Penetapan saldo laba | D12: Perusahaan memindahkan saldo laba periode berjalan ke laba ditahan. | E12: 5 | F12: 18000000 | G12: Saldo laba ditutup/dipindahkan ke laba ditahan. | I12: 5 | J12: 46604 | K12: Saldo Laba | L12: =Tabel2[[#This Row],[Nominal (Rp)]] -> 18000000 | N12: =IF($K12="","",IF(AND($K12=Kunci_Jurnal!$C12,IF($L12="",0,$L12)=IF(Kunci_Jurnal!$D12="",0,Kunci_Jurnal!$D12),IF($M12="",0,$M12)=IF(Kunci_Jurnal!$E12="",0,Kunci_Jurnal!$E12)),"Benar","Cek lagi")) -> Benar
I13: 5 | J13: 46604 | K13: Laba Ditahan | L13: =Tabel2[[#This Row],[Nominal (Rp)]] -> 0 | M13: =L12 -> 18000000 | N13: =IF($K13="","",IF(AND($K13=Kunci_Jurnal!$C13,IF($L13="",0,$L13)=IF(Kunci_Jurnal!$D13="",0,Kunci_Jurnal!$D13),IF($M13="",0,$M13)=IF(Kunci_Jurnal!$E13="",0,Kunci_Jurnal!$E13)),"Benar","Cek lagi")) -> Benar
A14: 6 | B14: 46605 | C14: Prive tunai | D14: Pemilik mengambil uang kas perusahaan untuk keperluan pribadi. | E14: 6 | F14: 3000000 | G14: Prive bertambah, kas berkurang. | I14: 6 | J14: 46605 | K14: Prive | L14: =Tabel2[[#This Row],[Nominal (Rp)]] -> 3000000 | N14: =IF($K14="","",IF(AND($K14=Kunci_Jurnal!$C14,IF($L14="",0,$L14)=IF(Kunci_Jurnal!$D14="",0,Kunci_Jurnal!$D14),IF($M14="",0,$M14)=IF(Kunci_Jurnal!$E14="",0,Kunci_Jurnal!$E14)),"Benar","Cek lagi")) -> Benar
I15: 6 | J15: 46605 | K15: Kas | L15: =Tabel2[[#This Row],[Nominal (Rp)]] -> 0 | M15: =L14 -> 3000000 | N15: =IF($K15="","",IF(AND($K15=Kunci_Jurnal!$C15,IF($L15="",0,$L15)=IF(Kunci_Jurnal!$D15="",0,Kunci_Jurnal!$D15),IF($M15="",0,$M15)=IF(Kunci_Jurnal!$E15="",0,Kunci_Jurnal!$E15)),"Benar","Cek lagi")) -> Benar
A16: 7 | B16: 46606 | C16: Pembelian persediaan kredit | D16: Perusahaan membeli persediaan barang dagang secara kredit dari pemasok. | E16: 7 | F16: 35000000 | G16: Persediaan bertambah, utang usaha bertambah. | I16: 7 | J16: 46606 | K16: Persediaan | L16: =Tabel2[[#This Row],[Nominal (Rp)]] -> 35000000 | N16: =IF($K16="","",IF(AND($K16=Kunci_Jurnal!$C16,IF($L16="",0,$L16)=IF(Kunci_Jurnal!$D16="",0,Kunci_Jurnal!$D16),IF($M16="",0,$M16)=IF(Kunci_Jurnal!$E16="",0,Kunci_Jurnal!$E16)),"Benar","Cek lagi")) -> Benar
I17: 7 | J17: 46606 | K17: Utang Usaha | L17: =Tabel2[[#This Row],[Nominal (Rp)]] -> 0 | M17: =L16 -> 35000000 | N17: =IF($K17="","",IF(AND($K17=Kunci_Jurnal!$C17,IF($L17="",0,$L17)=IF(Kunci_Jurnal!$D17="",0,Kunci_Jurnal!$D17),IF($M17="",0,$M17)=IF(Kunci_Jurnal!$E17="",0,Kunci_Jurnal!$E17)),"Benar","Cek lagi")) -> Benar
A18: 8 | B18: 46607 | C18: Pembelian perlengkapan tunai | D18: Perusahaan membeli perlengkapan kantor secara tunai. | E18: 8 | F18: 4500000 | G18: Perlengkapan bertambah, kas berkurang. | I18: 8 | J18: 46607 | K18: Perlengkapan | L18: =Tabel2[[#This Row],[Nominal (Rp)]] -> 4500000 | N18: =IF($K18="","",IF(AND($K18=Kunci_Jurnal!$C18,IF($L18="",0,$L18)=IF(Kunci_Jurnal!$D18="",0,Kunci_Jurnal!$D18),IF($M18="",0,$M18)=IF(Kunci_Jurnal!$E18="",0,Kunci_Jurnal!$E18)),"Benar","Cek lagi")) -> Benar
I19: 8 | J19: 46607 | K19: Kas | L19: =Tabel2[[#This Row],[Nominal (Rp)]] -> 0 | M19: =L18 -> 4500000 | N19: =IF($K19="","",IF(AND($K19=Kunci_Jurnal!$C19,IF($L19="",0,$L19)=IF(Kunci_Jurnal!$D19="",0,Kunci_Jurnal!$D19),IF($M19="",0,$M19)=IF(Kunci_Jurnal!$E19="",0,Kunci_Jurnal!$E19)),"Benar","Cek lagi")) -> Benar
A20: 9 | B20: 46608 | C20: Bayar sewa di muka | D20: Perusahaan membayar sewa kantor untuk beberapa bulan ke depan melalui bank. | E20: 9 | F20: 12000000 | G20: Sewa dibayar di muka adalah aset. | I20: 9 | J20: 46608 | K20: Sewa Dibayar di Muka | L20: =Tabel2[[#This Row],[Nominal (Rp)]] -> 12000000 | N20: =IF($K20="","",IF(AND($K20=Kunci_Jurnal!$C20,IF($L20="",0,$L20)=IF(Kunci_Jurnal!$D20="",0,Kunci_Jurnal!$D20),IF($M20="",0,$M20)=IF(Kunci_Jurnal!$E20="",0,Kunci_Jurnal!$E20)),"Benar","Cek lagi")) -> Benar
I21: 9 | J21: 46608 | K21: Bank | L21: =Tabel2[[#This Row],[Nominal (Rp)]] -> 0 | M21: =L20 -> 12000000 | N21: =IF($K21="","",IF(AND($K21=Kunci_Jurnal!$C21,IF($L21="",0,$L21)=IF(Kunci_Jurnal!$D21="",0,Kunci_Jurnal!$D21),IF($M21="",0,$M21)=IF(Kunci_Jurnal!$E21="",0,Kunci_Jurnal!$E21)),"Benar","Cek lagi")) -> Benar
A22: 10 | B22: 46609 | C22: Bayar asuransi di muka | D22: Perusahaan membayar premi asuransi tahunan melalui bank. | E22: 10 | F22: 6000000 | G22: Asuransi dibayar di muka adalah aset. | I22: 10 | J22: 46609 | K22: Asuransi Dibayar di Muka | L22: =Tabel2[[#This Row],[Nominal (Rp)]] -> 6000000 | N22: =IF($K22="","",IF(AND($K22=Kunci_Jurnal!$C22,IF($L22="",0,$L22)=IF(Kunci_Jurnal!$D22="",0,Kunci_Jurnal!$D22),IF($M22="",0,$M22)=IF(Kunci_Jurnal!$E22="",0,Kunci_Jurnal!$E22)),"Benar","Cek lagi")) -> Benar
I23: 10 | J23: 46609 | K23: Bank | L23: =Tabel2[[#This Row],[Nominal (Rp)]] -> 0 | M23: =L22 -> 6000000 | N23: =IF($K23="","",IF(AND($K23=Kunci_Jurnal!$C23,IF($L23="",0,$L23)=IF(Kunci_Jurnal!$D23="",0,Kunci_Jurnal!$D23),IF($M23="",0,$M23)=IF(Kunci_Jurnal!$E23="",0,Kunci_Jurnal!$E23)),"Benar","Cek lagi")) -> Benar
A24: 11 | B24: 46610 | C24: Bayar iklan di muka | D24: Perusahaan membayar paket iklan untuk kampanye bulan berikutnya melalui bank. | E24: 11 | F24: 7500000 | G24: Iklan dibayar di muka adalah aset. | I24: 11 | J24: 46610 | K24: Iklan Dibayar di Muka | L24: =Tabel2[[#This Row],[Nominal (Rp)]] -> 7500000 | N24: =IF($K24="","",IF(AND($K24=Kunci_Jurnal!$C24,IF($L24="",0,$L24)=IF(Kunci_Jurnal!$D24="",0,Kunci_Jurnal!$D24),IF($M24="",0,$M24)=IF(Kunci_Jurnal!$E24="",0,Kunci_Jurnal!$E24)),"Benar","Cek lagi")) -> Benar
I25: 11 | J25: 46610 | K25: Bank | L25: =Tabel2[[#This Row],[Nominal (Rp)]] -> 0 | M25: =L24 -> 7500000 | N25: =IF($K25="","",IF(AND($K25=Kunci_Jurnal!$C25,IF($L25="",0,$L25)=IF(Kunci_Jurnal!$D25="",0,Kunci_Jurnal!$D25),IF($M25="",0,$M25)=IF(Kunci_Jurnal!$E25="",0,Kunci_Jurnal!$E25)),"Benar","Cek lagi")) -> Benar
A26: 12 | B26: 46611 | C26: Uang muka pembelian | D26: Perusahaan membayar uang muka pembelian barang kepada pemasok melalui bank. | E26: 12 | F26: 10000000 | G26: Uang muka pembelian bertambah, bank berkurang. | I26: 12 | J26: 46611 | K26: Uang Muka Pembelian | L26: =Tabel2[[#This Row],[Nominal (Rp)]] -> 10000000 | N26: =IF($K26="","",IF(AND($K26=Kunci_Jurnal!$C26,IF($L26="",0,$L26)=IF(Kunci_Jurnal!$D26="",0,Kunci_Jurnal!$D26),IF($M26="",0,$M26)=IF(Kunci_Jurnal!$E26="",0,Kunci_Jurnal!$E26)),"Benar","Cek lagi")) -> Benar
I27: 12 | J27: 46611 | K27: Bank | L27: =Tabel2[[#This Row],[Nominal (Rp)]] -> 0 | M27: =L26 -> 10000000 | N27: =IF($K27="","",IF(AND($K27=Kunci_Jurnal!$C27,IF($L27="",0,$L27)=IF(Kunci_Jurnal!$D27="",0,Kunci_Jurnal!$D27),IF($M27="",0,$M27)=IF(Kunci_Jurnal!$E27="",0,Kunci_Jurnal!$E27)),"Benar","Cek lagi")) -> Benar
A28: 13 | B28: 46612 | C28: Pembelian peralatan kredit jangka pendek | D28: Perusahaan membeli peralatan operasional dengan kredit yang jatuh tempo kurang dari satu tahun. | E28: 13 | F28: 22000000 | G28: Peralatan bertambah, utang jangka pendek bertambah. | I28: 13 | J28: 46612 | K28: Peralatan | L28: =Tabel2[[#This Row],[Nominal (Rp)]] -> 22000000 | N28: =IF($K28="","",IF(AND($K28=Kunci_Jurnal!$C28,IF($L28="",0,$L28)=IF(Kunci_Jurnal!$D28="",0,Kunci_Jurnal!$D28),IF($M28="",0,$M28)=IF(Kunci_Jurnal!$E28="",0,Kunci_Jurnal!$E28)),"Benar","Cek lagi")) -> Benar
I29: 13 | J29: 46612 | K29: Utang Jangka Pendek | L29: =Tabel2[[#This Row],[Nominal (Rp)]] -> 0 | M29: =L28 -> 22000000 | N29: =IF($K29="","",IF(AND($K29=Kunci_Jurnal!$C29,IF($L29="",0,$L29)=IF(Kunci_Jurnal!$D29="",0,Kunci_Jurnal!$D29),IF($M29="",0,$M29)=IF(Kunci_Jurnal!$E29="",0,Kunci_Jurnal!$E29)),"Benar","Cek lagi")) -> Benar
A30: 14 | B30: 46613 | C30: Pembelian peralatan kantor kredit | D30: Perusahaan membeli meja dan komputer kantor secara kredit dari pemasok. | E30: 14 | F30: 15000000 | G30: Peralatan kantor bertambah, utang usaha bertambah. | I30: 14 | J30: 46613 | K30: Peralatan Kantor | L30: =Tabel2[[#This Row],[Nominal (Rp)]] -> 15000000 | N30: =IF($K30="","",IF(AND($K30=Kunci_Jurnal!$C30,IF($L30="",0,$L30)=IF(Kunci_Jurnal!$D30="",0,Kunci_Jurnal!$D30),IF($M30="",0,$M30)=IF(Kunci_Jurnal!$E30="",0,Kunci_Jurnal!$E30)),"Benar","Cek lagi")) -> Benar
I31: 14 | J31: 46613 | K31: Utang Usaha | L31: =Tabel2[[#This Row],[Nominal (Rp)]] -> 0 | M31: =L30 -> 15000000 | N31: =IF($K31="","",IF(AND($K31=Kunci_Jurnal!$C31,IF($L31="",0,$L31)=IF(Kunci_Jurnal!$D31="",0,Kunci_Jurnal!$D31),IF($M31="",0,$M31)=IF(Kunci_Jurnal!$E31="",0,Kunci_Jurnal!$E31)),"Benar","Cek lagi")) -> Benar
A32: 15 | B32: 46614 | C32: Pembelian kendaraan dengan pinjaman bank | D32: Perusahaan membeli kendaraan operasional menggunakan fasilitas pinjaman bank. | E32: 15 | F32: 180000000 | G32: Kendaraan bertambah, utang bank bertambah. | I32: 15 | J32: 46614 | K32: Kendaraan | L32: =Tabel2[[#This Row],[Nominal (Rp)]] -> 180000000 | N32: =IF($K32="","",IF(AND($K32=Kunci_Jurnal!$C32,IF($L32="",0,$L32)=IF(Kunci_Jurnal!$D32="",0,Kunci_Jurnal!$D32),IF($M32="",0,$M32)=IF(Kunci_Jurnal!$E32="",0,Kunci_Jurnal!$E32)),"Benar","Cek lagi")) -> Benar
I33: 15 | J33: 46614 | K33: Utang Bank | L33: =Tabel2[[#This Row],[Nominal (Rp)]] -> 0 | M33: =L32 -> 180000000 | N33: =IF($K33="","",IF(AND($K33=Kunci_Jurnal!$C33,IF($L33="",0,$L33)=IF(Kunci_Jurnal!$D33="",0,Kunci_Jurnal!$D33),IF($M33="",0,$M33)=IF(Kunci_Jurnal!$E33="",0,Kunci_Jurnal!$E33)),"Benar","Cek lagi")) -> Benar
A34: 16 | B34: 46615 | C34: Pembelian gedung kredit jangka panjang | D34: Perusahaan membeli gedung kantor dengan pembiayaan jangka panjang. | E34: 16 | F34: 350000000 | G34: Gedung bertambah, utang jangka panjang bertambah. | I34: 16 | J34: 46615 | K34: Gedung | L34: =Tabel2[[#This Row],[Nominal (Rp)]] -> 350000000 | N34: =IF($K34="","",IF(AND($K34=Kunci_Jurnal!$C34,IF($L34="",0,$L34)=IF(Kunci_Jurnal!$D34="",0,Kunci_Jurnal!$D34),IF($M34="",0,$M34)=IF(Kunci_Jurnal!$E34="",0,Kunci_Jurnal!$E34)),"Benar","Cek lagi")) -> Benar
I35: 16 | J35: 46615 | K35: Utang Jangka Panjang | L35: =Tabel2[[#This Row],[Nominal (Rp)]] -> 0 | M35: =L34 -> 350000000 | N35: =IF($K35="","",IF(AND($K35=Kunci_Jurnal!$C35,IF($L35="",0,$L35)=IF(Kunci_Jurnal!$D35="",0,Kunci_Jurnal!$D35),IF($M35="",0,$M35)=IF(Kunci_Jurnal!$E35="",0,Kunci_Jurnal!$E35)),"Benar","Cek lagi")) -> Benar
A36: 17 | B36: 46616 | C36: Pembelian tanah dengan pinjaman bank | D36: Perusahaan membeli tanah untuk lokasi usaha menggunakan fasilitas pinjaman bank. | E36: 17 | F36: 220000000 | G36: Tanah bertambah, utang bank bertambah. | I36: 17 | J36: 46616 | K36: Tanah | L36: =Tabel2[[#This Row],[Nominal (Rp)]] -> 220000000 | N36: =IF($K36="","",IF(AND($K36=Kunci_Jurnal!$C36,IF($L36="",0,$L36)=IF(Kunci_Jurnal!$D36="",0,Kunci_Jurnal!$D36),IF($M36="",0,$M36)=IF(Kunci_Jurnal!$E36="",0,Kunci_Jurnal!$E36)),"Benar","Cek lagi")) -> Benar
I37: 17 | J37: 46616 | K37: Utang Bank | L37: =Tabel2[[#This Row],[Nominal (Rp)]] -> 0 | M37: =L36 -> 220000000 | N37: =IF($K37="","",IF(AND($K37=Kunci_Jurnal!$C37,IF($L37="",0,$L37)=IF(Kunci_Jurnal!$D37="",0,Kunci_Jurnal!$D37),IF($M37="",0,$M37)=IF(Kunci_Jurnal!$E37="",0,Kunci_Jurnal!$E37)),"Benar","Cek lagi")) -> Benar
A38: 18 | B38: 46617 | C38: Pendapatan jasa tunai | D38: Perusahaan menerima pendapatan jasa konsultasi secara tunai. | E38: 18 | F38: 14000000 | G38: Kas bertambah, pendapatan jasa bertambah. | I38: 18 | J38: 46617 | K38: Kas | L38: =Tabel2[[#This Row],[Nominal (Rp)]] -> 14000000 | N38: =IF($K38="","",IF(AND($K38=Kunci_Jurnal!$C38,IF($L38="",0,$L38)=IF(Kunci_Jurnal!$D38="",0,Kunci_Jurnal!$D38),IF($M38="",0,$M38)=IF(Kunci_Jurnal!$E38="",0,Kunci_Jurnal!$E38)),"Benar","Cek lagi")) -> Benar
I39: 18 | J39: 46617 | K39: Pendapatan Jasa | L39: =Tabel2[[#This Row],[Nominal (Rp)]] -> 0 | M39: =L38 -> 14000000 | N39: =IF($K39="","",IF(AND($K39=Kunci_Jurnal!$C39,IF($L39="",0,$L39)=IF(Kunci_Jurnal!$D39="",0,Kunci_Jurnal!$D39),IF($M39="",0,$M39)=IF(Kunci_Jurnal!$E39="",0,Kunci_Jurnal!$E39)),"Benar","Cek lagi")) -> Benar
A40: 19 | B40: 46618 | C40: Penjualan barang kredit | D40: Perusahaan menjual barang dagang secara kredit kepada pelanggan. | E40: 19 | F40: 28000000 | G40: Piutang usaha bertambah, pendapatan penjualan bertambah. | I40: 19 | J40: 46618 | K40: Piutang Usaha | L40: =Tabel2[[#This Row],[Nominal (Rp)]] -> 28000000 | N40: =IF($K40="","",IF(AND($K40=Kunci_Jurnal!$C40,IF($L40="",0,$L40)=IF(Kunci_Jurnal!$D40="",0,Kunci_Jurnal!$D40),IF($M40="",0,$M40)=IF(Kunci_Jurnal!$E40="",0,Kunci_Jurnal!$E40)),"Benar","Cek lagi")) -> Benar
...

Sheet Kunci_Jurnal
A1: KUNCI JURNAL UMUM - 50 SOAL / 100 BARIS, JURNAL UMUM BERFUNGSI TEMPAT MENCATAT TRANSAKSI PERTAMA KALI.
A2: Sheet ini adalah sumber utama untuk menghitung Buku Besar, Neraca Saldo, dan laporan. Jangan ubah nama akun sembarangan.
A3: No | B3: Tanggal | C3: Akun | D3: Debit (Rp) | E3: Kredit (Rp) | F3: Alasan | H3: Daftar Akun
A4: 1 | B4: 46600 | C4: Kas | D4: 80000000 | F4: Kas bertambah karena menerima setoran modal. | H4: Kas
A5: 1 | B5: 46600 | C5: Modal | E5: 80000000 | F5: Modal pemilik bertambah. | H5: Bank
A6: 2 | B6: 46601 | C6: Bank | D6: 50000000 | F6: Saldo bank bertambah. | H6: Piutang Usaha
A7: 2 | B7: 46601 | C7: Kas | E7: 50000000 | F7: Kas tunai berkurang karena disetor ke bank. | H7: Piutang Karyawan
A8: 3 | B8: 46602 | C8: Bank | D8: 120000000 | F8: Dana hasil penerbitan saham masuk ke bank. | H8: Piutang Lain-lain
A9: 3 | B9: 46602 | C9: Modal Saham | E9: 120000000 | F9: Modal saham bertambah. | H9: Persediaan
A10: 4 | B10: 46603 | C10: Bank | D10: 25000000 | F10: Dana tambahan disetor masuk ke bank. | H10: Perlengkapan
A11: 4 | B11: 46603 | C11: Tambahan Modal Disetor | E11: 25000000 | F11: Tambahan modal disetor bertambah. | H11: Sewa Dibayar di Muka
A12: 5 | B12: 46604 | C12: Saldo Laba | D12: 18000000 | F12: Saldo laba dikurangi karena dipindahkan. | H12: Asuransi Dibayar di Muka
A13: 5 | B13: 46604 | C13: Laba Ditahan | E13: 18000000 | F13: Laba ditahan bertambah. | H13: Iklan Dibayar di Muka
A14: 6 | B14: 46605 | C14: Prive | D14: 3000000 | F14: Pengambilan pribadi dicatat sebagai prive. | H14: Uang Muka Pembelian
A15: 6 | B15: 46605 | C15: Kas | E15: 3000000 | F15: Kas berkurang karena diambil pemilik. | H15: Peralatan
A16: 7 | B16: 46606 | C16: Persediaan | D16: 35000000 | F16: Persediaan bertambah. | H16: Peralatan Kantor
A17: 7 | B17: 46606 | C17: Utang Usaha | E17: 35000000 | F17: Utang usaha bertambah karena pembelian kredit. | H17: Kendaraan
A18: 8 | B18: 46607 | C18: Perlengkapan | D18: 4500000 | F18: Perlengkapan bertambah. | H18: Gedung
A19: 8 | B19: 46607 | C19: Kas | E19: 4500000 | F19: Kas berkurang karena pembayaran tunai. | H19: Tanah
A20: 9 | B20: 46608 | C20: Sewa Dibayar di Muka | D20: 12000000 | F20: Manfaat sewa untuk periode berikutnya dicatat sebagai aset. | H20: Akumulasi Penyusutan Peralatan
A21: 9 | B21: 46608 | C21: Bank | E21: 12000000 | F21: Bank berkurang karena pembayaran sewa. | H21: Akumulasi Penyusutan Kendaraan
A22: 10 | B22: 46609 | C22: Asuransi Dibayar di Muka | D22: 6000000 | F22: Premi asuransi yang manfaatnya belum habis dicatat sebagai aset. | H22: Akumulasi Penyusutan Gedung
A23: 10 | B23: 46609 | C23: Bank | E23: 6000000 | F23: Bank berkurang karena pembayaran premi. | H23: Utang Usaha
A24: 11 | B24: 46610 | C24: Iklan Dibayar di Muka | D24: 7500000 | F24: Biaya iklan yang belum menjadi beban dicatat sebagai aset. | H24: Utang Gaji
A25: 11 | B25: 46610 | C25: Bank | E25: 7500000 | F25: Bank berkurang karena pembayaran iklan. | H25: Utang Pajak
A26: 12 | B26: 46611 | C26: Uang Muka Pembelian | D26: 10000000 | F26: Uang muka kepada pemasok dicatat sebagai aset. | H26: Utang PPh 21
A27: 12 | B27: 46611 | C27: Bank | E27: 10000000 | F27: Bank berkurang karena membayar uang muka. | H27: Utang PPN
A28: 13 | B28: 46612 | C28: Peralatan | D28: 22000000 | F28: Peralatan bertambah. | H28: Utang BPJS
A29: 13 | B29: 46612 | C29: Utang Jangka Pendek | E29: 22000000 | F29: Kewajiban jangka pendek bertambah. | H29: Utang Sewa
A30: 14 | B30: 46613 | C30: Peralatan Kantor | D30: 15000000 | F30: Peralatan kantor bertambah. | H30: Utang Bunga
A31: 14 | B31: 46613 | C31: Utang Usaha | E31: 15000000 | F31: Utang usaha bertambah karena pembelian kredit. | H31: Utang Bank
A32: 15 | B32: 46614 | C32: Kendaraan | D32: 180000000 | F32: Kendaraan operasional bertambah. | H32: Utang Jangka Pendek
A33: 15 | B33: 46614 | C33: Utang Bank | E33: 180000000 | F33: Utang kepada bank bertambah. | H33: Utang Jangka Panjang
A34: 16 | B34: 46615 | C34: Gedung | D34: 350000000 | F34: Gedung bertambah sebagai aset tetap. | H34: Pendapatan Diterima di Muka
A35: 16 | B35: 46615 | C35: Utang Jangka Panjang | E35: 350000000 | F35: Kewajiban jangka panjang bertambah. | H35: Modal
A36: 17 | B36: 46616 | C36: Tanah | D36: 220000000 | F36: Tanah bertambah sebagai aset perusahaan. | H36: Modal Saham
A37: 17 | B37: 46616 | C37: Utang Bank | E37: 220000000 | F37: Utang bank bertambah karena pembelian tanah dibiayai pinjaman bank. | H37: Tambahan Modal Disetor
A38: 18 | B38: 46617 | C38: Kas | D38: 14000000 | F38: Kas bertambah karena menerima pembayaran jasa. | H38: Laba Ditahan
A39: 18 | B39: 46617 | C39: Pendapatan Jasa | E39: 14000000 | F39: Pendapatan jasa bertambah. | H39: Prive
A40: 19 | B40: 46618 | C40: Piutang Usaha | D40: 28000000 | F40: Piutang usaha bertambah karena penjualan kredit. | H40: Saldo Laba
...

Sheet Buku_Besar
A1: BUKU BESAR RINGKAS - OTOMATIS, FUNGSI BUKU BESAR MENGELOMPOKKAN TRANSAKSI BERDASARKAN AKUN.
E2: ambil dari JU, total debit kredit | G2: Ambil Dari Penyesuaian | I2: 8 | J2: 9 | K2: Ambil Dari Jurnal Penutup | M2: 12 | N2: 13
A3: Kode Akun | B3: Nama Akun | C3: Kategori | D3: Saldo Normal | E3: Debit JU | F3: Kredit JU | G3: Debit Penyesuaian | H3: Kredit Penyesuaian | I3: Saldo Debit | J3: Saldo Kredit | K3: Debit Penutup | L3: Kredit Penutup | M3: Saldo Debit Akhir | N3: Saldo Kredit Akhir
A4: 1-001 | B4: Kas | C4: Aset | D4: Debit | E4: =SUMIF(jurnal[Akun],buku_besar[[#This Row],[Nama Akun]],jurnal[Debit (Rp)]) -> 103250000 | F4: =SUMIF(jurnal[Akun],buku_besar[[#This Row],[Nama Akun]],jurnal[Kredit (Rp)]) -> 68100000 | G4: =SUMIF(jurnal_penyesuaian[Akun],buku_besar[[#This Row],[Nama Akun]],jurnal_penyesuaian[Debit (Rp)]) -> 0 | H4: =SUMIF(jurnal_penyesuaian[Akun],buku_besar[[#This Row],[Nama Akun]],jurnal_penyesuaian[Kredit (Rp)]) -> 0 | I4: =MAX(0,(buku_besar[[#This Row],[Debit JU]]+buku_besar[[#This Row],[Debit Penyesuaian]]-buku_besar[[#This Row],[Kredit JU]]-buku_besar[[#This Row],[Kredit Penyesuaian]])) -> 35150000 | J4: =MAX(0,(buku_besar[[#This Row],[Kredit JU]]+buku_besar[[#This Row],[Kredit Penyesuaian]]-buku_besar[[#This Row],[Debit JU]]-buku_besar[[#This Row],[Debit Penyesuaian]])) -> 0 | K4: =MAX(0,(SUMIF(jurnal_penutup[Akun],buku_besar[[#This Row],[Nama Akun]],jurnal_penutup[Debit (Rp)]))) -> 0 | L4: =MAX(0,(SUMIF(jurnal_penutup[Akun],buku_besar[[#This Row],[Nama Akun]],jurnal_penutup[Kredit (Rp)]))) -> 0 | M4: =MAX(0,(buku_besar[[#This Row],[Debit JU]]+buku_besar[[#This Row],[Debit Penyesuaian]]+buku_besar[[#This Row],[Debit Penutup]])-(buku_besar[[#This Row],[Kredit JU]]+buku_besar[[#This Row],[Kredit Penyesuaian]]+buku_besar[[#This Row],[Kredit Penutup]])) -> 35150000 | N4: =MAX(0,(buku_besar[[#This Row],[Kredit JU]]+buku_besar[[#This Row],[Kredit Penyesuaian]]+buku_besar[[#This Row],[Kredit Penutup]])-(buku_besar[[#This Row],[Debit JU]]+buku_besar[[#This Row],[Debit Penyesuaian]]+buku_besar[[#This Row],[Debit Penutup]])) -> 0
A5: 1-002 | B5: Bank | C5: Aset | D5: Debit | E5: =SUMIF(jurnal[Akun],buku_besar[[#This Row],[Nama Akun]],jurnal[Debit (Rp)]) -> 231200000 | F5: =SUMIF(jurnal[Akun],buku_besar[[#This Row],[Nama Akun]],jurnal[Kredit (Rp)]) -> 55350000 | G5: =SUMIF(jurnal_penyesuaian[Akun],buku_besar[[#This Row],[Nama Akun]],jurnal_penyesuaian[Debit (Rp)]) -> 0 | H5: =SUMIF(jurnal_penyesuaian[Akun],buku_besar[[#This Row],[Nama Akun]],jurnal_penyesuaian[Kredit (Rp)]) -> 0 | I5: =MAX(0,(buku_besar[[#This Row],[Debit JU]]+buku_besar[[#This Row],[Debit Penyesuaian]]-buku_besar[[#This Row],[Kredit JU]]-buku_besar[[#This Row],[Kredit Penyesuaian]])) -> 175850000 | J5: =MAX(0,(buku_besar[[#This Row],[Kredit JU]]+buku_besar[[#This Row],[Kredit Penyesuaian]]-buku_besar[[#This Row],[Debit JU]]-buku_besar[[#This Row],[Debit Penyesuaian]])) -> 0 | K5: =MAX(0,(SUMIF(jurnal_penutup[Akun],buku_besar[[#This Row],[Nama Akun]],jurnal_penutup[Debit (Rp)]))) -> 0 | L5: =MAX(0,(SUMIF(jurnal_penutup[Akun],buku_besar[[#This Row],[Nama Akun]],jurnal_penutup[Kredit (Rp)]))) -> 0 | M5: =MAX(0,(buku_besar[[#This Row],[Debit JU]]+buku_besar[[#This Row],[Debit Penyesuaian]]+buku_besar[[#This Row],[Debit Penutup]])-(buku_besar[[#This Row],[Kredit JU]]+buku_besar[[#This Row],[Kredit Penyesuaian]]+buku_besar[[#This Row],[Kredit Penutup]])) -> 175850000 | N5: =MAX(0,(buku_besar[[#This Row],[Kredit JU]]+buku_besar[[#This Row],[Kredit Penyesuaian]]+buku_besar[[#This Row],[Kredit Penutup]])-(buku_besar[[#This Row],[Debit JU]]+buku_besar[[#This Row],[Debit Penyesuaian]]+buku_besar[[#This Row],[Debit Penutup]])) -> 0
A6: 1-003 | B6: Piutang Usaha | C6: Aset | D6: Debit | E6: =SUMIF(jurnal[Akun],buku_besar[[#This Row],[Nama Akun]],jurnal[Debit (Rp)]) -> 31080000 | F6: =SUMIF(jurnal[Akun],buku_besar[[#This Row],[Nama Akun]],jurnal[Kredit (Rp)]) -> 8000000 | G6: =SUMIF(jurnal_penyesuaian[Akun],buku_besar[[#This Row],[Nama Akun]],jurnal_penyesuaian[Debit (Rp)]) -> 0 | H6: =SUMIF(jurnal_penyesuaian[Akun],buku_besar[[#This Row],[Nama Akun]],jurnal_penyesuaian[Kredit (Rp)]) -> 0 | I6: =MAX(0,(buku_besar[[#This Row],[Debit JU]]+buku_besar[[#This Row],[Debit Penyesuaian]]-buku_besar[[#This Row],[Kredit JU]]-buku_besar[[#This Row],[Kredit Penyesuaian]])) -> 23080000 | J6: =MAX(0,(buku_besar[[#This Row],[Kredit JU]]+buku_besar[[#This Row],[Kredit Penyesuaian]]-buku_besar[[#This Row],[Debit JU]]-buku_besar[[#This Row],[Debit Penyesuaian]])) -> 0 | K6: =MAX(0,(SUMIF(jurnal_penutup[Akun],buku_besar[[#This Row],[Nama Akun]],jurnal_penutup[Debit (Rp)]))) -> 0 | L6: =MAX(0,(SUMIF(jurnal_penutup[Akun],buku_besar[[#This Row],[Nama Akun]],jurnal_penutup[Kredit (Rp)]))) -> 0 | M6: =MAX(0,(buku_besar[[#This Row],[Debit JU]]+buku_besar[[#This Row],[Debit Penyesuaian]]+buku_besar[[#This Row],[Debit Penutup]])-(buku_besar[[#This Row],[Kredit JU]]+buku_besar[[#This Row],[Kredit Penyesuaian]]+buku_besar[[#This Row],[Kredit Penutup]])) -> 23080000 | N6: =MAX(0,(buku_besar[[#This Row],[Kredit JU]]+buku_besar[[#This Row],[Kredit Penyesuaian]]+buku_besar[[#This Row],[Kredit Penutup]])-(buku_besar[[#This Row],[Debit JU]]+buku_besar[[#This Row],[Debit Penyesuaian]]+buku_besar[[#This Row],[Debit Penutup]])) -> 0
A7: 1-004 | B7: Piutang Karyawan | C7: Aset | D7: Debit | E7: =SUMIF(jurnal[Akun],buku_besar[[#This Row],[Nama Akun]],jurnal[Debit (Rp)]) -> 2500000 | F7: =SUMIF(jurnal[Akun],buku_besar[[#This Row],[Nama Akun]],jurnal[Kredit (Rp)]) -> 0 | G7: =SUMIF(jurnal_penyesuaian[Akun],buku_besar[[#This Row],[Nama Akun]],jurnal_penyesuaian[Debit (Rp)]) -> 0 | H7: =SUMIF(jurnal_penyesuaian[Akun],buku_besar[[#This Row],[Nama Akun]],jurnal_penyesuaian[Kredit (Rp)]) -> 0 | I7: =MAX(0,(buku_besar[[#This Row],[Debit JU]]+buku_besar[[#This Row],[Debit Penyesuaian]]-buku_besar[[#This Row],[Kredit JU]]-buku_besar[[#This Row],[Kredit Penyesuaian]])) -> 2500000 | J7: =MAX(0,(buku_besar[[#This Row],[Kredit JU]]+buku_besar[[#This Row],[Kredit Penyesuaian]]-buku_besar[[#This Row],[Debit JU]]-buku_besar[[#This Row],[Debit Penyesuaian]])) -> 0 | K7: =MAX(0,(SUMIF(jurnal_penutup[Akun],buku_besar[[#This Row],[Nama Akun]],jurnal_penutup[Debit (Rp)]))) -> 0 | L7: =MAX(0,(SUMIF(jurnal_penutup[Akun],buku_besar[[#This Row],[Nama Akun]],jurnal_penutup[Kredit (Rp)]))) -> 0 | M7: =MAX(0,(buku_besar[[#This Row],[Debit JU]]+buku_besar[[#This Row],[Debit Penyesuaian]]+buku_besar[[#This Row],[Debit Penutup]])-(buku_besar[[#This Row],[Kredit JU]]+buku_besar[[#This Row],[Kredit Penyesuaian]]+buku_besar[[#This Row],[Kredit Penutup]])) -> 2500000 | N7: =MAX(0,(buku_besar[[#This Row],[Kredit JU]]+buku_besar[[#This Row],[Kredit Penyesuaian]]+buku_besar[[#This Row],[Kredit Penutup]])-(buku_besar[[#This Row],[Debit JU]]+buku_besar[[#This Row],[Debit Penyesuaian]]+buku_besar[[#This Row],[Debit Penutup]])) -> 0
A8: 1-005 | B8: Piutang Lain-lain | C8: Aset | D8: Debit | E8: =SUMIF(jurnal[Akun],buku_besar[[#This Row],[Nama Akun]],jurnal[Debit (Rp)]) -> 3400000 | F8: =SUMIF(jurnal[Akun],buku_besar[[#This Row],[Nama Akun]],jurnal[Kredit (Rp)]) -> 1000000 | G8: =SUMIF(jurnal_penyesuaian[Akun],buku_besar[[#This Row],[Nama Akun]],jurnal_penyesuaian[Debit (Rp)]) -> 0 | H8: =SUMIF(jurnal_penyesuaian[Akun],buku_besar[[#This Row],[Nama Akun]],jurnal_penyesuaian[Kredit (Rp)]) -> 0 | I8: =MAX(0,(buku_besar[[#This Row],[Debit JU]]+buku_besar[[#This Row],[Debit Penyesuaian]]-buku_besar[[#This Row],[Kredit JU]]-buku_besar[[#This Row],[Kredit Penyesuaian]])) -> 2400000 | J8: =MAX(0,(buku_besar[[#This Row],[Kredit JU]]+buku_besar[[#This Row],[Kredit Penyesuaian]]-buku_besar[[#This Row],[Debit JU]]-buku_besar[[#This Row],[Debit Penyesuaian]])) -> 0 | K8: =MAX(0,(SUMIF(jurnal_penutup[Akun],buku_besar[[#This Row],[Nama Akun]],jurnal_penutup[Debit (Rp)]))) -> 0 | L8: =MAX(0,(SUMIF(jurnal_penutup[Akun],buku_besar[[#This Row],[Nama Akun]],jurnal_penutup[Kredit (Rp)]))) -> 0 | M8: =MAX(0,(buku_besar[[#This Row],[Debit JU]]+buku_besar[[#This Row],[Debit Penyesuaian]]+buku_besar[[#This Row],[Debit Penutup]])-(buku_besar[[#This Row],[Kredit JU]]+buku_besar[[#This Row],[Kredit Penyesuaian]]+buku_besar[[#This Row],[Kredit Penutup]])) -> 2400000 | N8: =MAX(0,(buku_besar[[#This Row],[Kredit JU]]+buku_besar[[#This Row],[Kredit Penyesuaian]]+buku_besar[[#This Row],[Kredit Penutup]])-(buku_besar[[#This Row],[Debit JU]]+buku_besar[[#This Row],[Debit Penyesuaian]]+buku_besar[[#This Row],[Debit Penutup]])) -> 0
A9: 1-006 | B9: Persediaan | C9: Aset | D9: Debit | E9: =SUMIF(jurnal[Akun],buku_besar[[#This Row],[Nama Akun]],jurnal[Debit (Rp)]) -> 35000000 | F9: =SUMIF(jurnal[Akun],buku_besar[[#This Row],[Nama Akun]],jurnal[Kredit (Rp)]) -> 0 | G9: =SUMIF(jurnal_penyesuaian[Akun],buku_besar[[#This Row],[Nama Akun]],jurnal_penyesuaian[Debit (Rp)]) -> 0 | H9: =SUMIF(jurnal_penyesuaian[Akun],buku_besar[[#This Row],[Nama Akun]],jurnal_penyesuaian[Kredit (Rp)]) -> 0 | I9: =MAX(0,(buku_besar[[#This Row],[Debit JU]]+buku_besar[[#This Row],[Debit Penyesuaian]]-buku_besar[[#This Row],[Kredit JU]]-buku_besar[[#This Row],[Kredit Penyesuaian]])) -> 35000000 | J9: =MAX(0,(buku_besar[[#This Row],[Kredit JU]]+buku_besar[[#This Row],[Kredit Penyesuaian]]-buku_besar[[#This Row],[Debit JU]]-buku_besar[[#This Row],[Debit Penyesuaian]])) -> 0 | K9: =MAX(0,(SUMIF(jurnal_penutup[Akun],buku_besar[[#This Row],[Nama Akun]],jurnal_penutup[Debit (Rp)]))) -> 0 | L9: =MAX(0,(SUMIF(jurnal_penutup[Akun],buku_besar[[#This Row],[Nama Akun]],jurnal_penutup[Kredit (Rp)]))) -> 0 | M9: =MAX(0,(buku_besar[[#This Row],[Debit JU]]+buku_besar[[#This Row],[Debit Penyesuaian]]+buku_besar[[#This Row],[Debit Penutup]])-(buku_besar[[#This Row],[Kredit JU]]+buku_besar[[#This Row],[Kredit Penyesuaian]]+buku_besar[[#This Row],[Kredit Penutup]])) -> 35000000 | N9: =MAX(0,(buku_besar[[#This Row],[Kredit JU]]+buku_besar[[#This Row],[Kredit Penyesuaian]]+buku_besar[[#This Row],[Kredit Penutup]])-(buku_besar[[#This Row],[Debit JU]]+buku_besar[[#This Row],[Debit Penyesuaian]]+buku_besar[[#This Row],[Debit Penutup]])) -> 0
A10: 1-007 | B10: Perlengkapan | C10: Aset | D10: Debit | E10: =SUMIF(jurnal[Akun],buku_besar[[#This Row],[Nama Akun]],jurnal[Debit (Rp)]) -> 4500000 | F10: =SUMIF(jurnal[Akun],buku_besar[[#This Row],[Nama Akun]],jurnal[Kredit (Rp)]) -> 0 | G10: =SUMIF(jurnal_penyesuaian[Akun],buku_besar[[#This Row],[Nama Akun]],jurnal_penyesuaian[Debit (Rp)]) -> 0 | H10: =SUMIF(jurnal_penyesuaian[Akun],buku_besar[[#This Row],[Nama Akun]],jurnal_penyesuaian[Kredit (Rp)]) -> 2000000 | I10: =MAX(0,(buku_besar[[#This Row],[Debit JU]]+buku_besar[[#This Row],[Debit Penyesuaian]]-buku_besar[[#This Row],[Kredit JU]]-buku_besar[[#This Row],[Kredit Penyesuaian]])) -> 2500000 | J10: =MAX(0,(buku_besar[[#This Row],[Kredit JU]]+buku_besar[[#This Row],[Kredit Penyesuaian]]-buku_besar[[#This Row],[Debit JU]]-buku_besar[[#This Row],[Debit Penyesuaian]])) -> 0 | K10: =MAX(0,(SUMIF(jurnal_penutup[Akun],buku_besar[[#This Row],[Nama Akun]],jurnal_penutup[Debit (Rp)]))) -> 0 | L10: =MAX(0,(SUMIF(jurnal_penutup[Akun],buku_besar[[#This Row],[Nama Akun]],jurnal_penutup[Kredit (Rp)]))) -> 0 | M10: =MAX(0,(buku_besar[[#This Row],[Debit JU]]+buku_besar[[#This Row],[Debit Penyesuaian]]+buku_besar[[#This Row],[Debit Penutup]])-(buku_besar[[#This Row],[Kredit JU]]+buku_besar[[#This Row],[Kredit Penyesuaian]]+buku_besar[[#This Row],[Kredit Penutup]])) -> 2500000 | N10: =MAX(0,(buku_besar[[#This Row],[Kredit JU]]+buku_besar[[#This Row],[Kredit Penyesuaian]]+buku_besar[[#This Row],[Kredit Penutup]])-(buku_besar[[#This Row],[Debit JU]]+buku_besar[[#This Row],[Debit Penyesuaian]]+buku_besar[[#This Row],[Debit Penutup]])) -> 0
A11: 1-008 | B11: Sewa Dibayar di Muka | C11: Aset | D11: Debit | E11: =SUMIF(jurnal[Akun],buku_besar[[#This Row],[Nama Akun]],jurnal[Debit (Rp)]) -> 12000000 | F11: =SUMIF(jurnal[Akun],buku_besar[[#This Row],[Nama Akun]],jurnal[Kredit (Rp)]) -> 0 | G11: =SUMIF(jurnal_penyesuaian[Akun],buku_besar[[#This Row],[Nama Akun]],jurnal_penyesuaian[Debit (Rp)]) -> 0 | H11: =SUMIF(jurnal_penyesuaian[Akun],buku_besar[[#This Row],[Nama Akun]],jurnal_penyesuaian[Kredit (Rp)]) -> 4000000 | I11: =MAX(0,(buku_besar[[#This Row],[Debit JU]]+buku_besar[[#This Row],[Debit Penyesuaian]]-buku_besar[[#This Row],[Kredit JU]]-buku_besar[[#This Row],[Kredit Penyesuaian]])) -> 8000000 | J11: =MAX(0,(buku_besar[[#This Row],[Kredit JU]]+buku_besar[[#This Row],[Kredit Penyesuaian]]-buku_besar[[#This Row],[Debit JU]]-buku_besar[[#This Row],[Debit Penyesuaian]])) -> 0 | K11: =MAX(0,(SUMIF(jurnal_penutup[Akun],buku_besar[[#This Row],[Nama Akun]],jurnal_penutup[Debit (Rp)]))) -> 0 | L11: =MAX(0,(SUMIF(jurnal_penutup[Akun],buku_besar[[#This Row],[Nama Akun]],jurnal_penutup[Kredit (Rp)]))) -> 0 | M11: =MAX(0,(buku_besar[[#This Row],[Debit JU]]+buku_besar[[#This Row],[Debit Penyesuaian]]+buku_besar[[#This Row],[Debit Penutup]])-(buku_besar[[#This Row],[Kredit JU]]+buku_besar[[#This Row],[Kredit Penyesuaian]]+buku_besar[[#This Row],[Kredit Penutup]])) -> 8000000 | N11: =MAX(0,(buku_besar[[#This Row],[Kredit JU]]+buku_besar[[#This Row],[Kredit Penyesuaian]]+buku_besar[[#This Row],[Kredit Penutup]])-(buku_besar[[#This Row],[Debit JU]]+buku_besar[[#This Row],[Debit Penyesuaian]]+buku_besar[[#This Row],[Debit Penutup]])) -> 0
A12: 1-009 | B12: Asuransi Dibayar di Muka | C12: Aset | D12: Debit | E12: =SUMIF(jurnal[Akun],buku_besar[[#This Row],[Nama Akun]],jurnal[Debit (Rp)]) -> 6000000 | F12: =SUMIF(jurnal[Akun],buku_besar[[#This Row],[Nama Akun]],jurnal[Kredit (Rp)]) -> 0 | G12: =SUMIF(jurnal_penyesuaian[Akun],buku_besar[[#This Row],[Nama Akun]],jurnal_penyesuaian[Debit (Rp)]) -> 0 | H12: =SUMIF(jurnal_penyesuaian[Akun],buku_besar[[#This Row],[Nama Akun]],jurnal_penyesuaian[Kredit (Rp)]) -> 1000000 | I12: =MAX(0,(buku_besar[[#This Row],[Debit JU]]+buku_besar[[#This Row],[Debit Penyesuaian]]-buku_besar[[#This Row],[Kredit JU]]-buku_besar[[#This Row],[Kredit Penyesuaian]])) -> 5000000 | J12: =MAX(0,(buku_besar[[#This Row],[Kredit JU]]+buku_besar[[#This Row],[Kredit Penyesuaian]]-buku_besar[[#This Row],[Debit JU]]-buku_besar[[#This Row],[Debit Penyesuaian]])) -> 0 | K12: =MAX(0,(SUMIF(jurnal_penutup[Akun],buku_besar[[#This Row],[Nama Akun]],jurnal_penutup[Debit (Rp)]))) -> 0 | L12: =MAX(0,(SUMIF(jurnal_penutup[Akun],buku_besar[[#This Row],[Nama Akun]],jurnal_penutup[Kredit (Rp)]))) -> 0 | M12: =MAX(0,(buku_besar[[#This Row],[Debit JU]]+buku_besar[[#This Row],[Debit Penyesuaian]]+buku_besar[[#This Row],[Debit Penutup]])-(buku_besar[[#This Row],[Kredit JU]]+buku_besar[[#This Row],[Kredit Penyesuaian]]+buku_besar[[#This Row],[Kredit Penutup]])) -> 5000000 | N12: =MAX(0,(buku_besar[[#This Row],[Kredit JU]]+buku_besar[[#This Row],[Kredit Penyesuaian]]+buku_besar[[#This Row],[Kredit Penutup]])-(buku_besar[[#This Row],[Debit JU]]+buku_besar[[#This Row],[Debit Penyesuaian]]+buku_besar[[#This Row],[Debit Penutup]])) -> 0
A13: 1-010 | B13: Iklan Dibayar di Muka | C13: Aset | D13: Debit | E13: =SUMIF(jurnal[Akun],buku_besar[[#This Row],[Nama Akun]],jurnal[Debit (Rp)]) -> 7500000 | F13: =SUMIF(jurnal[Akun],buku_besar[[#This Row],[Nama Akun]],jurnal[Kredit (Rp)]) -> 0 | G13: =SUMIF(jurnal_penyesuaian[Akun],buku_besar[[#This Row],[Nama Akun]],jurnal_penyesuaian[Debit (Rp)]) -> 0 | H13: =SUMIF(jurnal_penyesuaian[Akun],buku_besar[[#This Row],[Nama Akun]],jurnal_penyesuaian[Kredit (Rp)]) -> 1500000 | I13: =MAX(0,(buku_besar[[#This Row],[Debit JU]]+buku_besar[[#This Row],[Debit Penyesuaian]]-buku_besar[[#This Row],[Kredit JU]]-buku_besar[[#This Row],[Kredit Penyesuaian]])) -> 6000000 | J13: =MAX(0,(buku_besar[[#This Row],[Kredit JU]]+buku_besar[[#This Row],[Kredit Penyesuaian]]-buku_besar[[#This Row],[Debit JU]]-buku_besar[[#This Row],[Debit Penyesuaian]])) -> 0 | K13: =MAX(0,(SUMIF(jurnal_penutup[Akun],buku_besar[[#This Row],[Nama Akun]],jurnal_penutup[Debit (Rp)]))) -> 0 | L13: =MAX(0,(SUMIF(jurnal_penutup[Akun],buku_besar[[#This Row],[Nama Akun]],jurnal_penutup[Kredit (Rp)]))) -> 0 | M13: =MAX(0,(buku_besar[[#This Row],[Debit JU]]+buku_besar[[#This Row],[Debit Penyesuaian]]+buku_besar[[#This Row],[Debit Penutup]])-(buku_besar[[#This Row],[Kredit JU]]+buku_besar[[#This Row],[Kredit Penyesuaian]]+buku_besar[[#This Row],[Kredit Penutup]])) -> 6000000 | N13: =MAX(0,(buku_besar[[#This Row],[Kredit JU]]+buku_besar[[#This Row],[Kredit Penyesuaian]]+buku_besar[[#This Row],[Kredit Penutup]])-(buku_besar[[#This Row],[Debit JU]]+buku_besar[[#This Row],[Debit Penyesuaian]]+buku_besar[[#This Row],[Debit Penutup]])) -> 0
A14: 1-011 | B14: Uang Muka Pembelian | C14: Aset | D14: Debit | E14: =SUMIF(jurnal[Akun],buku_besar[[#This Row],[Nama Akun]],jurnal[Debit (Rp)]) -> 10000000 | F14: =SUMIF(jurnal[Akun],buku_besar[[#This Row],[Nama Akun]],jurnal[Kredit (Rp)]) -> 2000000 | G14: =SUMIF(jurnal_penyesuaian[Akun],buku_besar[[#This Row],[Nama Akun]],jurnal_penyesuaian[Debit (Rp)]) -> 0 | H14: =SUMIF(jurnal_penyesuaian[Akun],buku_besar[[#This Row],[Nama Akun]],jurnal_penyesuaian[Kredit (Rp)]) -> 0 | I14: =MAX(0,(buku_besar[[#This Row],[Debit JU]]+buku_besar[[#This Row],[Debit Penyesuaian]]-buku_besar[[#This Row],[Kredit JU]]-buku_besar[[#This Row],[Kredit Penyesuaian]])) -> 8000000 | J14: =MAX(0,(buku_besar[[#This Row],[Kredit JU]]+buku_besar[[#This Row],[Kredit Penyesuaian]]-buku_besar[[#This Row],[Debit JU]]-buku_besar[[#This Row],[Debit Penyesuaian]])) -> 0 | K14: =MAX(0,(SUMIF(jurnal_penutup[Akun],buku_besar[[#This Row],[Nama Akun]],jurnal_penutup[Debit (Rp)]))) -> 0 | L14: =MAX(0,(SUMIF(jurnal_penutup[Akun],buku_besar[[#This Row],[Nama Akun]],jurnal_penutup[Kredit (Rp)]))) -> 0 | M14: =MAX(0,(buku_besar[[#This Row],[Debit JU]]+buku_besar[[#This Row],[Debit Penyesuaian]]+buku_besar[[#This Row],[Debit Penutup]])-(buku_besar[[#This Row],[Kredit JU]]+buku_besar[[#This Row],[Kredit Penyesuaian]]+buku_besar[[#This Row],[Kredit Penutup]])) -> 8000000 | N14: =MAX(0,(buku_besar[[#This Row],[Kredit JU]]+buku_besar[[#This Row],[Kredit Penyesuaian]]+buku_besar[[#This Row],[Kredit Penutup]])-(buku_besar[[#This Row],[Debit JU]]+buku_besar[[#This Row],[Debit Penyesuaian]]+buku_besar[[#This Row],[Debit Penutup]])) -> 0
A15: 1-012 | B15: Peralatan | C15: Aset | D15: Debit | E15: =SUMIF(jurnal[Akun],buku_besar[[#This Row],[Nama Akun]],jurnal[Debit (Rp)]) -> 22000000 | F15: =SUMIF(jurnal[Akun],buku_besar[[#This Row],[Nama Akun]],jurnal[Kredit (Rp)]) -> 0 | G15: =SUMIF(jurnal_penyesuaian[Akun],buku_besar[[#This Row],[Nama Akun]],jurnal_penyesuaian[Debit (Rp)]) -> 0 | H15: =SUMIF(jurnal_penyesuaian[Akun],buku_besar[[#This Row],[Nama Akun]],jurnal_penyesuaian[Kredit (Rp)]) -> 0 | I15: =MAX(0,(buku_besar[[#This Row],[Debit JU]]+buku_besar[[#This Row],[Debit Penyesuaian]]-buku_besar[[#This Row],[Kredit JU]]-buku_besar[[#This Row],[Kredit Penyesuaian]])) -> 22000000 | J15: =MAX(0,(buku_besar[[#This Row],[Kredit JU]]+buku_besar[[#This Row],[Kredit Penyesuaian]]-buku_besar[[#This Row],[Debit JU]]-buku_besar[[#This Row],[Debit Penyesuaian]])) -> 0 | K15: =MAX(0,(SUMIF(jurnal_penutup[Akun],buku_besar[[#This Row],[Nama Akun]],jurnal_penutup[Debit (Rp)]))) -> 0 | L15: =MAX(0,(SUMIF(jurnal_penutup[Akun],buku_besar[[#This Row],[Nama Akun]],jurnal_penutup[Kredit (Rp)]))) -> 0 | M15: =MAX(0,(buku_besar[[#This Row],[Debit JU]]+buku_besar[[#This Row],[Debit Penyesuaian]]+buku_besar[[#This Row],[Debit Penutup]])-(buku_besar[[#This Row],[Kredit JU]]+buku_besar[[#This Row],[Kredit Penyesuaian]]+buku_besar[[#This Row],[Kredit Penutup]])) -> 22000000 | N15: =MAX(0,(buku_besar[[#This Row],[Kredit JU]]+buku_besar[[#This Row],[Kredit Penyesuaian]]+buku_besar[[#This Row],[Kredit Penutup]])-(buku_besar[[#This Row],[Debit JU]]+buku_besar[[#This Row],[Debit Penyesuaian]]+buku_besar[[#This Row],[Debit Penutup]])) -> 0
... A67: 5-020 | B67: Beban Lain-lain | C67: Beban | D67: Debit | E67: =SUMIF(jurnal[Akun],buku_besar[[#This Row],[Nama Akun]],jurnal[Debit (Rp)]) -> 0 | F67: =SUMIF(jurnal[Akun],buku_besar[[#This Row],[Nama Akun]],jurnal[Kredit (Rp)]) -> 0 | G67: =SUMIF(jurnal_penyesuaian[Akun],buku_besar[[#This Row],[Nama Akun]],jurnal_penyesuaian[Debit (Rp)]) -> 5900000 | H67: =SUMIF(jurnal_penyesuaian[Akun],buku_besar[[#This Row],[Nama Akun]],jurnal_penyesuaian[Kredit (Rp)]) -> 0 | I67: =MAX(0,(buku_besar[[#This Row],[Debit JU]]+buku_besar[[#This Row],[Debit Penyesuaian]]-buku_besar[[#This Row],[Kredit JU]]-buku_besar[[#This Row],[Kredit Penyesuaian]])) -> 5900000 | J67: =MAX(0,(buku_besar[[#This Row],[Kredit JU]]+buku_besar[[#This Row],[Kredit Penyesuaian]]-buku_besar[[#This Row],[Debit JU]]-buku_besar[[#This Row],[Debit Penyesuaian]])) -> 0 | K67: =MAX(0,(SUMIF(jurnal_penutup[Akun],buku_besar[[#This Row],[Nama Akun]],jurnal_penutup[Debit (Rp)]))) -> 0 | L67: =MAX(0,(SUMIF(jurnal_penutup[Akun],buku_besar[[#This Row],[Nama Akun]],jurnal_penutup[Kredit (Rp)]))) -> 5900000 | M67: =MAX(0,(buku_besar[[#This Row],[Debit JU]]+buku_besar[[#This Row],[Debit Penyesuaian]]+buku_besar[[#This Row],[Debit Penutup]])-(buku_besar[[#This Row],[Kredit JU]]+buku_besar[[#This Row],[Kredit Penyesuaian]]+buku_besar[[#This Row],[Kredit Penutup]])) -> 0 | N67: =MAX(0,(buku_besar[[#This Row],[Kredit JU]]+buku_besar[[#This Row],[Kredit Penyesuaian]]+buku_besar[[#This Row],[Kredit Penutup]])-(buku_besar[[#This Row],[Debit JU]]+buku_besar[[#This Row],[Debit Penyesuaian]]+buku_besar[[#This Row],[Debit Penutup]])) -> 0
A69: TOTAL | E69: =SUM(E4:E67) -> 1308430000 | F69: =SUM(F4:F67) -> 1308430000 | G69: =SUM(G4:G67) -> 24400000 | H69: =SUM(H4:H67) -> 24400000 | I69: =SUM(I4:I67) -> 1164980000 | J69: =SUM(J4:J67) -> 1164980000 | K69: =SUM(K4:K67) -> 125350000 | L69: =SUM(L4:L67) -> 125350000 | ... N69: =SUM(N4:N67) -> 1093130000

Sheet Neraca_Saldo
A1: NERACA SALDO - SEBELUM PENYESUAIAN, FUNGSI NERACA SALDO MENGECEK SALDO SELURUH AKUN.
A3: Kode Akun | B3: Nama Akun | C3: Kategori | D3: Saldo Normal | E3: Debit (Rp) | F3: Kredit (Rp)
A4: 1-001 | B4: Kas | C4: Aset | D4: Debit | E4: =MAX(0,(SUMIF(buku_besar[Nama Akun],Table17[[#This Row],[Nama Akun]],buku_besar[Debit JU])-SUMIF(buku_besar[Nama Akun],Table17[[#This Row],[Nama Akun]],buku_besar[Kredit JU]))) -> 35150000 | F4: =MAX(0,(SUMIF(buku_besar[Nama Akun],Table17[[#This Row],[Nama Akun]],buku_besar[Kredit JU])-SUMIF(buku_besar[Nama Akun],Table17[[#This Row],[Nama Akun]],buku_besar[Debit JU]))) -> 0
A5: 1-002 | B5: Bank | C5: Aset | D5: Debit | E5: =MAX(0,(SUMIF(buku_besar[Nama Akun],Table17[[#This Row],[Nama Akun]],buku_besar[Debit JU])-SUMIF(buku_besar[Nama Akun],Table17[[#This Row],[Nama Akun]],buku_besar[Kredit JU]))) -> 175850000 | F5: =MAX(0,(SUMIF(buku_besar[Nama Akun],Table17[[#This Row],[Nama Akun]],buku_besar[Kredit JU])-SUMIF(buku_besar[Nama Akun],Table17[[#This Row],[Nama Akun]],buku_besar[Debit JU]))) -> 0
A6: 1-003 | B6: Piutang Usaha | C6: Aset | D6: Debit | E6: =MAX(0,(SUMIF(buku_besar[Nama Akun],Table17[[#This Row],[Nama Akun]],buku_besar[Debit JU])-SUMIF(buku_besar[Nama Akun],Table17[[#This Row],[Nama Akun]],buku_besar[Kredit JU]))) -> 23080000 | F6: =MAX(0,(SUMIF(buku_besar[Nama Akun],Table17[[#This Row],[Nama Akun]],buku_besar[Kredit JU])-SUMIF(buku_besar[Nama Akun],Table17[[#This Row],[Nama Akun]],buku_besar[Debit JU]))) -> 0
A7: 1-004 | B7: Piutang Karyawan | C7: Aset | D7: Debit | E7: =MAX(0,(SUMIF(buku_besar[Nama Akun],Table17[[#This Row],[Nama Akun]],buku_besar[Debit JU])-SUMIF(buku_besar[Nama Akun],Table17[[#This Row],[Nama Akun]],buku_besar[Kredit JU]))) -> 2500000 | F7: =MAX(0,(SUMIF(buku_besar[Nama Akun],Table17[[#This Row],[Nama Akun]],buku_besar[Kredit JU])-SUMIF(buku_besar[Nama Akun],Table17[[#This Row],[Nama Akun]],buku_besar[Debit JU]))) -> 0
A8: 1-005 | B8: Piutang Lain-lain | C8: Aset | D8: Debit | E8: =MAX(0,(SUMIF(buku_besar[Nama Akun],Table17[[#This Row],[Nama Akun]],buku_besar[Debit JU])-SUMIF(buku_besar[Nama Akun],Table17[[#This Row],[Nama Akun]],buku_besar[Kredit JU]))) -> 2400000 | F8: =MAX(0,(SUMIF(buku_besar[Nama Akun],Table17[[#This Row],[Nama Akun]],buku_besar[Kredit JU])-SUMIF(buku_besar[Nama Akun],Table17[[#This Row],[Nama Akun]],buku_besar[Debit JU]))) -> 0
A9: 1-006 | B9: Persediaan | C9: Aset | D9: Debit | E9: =MAX(0,(SUMIF(buku_besar[Nama Akun],Table17[[#This Row],[Nama Akun]],buku_besar[Debit JU])-SUMIF(buku_besar[Nama Akun],Table17[[#This Row],[Nama Akun]],buku_besar[Kredit JU]))) -> 35000000 | F9: =MAX(0,(SUMIF(buku_besar[Nama Akun],Table17[[#This Row],[Nama Akun]],buku_besar[Kredit JU])-SUMIF(buku_besar[Nama Akun],Table17[[#This Row],[Nama Akun]],buku_besar[Debit JU]))) -> 0
A10: 1-007 | B10: Perlengkapan | C10: Aset | D10: Debit | E10: =MAX(0,(SUMIF(buku_besar[Nama Akun],Table17[[#This Row],[Nama Akun]],buku_besar[Debit JU])-SUMIF(buku_besar[Nama Akun],Table17[[#This Row],[Nama Akun]],buku_besar[Kredit JU]))) -> 4500000 | F10: =MAX(0,(SUMIF(buku_besar[Nama Akun],Table17[[#This Row],[Nama Akun]],buku_besar[Kredit JU])-SUMIF(buku_besar[Nama Akun],Table17[[#This Row],[Nama Akun]],buku_besar[Debit JU]))) -> 0
A11: 1-008 | B11: Sewa Dibayar di Muka | C11: Aset | D11: Debit | E11: =MAX(0,(SUMIF(buku_besar[Nama Akun],Table17[[#This Row],[Nama Akun]],buku_besar[Debit JU])-SUMIF(buku_besar[Nama Akun],Table17[[#This Row],[Nama Akun]],buku_besar[Kredit JU]))) -> 12000000 | F11: =MAX(0,(SUMIF(buku_besar[Nama Akun],Table17[[#This Row],[Nama Akun]],buku_besar[Kredit JU])-SUMIF(buku_besar[Nama Akun],Table17[[#This Row],[Nama Akun]],buku_besar[Debit JU]))) -> 0
A12: 1-009 | B12: Asuransi Dibayar di Muka | C12: Aset | D12: Debit | E12: =MAX(0,(SUMIF(buku_besar[Nama Akun],Table17[[#This Row],[Nama Akun]],buku_besar[Debit JU])-SUMIF(buku_besar[Nama Akun],Table17[[#This Row],[Nama Akun]],buku_besar[Kredit JU]))) -> 6000000 | F12: =MAX(0,(SUMIF(buku_besar[Nama Akun],Table17[[#This Row],[Nama Akun]],buku_besar[Kredit JU])-SUMIF(buku_besar[Nama Akun],Table17[[#This Row],[Nama Akun]],buku_besar[Debit JU]))) -> 0
A13: 1-010 | B13: Iklan Dibayar di Muka | C13: Aset | D13: Debit | E13: =MAX(0,(SUMIF(buku_besar[Nama Akun],Table17[[#This Row],[Nama Akun]],buku_besar[Debit JU])-SUMIF(buku_besar[Nama Akun],Table17[[#This Row],[Nama Akun]],buku_besar[Kredit JU]))) -> 7500000 | F13: =MAX(0,(SUMIF(buku_besar[Nama Akun],Table17[[#This Row],[Nama Akun]],buku_besar[Kredit JU])-SUMIF(buku_besar[Nama Akun],Table17[[#This Row],[Nama Akun]],buku_besar[Debit JU]))) -> 0
A14: 1-011 | B14: Uang Muka Pembelian | C14: Aset | D14: Debit | E14: =MAX(0,(SUMIF(buku_besar[Nama Akun],Table17[[#This Row],[Nama Akun]],buku_besar[Debit JU])-SUMIF(buku_besar[Nama Akun],Table17[[#This Row],[Nama Akun]],buku_besar[Kredit JU]))) -> 8000000 | F14: =MAX(0,(SUMIF(buku_besar[Nama Akun],Table17[[#This Row],[Nama Akun]],buku_besar[Kredit JU])-SUMIF(buku_besar[Nama Akun],Table17[[#This Row],[Nama Akun]],buku_besar[Debit JU]))) -> 0
A15: 1-012 | B15: Peralatan | C15: Aset | D15: Debit | E15: =MAX(0,(SUMIF(buku_besar[Nama Akun],Table17[[#This Row],[Nama Akun]],buku_besar[Debit JU])-SUMIF(buku_besar[Nama Akun],Table17[[#This Row],[Nama Akun]],buku_besar[Kredit JU]))) -> 22000000 | F15: =MAX(0,(SUMIF(buku_besar[Nama Akun],Table17[[#This Row],[Nama Akun]],buku_besar[Kredit JU])-SUMIF(buku_besar[Nama Akun],Table17[[#This Row],[Nama Akun]],buku_besar[Debit JU]))) -> 0
... A67: 5-020 | B67: Beban Lain-lain | C67: Beban | D67: Debit | E67: =MAX(0,(SUMIF(buku_besar[Nama Akun],Table17[[#This Row],[Nama Akun]],buku_besar[Debit JU])-SUMIF(buku_besar[Nama Akun],Table17[[#This Row],[Nama Akun]],buku_besar[Kredit JU]))) -> 0 | F67: =MAX(0,(SUMIF(buku_besar[Nama Akun],Table17[[#This Row],[Nama Akun]],buku_besar[Kredit JU])-SUMIF(buku_besar[Nama Akun],Table17[[#This Row],[Nama Akun]],buku_besar[Debit JU]))) -> 0
A69: TOTAL | E69: =SUM(E4:E67) -> 1154080000 | F69: =SUM(F4:F67) -> 1154080000
A70: CEK | F70: =IF(E69=F69,"BALANCE","SELISIH "&TEXT(E69-F69,"#,##0")) -> BALANCE

Sheet Jurnal_Penyesuaian
A1: SOAL JURNAL PENYESUAIAN AKHIR PERIODE, FUNGSI JURNAL PENYESUAIAN MENCATAT TRANSAKSI YANG BELUM TERCATAT ATAU PERLU DIPERBAIKI. | J1: JURNAL PENYESUAIAN - AREA LATIHAN
A2: Kerjakan jurnal penyesuaian berdasarkan informasi akhir periode di bawah ini. | J2: Isi kolom Akun, Debit, dan Kredit. Kolom Cek membandingkan jawaban dengan Kunci_Penyesuaian.
A3: No | B3: Tanggal | C3: Jenis Penyesuaian | D3: Informasi Akhir Periode | E3: Nominal (Rp) | F3: No2 | G3: Petunjuk | J3: No | K3: Tanggal | L3: Akun | M3: Debit (Rp) | N3: Kredit (Rp) | O3: Cek
A4: 1 | B4: 46660 | C4: Perlengkapan terpakai | D4: Hasil pemeriksaan fisik menunjukkan perlengkapan yang masih tersisa sebesar Rp2.500.000. Saldo perlengkapan sebelum penyesuaian berasal dari pembelian Rp4.500.000. | E4: 2000000 | F4: 1 | G4: Beban perlengkapan diakui sebesar perlengkapan yang sudah terpakai. | J4: 1 | K4: 46660 | L4: Beban Perlengkapan | M4: =Table8[[#This Row],[Nominal (Rp)]] -> 2000000 | O4: =IF($L4="","",IF(AND($L4=Kunci_Penyesuaian!$C4,IF($M4="",0,$M4)=IF(Kunci_Penyesuaian!$D4="",0,Kunci_Penyesuaian!$D4),IF($N4="",0,$N4)=IF(Kunci_Penyesuaian!$E4="",0,Kunci_Penyesuaian!$E4)),"Benar","Cek lagi")) -> Benar
A5: 2 | J5: 1 | K5: 46660 | L5: Perlengkapan | N5: =M4 -> 2000000 | O5: =IF($L5="","",IF(AND($L5=Kunci_Penyesuaian!$C5,IF($M5="",0,$M5)=IF(Kunci_Penyesuaian!$D5="",0,Kunci_Penyesuaian!$D5),IF($N5="",0,$N5)=IF(Kunci_Penyesuaian!$E5="",0,Kunci_Penyesuaian!$E5)),"Benar","Cek lagi")) -> Benar
A6: 3 | B6: 46660 | C6: Sewa terpakai | D6: Dari sewa dibayar di muka, bagian yang sudah menjadi beban periode berjalan adalah Rp4.000.000. | E6: 4000000 | F6: 2 | G6: Kurangi aset sewa dibayar di muka dan akui beban sewa. | J6: 2 | K6: 46660 | L6: Beban Sewa | M6: =Table8[[#This Row],[Nominal (Rp)]] -> 4000000 | O6: =IF($L6="","",IF(AND($L6=Kunci_Penyesuaian!$C6,IF($M6="",0,$M6)=IF(Kunci_Penyesuaian!$D6="",0,Kunci_Penyesuaian!$D6),IF($N6="",0,$N6)=IF(Kunci_Penyesuaian!$E6="",0,Kunci_Penyesuaian!$E6)),"Benar","Cek lagi")) -> Benar
A7: 4 | J7: 2 | K7: 46660 | L7: Sewa Dibayar di Muka | N7: =M6 -> 4000000 | O7: =IF($L7="","",IF(AND($L7=Kunci_Penyesuaian!$C7,IF($M7="",0,$M7)=IF(Kunci_Penyesuaian!$D7="",0,Kunci_Penyesuaian!$D7),IF($N7="",0,$N7)=IF(Kunci_Penyesuaian!$E7="",0,Kunci_Penyesuaian!$E7)),"Benar","Cek lagi")) -> Benar
A8: 5 | B8: 46660 | C8: Asuransi terpakai | D8: Premi asuransi dibayar di muka yang sudah terpakai sampai akhir periode sebesar Rp1.000.000. | E8: 1000000 | F8: 3 | G8: Kurangi aset asuransi dibayar di muka dan akui beban asuransi. | J8: 3 | K8: 46660 | L8: Beban Asuransi | M8: =Table8[[#This Row],[Nominal (Rp)]] -> 1000000 | O8: =IF($L8="","",IF(AND($L8=Kunci_Penyesuaian!$C8,IF($M8="",0,$M8)=IF(Kunci_Penyesuaian!$D8="",0,Kunci_Penyesuaian!$D8),IF($N8="",0,$N8)=IF(Kunci_Penyesuaian!$E8="",0,Kunci_Penyesuaian!$E8)),"Benar","Cek lagi")) -> Benar
A9: 6 | J9: 3 | K9: 46660 | L9: Asuransi Dibayar di Muka | N9: =M8 -> 1000000 | O9: =IF($L9="","",IF(AND($L9=Kunci_Penyesuaian!$C9,IF($M9="",0,$M9)=IF(Kunci_Penyesuaian!$D9="",0,Kunci_Penyesuaian!$D9),IF($N9="",0,$N9)=IF(Kunci_Penyesuaian!$E9="",0,Kunci_Penyesuaian!$E9)),"Benar","Cek lagi")) -> Benar
A10: 7 | B10: 46660 | C10: Iklan terpakai | D10: Paket iklan dibayar di muka yang sudah tayang dan menjadi beban periode berjalan sebesar Rp1.500.000. | E10: 1500000 | F10: 4 | G10: Kurangi iklan dibayar di muka dan akui beban iklan. | J10: 4 | K10: 46660 | L10: Beban Iklan | M10: =Table8[[#This Row],[Nominal (Rp)]] -> 1500000 | O10: =IF($L10="","",IF(AND($L10=Kunci_Penyesuaian!$C10,IF($M10="",0,$M10)=IF(Kunci_Penyesuaian!$D10="",0,Kunci_Penyesuaian!$D10),IF($N10="",0,$N10)=IF(Kunci_Penyesuaian!$E10="",0,Kunci_Penyesuaian!$E10)),"Benar","Cek lagi")) -> Benar
A11: 8 | J11: 4 | K11: 46660 | L11: Iklan Dibayar di Muka | N11: =M10 -> 1500000 | O11: =IF($L11="","",IF(AND($L11=Kunci_Penyesuaian!$C11,IF($M11="",0,$M11)=IF(Kunci_Penyesuaian!$D11="",0,Kunci_Penyesuaian!$D11),IF($N11="",0,$N11)=IF(Kunci_Penyesuaian!$E11="",0,Kunci_Penyesuaian!$E11)),"Benar","Cek lagi")) -> Benar
A12: 9 | B12: 46660 | C12: Penyusutan peralatan | D12: Penyusutan peralatan periode ini dihitung sebesar Rp1.800.000. | E12: 1800000 | F12: 5 | G12: Akui beban penyusutan dan akumulasi penyusutan peralatan. | J12: 5 | K12: 46660 | L12: Beban Penyusutan Peralatan | M12: =Table8[[#This Row],[Nominal (Rp)]] -> 1800000 | O12: =IF($L12="","",IF(AND($L12=Kunci_Penyesuaian!$C12,IF($M12="",0,$M12)=IF(Kunci_Penyesuaian!$D12="",0,Kunci_Penyesuaian!$D12),IF($N12="",0,$N12)=IF(Kunci_Penyesuaian!$E12="",0,Kunci_Penyesuaian!$E12)),"Benar","Cek lagi")) -> Benar
A13: 10 | J13: 5 | K13: 46660 | L13: Akumulasi Penyusutan Peralatan | N13: =M12 -> 1800000 | O13: =IF($L13="","",IF(AND($L13=Kunci_Penyesuaian!$C13,IF($M13="",0,$M13)=IF(Kunci_Penyesuaian!$D13="",0,Kunci_Penyesuaian!$D13),IF($N13="",0,$N13)=IF(Kunci_Penyesuaian!$E13="",0,Kunci_Penyesuaian!$E13)),"Benar","Cek lagi")) -> Benar
B14: 46660 | C14: Penyusutan kendaraan | D14: Penyusutan kendaraan periode ini dihitung sebesar Rp2.400.000. | E14: 2400000 | F14: 6 | G14: Gunakan Beban Lain-lain karena akun beban penyusutan kendaraan belum tersedia di COA. | J14: 6 | K14: 46660 | L14: Beban Lain-lain | M14: =Table8[[#This Row],[Nominal (Rp)]] -> 2400000 | O14: =IF($L14="","",IF(AND($L14=Kunci_Penyesuaian!$C14,IF($M14="",0,$M14)=IF(Kunci_Penyesuaian!$D14="",0,Kunci_Penyesuaian!$D14),IF($N14="",0,$N14)=IF(Kunci_Penyesuaian!$E14="",0,Kunci_Penyesuaian!$E14)),"Benar","Cek lagi")) -> Benar
J15: 6 | K15: 46660 | L15: Akumulasi Penyusutan Kendaraan | N15: =M14 -> 2400000 | O15: =IF($L15="","",IF(AND($L15=Kunci_Penyesuaian!$C15,IF($M15="",0,$M15)=IF(Kunci_Penyesuaian!$D15="",0,Kunci_Penyesuaian!$D15),IF($N15="",0,$N15)=IF(Kunci_Penyesuaian!$E15="",0,Kunci_Penyesuaian!$E15)),"Benar","Cek lagi")) -> Benar
