Workbook

Sheet Sheet1
A1: A. SALDO AWAL | B1: A. Saldo Awal
A3: No | B3: Akun | C3: Debit (Rp) | D3: Kredit (Rp)
A4: 1 | B4: Bank | C4: 200000000 | D4: –
A5: 2 | B5: Persediaan Barang Dagang | C5: 100000000 | D5: –
A6: 3 | B6: Peralatan | C6: 50000000 | D6: –
A7: 4 | B7: Akumulasi Penyusutan Peralatan | C7: – | D7: 10000000
A8: 5 | B8: Utang Usaha | C8: – | D8: 40000000
A9: 6 | B9: Utang Bank Jangka Panjang | C9: – | D9: 50000000
A10: 7 | B10: Modal Saham | C10: – | D10: 250000000
B11: Total | C11: 350000000 | D11: 350000000
A15: B. 10 TRANSAKSI & JURNAL UMUM | B15: B. 10 Transaksi & Jurnal Umum
A17: No | B17: Tingkat / Jenis | C17: Soal | D17: Tambahan / Fakta Penting | E17: Nominal (Rp) | F17: Petunjuk | G17: Akun Jawaban | H17: Debit (Rp) | I17: Kredit (Rp) | J17: akun koreksi | K17: debit koreksi | L17: kredit koreksi
A18: 1 | B18: Mudah / Pembelian persediaan kredit | C18: Perusahaan membeli persediaan dari Supplier A secara kredit sebesar Rp80.000.000 sebelum PPN. | D18: PPN latihan efektif 11%; satu invoice; belum dibayar. | E18: 80000000 | F18: Debit Persediaan dan PPN Masukan; kredit Utang Usaha. | G18: Persediaan Barang Dagang | H18: 80000000 | I18: – | J18: =IF(jurnal[[#This Row],[Akun Jawaban]]="","",IF(jurnal[[#This Row],[Akun Jawaban]]=Sheet4!G2,"benar","salah")) -> benar | K18: =IF(jurnal[[#This Row],[Debit (Rp)]]="","",IF(jurnal[[#This Row],[Debit (Rp)]]=Sheet4!H2,"benar","salah")) -> benar | L18: =IF(jurnal[[#This Row],[Kredit (Rp)]]="","",IF(jurnal[[#This Row],[Kredit (Rp)]]=Sheet4!I2,"benar","salah")) -> benar
G19: PPN Masukan | H19: 8800000 | I19: – | J19: =IF(jurnal[[#This Row],[Akun Jawaban]]="","",IF(jurnal[[#This Row],[Akun Jawaban]]=Sheet4!G3,"benar","salah")) -> benar | K19: =IF(jurnal[[#This Row],[Debit (Rp)]]="","",IF(jurnal[[#This Row],[Debit (Rp)]]=Sheet4!H3,"benar","salah")) -> benar | L19: =IF(jurnal[[#This Row],[Kredit (Rp)]]="","",IF(jurnal[[#This Row],[Kredit (Rp)]]=Sheet4!I3,"benar","salah")) -> benar
G20: Utang Usaha | H20: – | I20: 88800000 | J20: =IF(jurnal[[#This Row],[Akun Jawaban]]="","",IF(jurnal[[#This Row],[Akun Jawaban]]=Sheet4!G4,"benar","salah")) -> benar | K20: =IF(jurnal[[#This Row],[Debit (Rp)]]="","",IF(jurnal[[#This Row],[Debit (Rp)]]=Sheet4!H4,"benar","salah")) -> benar | L20: =IF(jurnal[[#This Row],[Kredit (Rp)]]="","",IF(jurnal[[#This Row],[Kredit (Rp)]]=Sheet4!I4,"benar","salah")) -> benar
A21: 2 | B21: Mudah / Penjualan tunai | C21: Perusahaan menjual barang dagang secara tunai sebesar Rp120.000.000 sebelum PPN. HPP barang yang dijual sebesar Rp70.000.000. | D21: PPN 11%; sistem perpetual; dibayar melalui bank. | E21: 120000000 | F21: Buat dua kelompok jurnal: penjualan + PPN dan HPP + persediaan. | G21: Bank | H21: 133200000 | I21: – | J21: =IF(jurnal[[#This Row],[Akun Jawaban]]="","",IF(jurnal[[#This Row],[Akun Jawaban]]=Sheet4!G5,"benar","salah")) -> benar | K21: =IF(jurnal[[#This Row],[Debit (Rp)]]="","",IF(jurnal[[#This Row],[Debit (Rp)]]=Sheet4!H5,"benar","salah")) -> benar | L21: =IF(jurnal[[#This Row],[Kredit (Rp)]]="","",IF(jurnal[[#This Row],[Kredit (Rp)]]=Sheet4!I5,"benar","salah")) -> benar
G22: Penjualan | H22: – | I22: 120000000 | J22: =IF(jurnal[[#This Row],[Akun Jawaban]]="","",IF(jurnal[[#This Row],[Akun Jawaban]]=Sheet4!G6,"benar","salah")) -> benar | K22: =IF(jurnal[[#This Row],[Debit (Rp)]]="","",IF(jurnal[[#This Row],[Debit (Rp)]]=Sheet4!H6,"benar","salah")) -> benar | L22: =IF(jurnal[[#This Row],[Kredit (Rp)]]="","",IF(jurnal[[#This Row],[Kredit (Rp)]]=Sheet4!I6,"benar","salah")) -> benar
G23: PPN Keluaran | H23: – | I23: 13200000 | J23: =IF(jurnal[[#This Row],[Akun Jawaban]]="","",IF(jurnal[[#This Row],[Akun Jawaban]]=Sheet4!G7,"benar","salah")) -> benar | K23: =IF(jurnal[[#This Row],[Debit (Rp)]]="","",IF(jurnal[[#This Row],[Debit (Rp)]]=Sheet4!H7,"benar","salah")) -> benar | L23: =IF(jurnal[[#This Row],[Kredit (Rp)]]="","",IF(jurnal[[#This Row],[Kredit (Rp)]]=Sheet4!I7,"benar","salah")) -> benar
G24: HPP | H24: 70000000 | I24: – | J24: =IF(jurnal[[#This Row],[Akun Jawaban]]="","",IF(jurnal[[#This Row],[Akun Jawaban]]=Sheet4!G8,"benar","salah")) -> benar | K24: =IF(jurnal[[#This Row],[Debit (Rp)]]="","",IF(jurnal[[#This Row],[Debit (Rp)]]=Sheet4!H8,"benar","salah")) -> benar | L24: =IF(jurnal[[#This Row],[Kredit (Rp)]]="","",IF(jurnal[[#This Row],[Kredit (Rp)]]=Sheet4!I8,"benar","salah")) -> benar
G25: Persediaan Barang Dagang | H25: – | I25: 70000000 | J25: =IF(jurnal[[#This Row],[Akun Jawaban]]="","",IF(jurnal[[#This Row],[Akun Jawaban]]=Sheet4!G9,"benar","salah")) -> benar | K25: =IF(jurnal[[#This Row],[Debit (Rp)]]="","",IF(jurnal[[#This Row],[Debit (Rp)]]=Sheet4!H9,"benar","salah")) -> benar | L25: =IF(jurnal[[#This Row],[Kredit (Rp)]]="","",IF(jurnal[[#This Row],[Kredit (Rp)]]=Sheet4!I9,"benar","salah")) -> benar
A26: 3 | B26: Mudah / Penjualan kredit | C26: Perusahaan menjual barang kepada Pelanggan B secara kredit sebesar Rp90.000.000 sebelum PPN. HPP barang yang dijual Rp50.000.000. | D26: PPN 11%; termin 30 hari. | E26: 90000000 | F26: Debit Piutang; kredit Penjualan dan PPN Keluaran; lalu HPP dan Persediaan. | G26: Piutang Usaha | H26: 99900000 | I26: – | J26: =IF(jurnal[[#This Row],[Akun Jawaban]]="","",IF(jurnal[[#This Row],[Akun Jawaban]]=Sheet4!G10,"benar","salah")) -> benar | K26: =IF(jurnal[[#This Row],[Debit (Rp)]]="","",IF(jurnal[[#This Row],[Debit (Rp)]]=Sheet4!H10,"benar","salah")) -> benar | L26: =IF(jurnal[[#This Row],[Kredit (Rp)]]="","",IF(jurnal[[#This Row],[Kredit (Rp)]]=Sheet4!I10,"benar","salah")) -> benar
G27: Penjualan | H27: – | I27: 90000000 | J27: =IF(jurnal[[#This Row],[Akun Jawaban]]="","",IF(jurnal[[#This Row],[Akun Jawaban]]=Sheet4!G11,"benar","salah")) -> benar | K27: =IF(jurnal[[#This Row],[Debit (Rp)]]="","",IF(jurnal[[#This Row],[Debit (Rp)]]=Sheet4!H11,"benar","salah")) -> benar | L27: =IF(jurnal[[#This Row],[Kredit (Rp)]]="","",IF(jurnal[[#This Row],[Kredit (Rp)]]=Sheet4!I11,"benar","salah")) -> benar
G28: PPN Keluaran | H28: – | I28: 9900000 | J28: =IF(jurnal[[#This Row],[Akun Jawaban]]="","",IF(jurnal[[#This Row],[Akun Jawaban]]=Sheet4!G12,"benar","salah")) -> benar | K28: =IF(jurnal[[#This Row],[Debit (Rp)]]="","",IF(jurnal[[#This Row],[Debit (Rp)]]=Sheet4!H12,"benar","salah")) -> benar | L28: =IF(jurnal[[#This Row],[Kredit (Rp)]]="","",IF(jurnal[[#This Row],[Kredit (Rp)]]=Sheet4!I12,"benar","salah")) -> benar
G29: HPP | H29: 50000000 | I29: – | J29: =IF(jurnal[[#This Row],[Akun Jawaban]]="","",IF(jurnal[[#This Row],[Akun Jawaban]]=Sheet4!G13,"benar","salah")) -> benar | K29: =IF(jurnal[[#This Row],[Debit (Rp)]]="","",IF(jurnal[[#This Row],[Debit (Rp)]]=Sheet4!H13,"benar","salah")) -> benar | L29: =IF(jurnal[[#This Row],[Kredit (Rp)]]="","",IF(jurnal[[#This Row],[Kredit (Rp)]]=Sheet4!I13,"benar","salah")) -> benar
G30: Persediaan Barang Dagang | H30: – | I30: 50000000 | J30: =IF(jurnal[[#This Row],[Akun Jawaban]]="","",IF(jurnal[[#This Row],[Akun Jawaban]]=Sheet4!G14,"benar","salah")) -> benar | K30: =IF(jurnal[[#This Row],[Debit (Rp)]]="","",IF(jurnal[[#This Row],[Debit (Rp)]]=Sheet4!H14,"benar","salah")) -> benar | L30: =IF(jurnal[[#This Row],[Kredit (Rp)]]="","",IF(jurnal[[#This Row],[Kredit (Rp)]]=Sheet4!I14,"benar","salah")) -> benar
A31: 4 | B31: Mudah / Retur pembelian | C31: Perusahaan mengembalikan barang kepada Supplier A sebesar Rp8.000.000 sebelum PPN karena rusak. | D31: PPN 11% dibatalkan; retur mengurangi utang. | E31: 8000000 | F31: Debit Utang Usaha; kredit Persediaan dan PPN Masukan. | G31: Utang Usaha | H31: 8880000 | I31: – | J31: =IF(jurnal[[#This Row],[Akun Jawaban]]="","",IF(jurnal[[#This Row],[Akun Jawaban]]=Sheet4!G15,"benar","salah")) -> benar | K31: =IF(jurnal[[#This Row],[Debit (Rp)]]="","",IF(jurnal[[#This Row],[Debit (Rp)]]=Sheet4!H15,"benar","salah")) -> benar | L31: =IF(jurnal[[#This Row],[Kredit (Rp)]]="","",IF(jurnal[[#This Row],[Kredit (Rp)]]=Sheet4!I15,"benar","salah")) -> benar
G32: Persediaan Barang Dagang | H32: – | I32: 8000000 | J32: =IF(jurnal[[#This Row],[Akun Jawaban]]="","",IF(jurnal[[#This Row],[Akun Jawaban]]=Sheet4!G16,"benar","salah")) -> benar | K32: =IF(jurnal[[#This Row],[Debit (Rp)]]="","",IF(jurnal[[#This Row],[Debit (Rp)]]=Sheet4!H16,"benar","salah")) -> benar | L32: =IF(jurnal[[#This Row],[Kredit (Rp)]]="","",IF(jurnal[[#This Row],[Kredit (Rp)]]=Sheet4!I16,"benar","salah")) -> benar
G33: PPN Masukan | H33: – | I33: 880000 | J33: =IF(jurnal[[#This Row],[Akun Jawaban]]="","",IF(jurnal[[#This Row],[Akun Jawaban]]=Sheet4!G17,"benar","salah")) -> benar | K33: =IF(jurnal[[#This Row],[Debit (Rp)]]="","",IF(jurnal[[#This Row],[Debit (Rp)]]=Sheet4!H17,"benar","salah")) -> benar | L33: =IF(jurnal[[#This Row],[Kredit (Rp)]]="","",IF(jurnal[[#This Row],[Kredit (Rp)]]=Sheet4!I17,"benar","salah")) -> benar
A34: 5 | B34: Menengah / Retur penjualan | C34: Pelanggan B mengembalikan barang yang sebelumnya dibeli sebesar Rp10.000.000 sebelum PPN. HPP barang yang kembali Rp6.000.000. | D34: PPN 11%; barang kembali ke persediaan. | E34: 10000000 | F34: Catat retur, pembalikan PPN, dan pemulihan persediaan/HPP. | G34: Retur Penjualan | H34: 10000000 | I34: – | J34: =IF(jurnal[[#This Row],[Akun Jawaban]]="","",IF(jurnal[[#This Row],[Akun Jawaban]]=Sheet4!G18,"benar","salah")) -> benar | K34: =IF(jurnal[[#This Row],[Debit (Rp)]]="","",IF(jurnal[[#This Row],[Debit (Rp)]]=Sheet4!H18,"benar","salah")) -> benar | L34: =IF(jurnal[[#This Row],[Kredit (Rp)]]="","",IF(jurnal[[#This Row],[Kredit (Rp)]]=Sheet4!I18,"benar","salah")) -> benar
G35: PPN Keluaran | H35: 1100000 | I35: – | J35: =IF(jurnal[[#This Row],[Akun Jawaban]]="","",IF(jurnal[[#This Row],[Akun Jawaban]]=Sheet4!G19,"benar","salah")) -> benar | K35: =IF(jurnal[[#This Row],[Debit (Rp)]]="","",IF(jurnal[[#This Row],[Debit (Rp)]]=Sheet4!H19,"benar","salah")) -> benar | L35: =IF(jurnal[[#This Row],[Kredit (Rp)]]="","",IF(jurnal[[#This Row],[Kredit (Rp)]]=Sheet4!I19,"benar","salah")) -> benar
G36: Piutang Usaha | H36: – | I36: 11100000 | J36: =IF(jurnal[[#This Row],[Akun Jawaban]]="","",IF(jurnal[[#This Row],[Akun Jawaban]]=Sheet4!G20,"benar","salah")) -> benar | K36: =IF(jurnal[[#This Row],[Debit (Rp)]]="","",IF(jurnal[[#This Row],[Debit (Rp)]]=Sheet4!H20,"benar","salah")) -> benar | L36: =IF(jurnal[[#This Row],[Kredit (Rp)]]="","",IF(jurnal[[#This Row],[Kredit (Rp)]]=Sheet4!I20,"benar","salah")) -> benar
G37: Persediaan Barang Dagang | H37: 6000000 | I37: – | J37: =IF(jurnal[[#This Row],[Akun Jawaban]]="","",IF(jurnal[[#This Row],[Akun Jawaban]]=Sheet4!G21,"benar","salah")) -> benar | K37: =IF(jurnal[[#This Row],[Debit (Rp)]]="","",IF(jurnal[[#This Row],[Debit (Rp)]]=Sheet4!H21,"benar","salah")) -> benar | L37: =IF(jurnal[[#This Row],[Kredit (Rp)]]="","",IF(jurnal[[#This Row],[Kredit (Rp)]]=Sheet4!I21,"benar","salah")) -> benar
G38: HPP | H38: – | I38: 6000000 | J38: =IF(jurnal[[#This Row],[Akun Jawaban]]="","",IF(jurnal[[#This Row],[Akun Jawaban]]=Sheet4!G22,"benar","salah")) -> benar | K38: =IF(jurnal[[#This Row],[Debit (Rp)]]="","",IF(jurnal[[#This Row],[Debit (Rp)]]=Sheet4!H22,"benar","salah")) -> benar | L38: =IF(jurnal[[#This Row],[Kredit (Rp)]]="","",IF(jurnal[[#This Row],[Kredit (Rp)]]=Sheet4!I22,"benar","salah")) -> benar
A39: 6 | B39: Menengah / Pembayaran utang | C39: Perusahaan membayar sebagian utang kepada Supplier A sebesar Rp50.000.000 melalui bank. | D39: Pelunasan sebagian; tidak ada diskon. | E39: 50000000 | F39: Debit Utang Usaha; kredit Bank. | G39: Utang Usaha | H39: 50000000 | I39: – | J39: =IF(jurnal[[#This Row],[Akun Jawaban]]="","",IF(jurnal[[#This Row],[Akun Jawaban]]=Sheet4!G23,"benar","salah")) -> benar | K39: =IF(jurnal[[#This Row],[Debit (Rp)]]="","",IF(jurnal[[#This Row],[Debit (Rp)]]=Sheet4!H23,"benar","salah")) -> benar | L39: =IF(jurnal[[#This Row],[Kredit (Rp)]]="","",IF(jurnal[[#This Row],[Kredit (Rp)]]=Sheet4!I23,"benar","salah")) -> benar
G40: Bank | H40: – | I40: 50000000 | J40: =IF(jurnal[[#This Row],[Akun Jawaban]]="","",IF(jurnal[[#This Row],[Akun Jawaban]]=Sheet4!G24,"benar","salah")) -> benar | K40: =IF(jurnal[[#This Row],[Debit (Rp)]]="","",IF(jurnal[[#This Row],[Debit (Rp)]]=Sheet4!H24,"benar","salah")) -> benar | L40: =IF(jurnal[[#This Row],[Kredit (Rp)]]="","",IF(jurnal[[#This Row],[Kredit (Rp)]]=Sheet4!I24,"benar","salah")) -> benar
A41: 7 | B41: Menengah / Beban utilitas | C41: Perusahaan membayar biaya listrik dan air Rp5.000.000 melalui bank. | D41: Tidak ada PPN dalam soal latihan. | E41: 5000000 | F41: Debit Beban Utilitas; kredit Bank. | G41: Beban Utilitas | H41: 5000000 | I41: – | J41: =IF(jurnal[[#This Row],[Akun Jawaban]]="","",IF(jurnal[[#This Row],[Akun Jawaban]]=Sheet4!G25,"benar","salah")) -> benar | K41: =IF(jurnal[[#This Row],[Debit (Rp)]]="","",IF(jurnal[[#This Row],[Debit (Rp)]]=Sheet4!H25,"benar","salah")) -> benar | L41: =IF(jurnal[[#This Row],[Kredit (Rp)]]="","",IF(jurnal[[#This Row],[Kredit (Rp)]]=Sheet4!I25,"benar","salah")) -> benar
G42: Bank | H42: – | I42: 5000000 | J42: =IF(jurnal[[#This Row],[Akun Jawaban]]="","",IF(jurnal[[#This Row],[Akun Jawaban]]=Sheet4!G26,"benar","salah")) -> benar | K42: =IF(jurnal[[#This Row],[Debit (Rp)]]="","",IF(jurnal[[#This Row],[Debit (Rp)]]=Sheet4!H26,"benar","salah")) -> benar | L42: =IF(jurnal[[#This Row],[Kredit (Rp)]]="","",IF(jurnal[[#This Row],[Kredit (Rp)]]=Sheet4!I26,"benar","salah")) -> benar
A43: 8 | B43: Menengah / Pembayaran gaji | C43: Perusahaan membayar gaji karyawan sebesar Rp12.000.000 melalui bank. | D43: Tidak ada potongan pajak dalam soal latihan. | E43: 12000000 | F43: Debit Beban Gaji; kredit Bank. | G43: Beban Gaji | H43: 12000000 | I43: – | J43: =IF(jurnal[[#This Row],[Akun Jawaban]]="","",IF(jurnal[[#This Row],[Akun Jawaban]]=Sheet4!G27,"benar","salah")) -> benar | K43: =IF(jurnal[[#This Row],[Debit (Rp)]]="","",IF(jurnal[[#This Row],[Debit (Rp)]]=Sheet4!H27,"benar","salah")) -> benar | L43: =IF(jurnal[[#This Row],[Kredit (Rp)]]="","",IF(jurnal[[#This Row],[Kredit (Rp)]]=Sheet4!I27,"benar","salah")) -> benar
G44: Bank | H44: – | I44: 12000000 | J44: =IF(jurnal[[#This Row],[Akun Jawaban]]="","",IF(jurnal[[#This Row],[Akun Jawaban]]=Sheet4!G28,"benar","salah")) -> benar | K44: =IF(jurnal[[#This Row],[Debit (Rp)]]="","",IF(jurnal[[#This Row],[Debit (Rp)]]=Sheet4!H28,"benar","salah")) -> benar | L44: =IF(jurnal[[#This Row],[Kredit (Rp)]]="","",IF(jurnal[[#This Row],[Kredit (Rp)]]=Sheet4!I28,"benar","salah")) -> benar
A45: 9 | B45: Sulit / Pembelian aset tunai | C45: Perusahaan membeli peralatan sebesar Rp30.000.000 sebelum PPN dan membayarnya melalui bank. | D45: PPN efektif 11%; peralatan siap digunakan. | E45: 30000000 | F45: Debit Peralatan dan PPN Masukan; kredit Bank. | G45: Peralatan | H45: 30000000 | I45: – | J45: =IF(jurnal[[#This Row],[Akun Jawaban]]="","",IF(jurnal[[#This Row],[Akun Jawaban]]=Sheet4!G29,"benar","salah")) -> benar | K45: =IF(jurnal[[#This Row],[Debit (Rp)]]="","",IF(jurnal[[#This Row],[Debit (Rp)]]=Sheet4!H29,"benar","salah")) -> benar | L45: =IF(jurnal[[#This Row],[Kredit (Rp)]]="","",IF(jurnal[[#This Row],[Kredit (Rp)]]=Sheet4!I29,"benar","salah")) -> benar
...

Sheet Sheet4
A1: No | B1: Tingkat / Jenis | C1: Soal | D1: Tambahan / Fakta Penting | E1: Nominal (Rp) | F1: Petunjuk | G1: Akun Jawaban | H1: Debit (Rp) | I1: Kredit (Rp)
A2: 1 | B2: Mudah / Pembelian persediaan kredit | C2: Perusahaan membeli persediaan dari Supplier A secara kredit sebesar Rp80.000.000 sebelum PPN. | D2: PPN latihan efektif 11%; satu invoice; belum dibayar. | E2: 80000000 | F2: Debit Persediaan dan PPN Masukan; kredit Utang Usaha. | G2: Persediaan Barang Dagang | H2: 80000000 | I2: –
G3: PPN Masukan | H3: 8800000 | I3: –
G4: Utang Usaha | H4: – | I4: 88800000
A5: 2 | B5: Mudah / Penjualan tunai | C5: Perusahaan menjual barang dagang secara tunai sebesar Rp120.000.000 sebelum PPN. HPP barang yang dijual sebesar Rp70.000.000. | D5: PPN 11%; sistem perpetual; dibayar melalui bank. | E5: 120000000 | F5: Buat dua kelompok jurnal: penjualan + PPN dan HPP + persediaan. | G5: Bank | H5: 133200000 | I5: –
G6: Penjualan | H6: – | I6: 120000000
G7: PPN Keluaran | H7: – | I7: 13200000
G8: HPP | H8: 70000000 | I8: –
G9: Persediaan Barang Dagang | H9: – | I9: 70000000
A10: 3 | B10: Mudah / Penjualan kredit | C10: Perusahaan menjual barang kepada Pelanggan B secara kredit sebesar Rp90.000.000 sebelum PPN. HPP barang yang dijual Rp50.000.000. | D10: PPN 11%; termin 30 hari. | E10: 90000000 | F10: Debit Piutang; kredit Penjualan dan PPN Keluaran; lalu HPP dan Persediaan. | G10: Piutang Usaha | H10: 99900000 | I10: –
G11: Penjualan | H11: – | I11: 90000000
G12: PPN Keluaran | H12: – | I12: 9900000
G13: HPP | H13: 50000000 | I13: –
G14: Persediaan Barang Dagang | H14: – | I14: 50000000
A15: 4 | B15: Mudah / Retur pembelian | C15: Perusahaan mengembalikan barang kepada Supplier A sebesar Rp8.000.000 sebelum PPN karena rusak. | D15: PPN 11% dibatalkan; retur mengurangi utang. | E15: 8000000 | F15: Debit Utang Usaha; kredit Persediaan dan PPN Masukan. | G15: Utang Usaha | H15: 8880000 | I15: –
G16: Persediaan Barang Dagang | H16: – | I16: 8000000
G17: PPN Masukan | H17: – | I17: 880000
A18: 5 | B18: Menengah / Retur penjualan | C18: Pelanggan B mengembalikan barang yang sebelumnya dibeli sebesar Rp10.000.000 sebelum PPN. HPP barang yang kembali Rp6.000.000. | D18: PPN 11%; barang kembali ke persediaan. | E18: 10000000 | F18: Catat retur, pembalikan PPN, dan pemulihan persediaan/HPP. | G18: Retur Penjualan | H18: 10000000 | I18: –
G19: PPN Keluaran | H19: 1100000 | I19: –
G20: Piutang Usaha | H20: – | I20: 11100000
G21: Persediaan Barang Dagang | H21: 6000000 | I21: –
G22: HPP | H22: – | I22: 6000000
A23: 6 | B23: Menengah / Pembayaran utang | C23: Perusahaan membayar sebagian utang kepada Supplier A sebesar Rp50.000.000 melalui bank. | D23: Pelunasan sebagian; tidak ada diskon. | E23: 50000000 | F23: Debit Utang Usaha; kredit Bank. | G23: Utang Usaha | H23: 50000000 | I23: –
G24: Bank | H24: – | I24: 50000000
A25: 7 | B25: Menengah / Beban utilitas | C25: Perusahaan membayar biaya listrik dan air Rp5.000.000 melalui bank. | D25: Tidak ada PPN dalam soal latihan. | E25: 5000000 | F25: Debit Beban Utilitas; kredit Bank. | G25: Beban Utilitas | H25: 5000000 | I25: –
G26: Bank | H26: – | I26: 5000000
A27: 8 | B27: Menengah / Pembayaran gaji | C27: Perusahaan membayar gaji karyawan sebesar Rp12.000.000 melalui bank. | D27: Tidak ada potongan pajak dalam soal latihan. | E27: 12000000 | F27: Debit Beban Gaji; kredit Bank. | G27: Beban Gaji | H27: 12000000 | I27: –
G28: Bank | H28: – | I28: 12000000
A29: 9 | B29: Sulit / Pembelian aset tunai | C29: Perusahaan membeli peralatan sebesar Rp30.000.000 sebelum PPN dan membayarnya melalui bank. | D29: PPN efektif 11%; peralatan siap digunakan. | E29: 30000000 | F29: Debit Peralatan dan PPN Masukan; kredit Bank. | G29: Peralatan | H29: 30000000 | I29: –
G30: PPN Masukan | H30: 3300000 | I30: –
G31: Bank | H31: – | I31: 33300000
A32: 10 | B32: Sulit / Rekonsiliasi PPN | C32: Pada akhir bulan perusahaan melakukan kompensasi PPN. PPN Keluaran sebesar Rp22.000.000 dan PPN Masukan sebesar Rp11.220.000. | D32: Selisih PPN menjadi Utang PPN sebesar Rp10.780.000. | E32: 22000000 | F32: Debit PPN Keluaran; kredit PPN Masukan dan Utang PPN. | G32: PPN Keluaran | H32: 22000000 | I32: –
G33: PPN Masukan | H33: – | I33: 11220000
G34: Utang PPN | H34: – | I34: 10780000

Sheet Sheet2
A1: C. LAPORAN LABA RUGI
A2: PT Sumber Pasok Abadi
A3: Laporan Laba Rugi
A4: Untuk Bulan Januari 2026
A6: Keterangan | B6: Jumlah
A7: Penjualan | B7: =Sheet1!I22+Sheet1!I27 -> 210000000
A8: Retur Penjualan | B8: =Sheet1!H34 -> 10000000
A9: Penjualan Bersih | B9: =B7-B8 -> 200000000
A11: HPP dari penjualan tunai | B11: =Sheet1!H24 -> 70000000
A12: HPP dari penjualan kredit | B12: =Sheet1!H29 -> 50000000
A13: Dikurangi: HPP barang retur | B13: =-Sheet1!I38 -> -6000000
A14: Harga Pokok Penjualan | B14: =SUM(B11:B13) -> 114000000
A16: Laba Kotor | B16: =B9-B14 -> 86000000
A17: Beban Utilitas | B17: =Sheet1!H41 -> 5000000
A18: Beban Gaji | B18: =Sheet1!H43 -> 12000000
A19: Total Beban Operasional | B19: =SUM(B17:B18) -> 17000000
A21: Laba Bersih | B21: =B16-B19 -> 69000000

Sheet Sheet3
A1: D. NERACA / LAPORAN POSISI KEUANGAN
A2: PT Sumber Pasok Abadi
A3: Laporan Posisi Keuangan
A4: Per 31 Januari 2026
A6: ASET
A8: Aset Lancar | B8: Jumlah
A9: Bank | B9: =Sheet1!C4+Sheet1!H21-SUM(Sheet1!I40,Sheet1!I42,Sheet1!I44,Sheet1!I47) -> 232900000
A10: Piutang Usaha | B10: =Sheet1!H26-Sheet1!I36 -> 88800000
A11: Persediaan Barang Dagang | B11: =Sheet1!C5+Sheet1!H18+Sheet1!H37-SUM(Sheet1!I25,Sheet1!I30,Sheet1!I32) -> 58000000
A12: Total Aset Lancar | B12: =SUM(B9:B11) -> 379700000
A13: Aset Tetap | B13: Jumlah
A14: Peralatan | B14: =Sheet1!C6+Sheet1!H45 -> 80000000
A15: Akumulasi Penyusutan Peralatan | B15: =-Sheet1!D7 -> -10000000
A16: Nilai Buku Peralatan | B16: =SUM(B14:B15) -> 70000000
A18: TOTAL ASET | B18: =B12+B16 -> 449700000
A21: LIABILITAS
A23: Liabilitas | B23: Jumlah
A24: Utang Usaha | B24: =Sheet1!D8+Sheet1!I20-SUM(Sheet1!H31,Sheet1!H39) -> 69920000
A25: Utang Bank Jangka Panjang | B25: =Sheet1!D9 -> 50000000
A26: Utang PPN | B26: =Sheet1!I50 -> 10780000
A27: TOTAL LIABILITAS | B27: =SUM(B24:B26) -> 130700000
A29: EKUITAS
A31: Ekuitas | B31: Jumlah
A32: Modal Saham | B32: =Sheet1!D10 -> 250000000
A33: Laba Bersih Januari | B33: =Sheet2!B21 -> 69000000
A34: TOTAL EKUITAS | B34: =SUM(B32:B33) -> 319000000
A36: CHECK
A38: Pemeriksaan | B38: Jumlah
A39: Total Aset | B39: =B18 -> 449700000
A40: Total Liabilitas + Ekuitas | B40: =B27+B34 -> 449700000
A41: Selisih | B41: =B39-B40 -> 0
A42: STATUS | B42: =IF(B41=0,"BALANCE ✅","TIDAK BALANCE ❌") -> BALANCE ✅
