Workbook

Sheet Dashboard_Accounting
A1: ACCOUNTING WORKBOOK DASHBOARD – PT SINAR NIAGA INDONESIA
A2: Panel kontrol workbook latihan: volume latihan, tie-out, performa, dan saldo utama.
A4: KPI | B4: Nilai | C4: Status | D4: Sumber | F4: P&L Snapshot | G4: Rp
A5: Jurnal Umum | B5: 80 soal | C5: READY | D5: Soal_dan_Jurnal | F5: Penjualan Bersih | G5: =Laba_Rugi!$B$8 -> 669400000
A6: Jurnal Penyesuaian | B6: 30 soal | C6: READY | D6: Jurnal_Penyesuaian | F6: HPP | G6: =Laba_Rugi!$B$9 -> 391400000
A7: COA | B7: 88 akun | C7: READY | D7: COA | F7: Laba Kotor | G7: =Laba_Rugi!$B$10 -> 278000000
A8: Saldo Awal | B8: 569.000.000 | C8: BALANCE | D8: Saldo_Awal | F8: Beban Operasi | G8: =Laba_Rugi!$B$37 -> 138550000
A9: Neraca Saldo | B9: =Neraca_Saldo!E92 -> 5752570000 | C9: =IF(ABS(Neraca_Saldo!E92-Neraca_Saldo!F92)<0.01,"BALANCE","PERIKSA") -> BALANCE | D9: Neraca_Saldo | F9: Laba Operasi | G9: =Laba_Rugi!$B$38 -> 139450000
A10: NS Setelah Penyesuaian | B10: =NS_Setelah_Penyesuaian!E92 -> 5899864000 | C10: =IF(ABS(NS_Setelah_Penyesuaian!E92-NS_Setelah_Penyesuaian!F92)<0.01,"BALANCE","PERIKSA") -> BALANCE | D10: NS_Setelah_Penyesuaian | F10: Laba Bersih | G10: =Laba_Rugi!$B$45 -> 134800000
A11: NS Setelah Penutupan | B11: =NS_Setelah_Penutupan!E92 -> 2514400000 | C11: =IF(ABS(NS_Setelah_Penutupan!E92-NS_Setelah_Penutupan!F92)<0.01,"BALANCE","PERIKSA") -> BALANCE | D11: NS_Setelah_Penutupan
A12: Rekonsiliasi Bank | B12: =Rekonsiliasi_Bank!B13 -> BALANCE | C12: =B12 -> BALANCE | D12: Rekonsiliasi_Bank
A13: AP Subledger | B13: =Rekap_AP!G11 -> 148400000 | C13: =Rekonsiliasi_Akun!E4 -> TIED | D13: Rekap_AP
A14: AR Subledger | B14: =Rekap_AR!I8 -> 116140000 | C14: =Rekonsiliasi_Akun!E5 -> TIED | D14: Rekap_AR
A15: Laba Bersih | B15: =Laba_Rugi!$B$45 -> 134800000 | C15: =IF(B15>=0,"PROFIT","LOSS") -> PROFIT | D15: Laba_Rugi
A16: Total Aset | B16: =Posisi_Keuangan!B28 -> 2456150000 | C16: =Posisi_Keuangan!E33 -> BALANCE | D16: Posisi_Keuangan

Sheet Petunjuk
A1: LATIHAN AKUNTANSI PERUSAHAAN DAGANG – WORKBOOK SIMULASI ACCOUNTING END-TO-END
A3: 1 | B3: Mulai dari Dashboard_Accounting untuk melihat status tie-out dan ringkasan workbook.
A4: 2 | B4: Baca Parameter_Latihan sebelum mengerjakan: periode, kebijakan perpetual/accrual, PPN/PPh, dan asumsi latihan.
A5: 3 | B5: Gunakan COA sebagai daftar akun resmi 88 akun. Jangan membuat akun baru sembarangan; gunakan akun yang paling spesifik.
A6: 4 | B6: Data_Master berisi supplier, customer, SKU, dan dokumen master untuk membuat kasus lebih realistis.
A7: 5 | B7: Saldo_Awal berisi posisi per 31-Des-2026 dan harus balance sebelum transaksi Januari dimasukkan.
A8: 6 | B8: Soal_dan_Jurnal berisi 80 kasus Basic → Intermediate → Advanced. Kolom J:L adalah area jawaban siswa.
A9: 7 | B9: Selesaikan setiap jurnal dengan menentukan tanggal, akun, debit, kredit, counterparty, dan dokumen pendukung.
A10: 8 | B10: Kolom M:P di Soal_dan_Jurnal adalah self-check otomatis terhadap Kunci_Jurnal_80.
A11: 9 | B11: Kunci_Jurnal_80 adalah jawaban pembanding mentor. Gunakan untuk review setelah latihan, bukan sebelum mengerjakan.
A12: 10 | B12: Buku_Besar memposting Saldo Awal + Jurnal Umum + Penyesuaian + Jurnal Penutup secara formula-driven.
A13: 11 | B13: Rekap_AP melatih invoice supplier, retur, pembayaran, diskon, dan aging saldo utang.
A14: 12 | B14: Rekap_AR melatih invoice customer, retur/rebate, NSF, penerimaan, write-off, dan aging saldo piutang.
... A21: 19 | B21: Gunakan Kamus_Rumus untuk memahami prinsip SUMIF/SUMIFS, saldo normal, rekonsiliasi, dan kontrol balance.

Sheet Parameter_Latihan
A1: PARAMETER & ASUMSI LATIHAN – JANGAN DISAMAKAN OTOMATIS DENGAN PERLAKUAN PAJAK RIIL
A3: Parameter | B3: Nilai | C3: Satuan | D3: Status | E3: Catatan | F3: Sumber
A4: Periode mulai | B4: 46388 | C4: tanggal | D4: Fixed | E4: Awal periode latihan | F4: Workbook
A5: Periode akhir | B5: 46418 | C5: tanggal | D5: Fixed | E5: Akhir periode latihan | F5: Workbook
A6: PPN tarif umum (referensi) | B6: 0.12 | C6: % | D6: Referensi | E6: Tarif umum berdasarkan rezim sejak 2025; konteks objek harus dicek. | F6: https://www.pajak.go.id/id/peraturan/harmonisasi-peraturan-perpajakan
A7: PPN efektif latihan | B7: 0.11 | C7: % | D7: Asumsi latihan | E7: Dipakai pada soal yang secara eksplisit menyatakan PPN latihan efektif 11%. | F7: https://stats.pajak.go.id/id/siaran-pers/pemerintah-terbitkan-aturan-dpp-nilai-lain-dan-besaran-tertentu-pajak-pertambahan-nilai
A8: PPh 23 jasa tertentu | B8: 0.02 | C8: % | D8: Referensi/latihan | E8: 2% dari jumlah bruto untuk jasa tertentu; kasus hanya menggunakan objek yang dinyatakan. | F8: https://www.pajak.go.id/id/pph-pasal-23
A9: PPh Final sewa tanah/bangunan | B9: 0.1 | C9: % | D9: Referensi | E9: 10% dari jumlah bruto sewa tanah/bangunan. | F9: https://pajak.go.id/id/pph-pasal-4-ayat-2
A10: PPh 22 pembelian oleh pemungut tertentu | B10: 0.015 | C10: % | D10: Referensi/latihan | E10: 1,5% dari harga pembelian tidak termasuk PPN pada konteks pemungut tertentu. | F10: https://pajak.go.id/pph-pasal-22
A11: PPh 22 impor API | B11: 0.025 | C11: % | D11: Referensi/latihan | E11: 2,5% dari nilai impor untuk impor dengan API. | F11: https://pajak.go.id/pph-pasal-22
A12: PPh 21 | C12: Rp | D12: Asumsi latihan | E12: Nominal pajak ditetapkan per soal; simulasi detail payroll ada di sheet Payroll. | F12: https://stats.pajak.go.id/id/artikel/tarif-efektif-rata-rata-penyempurnaan-perhitungan-pph-pasal-21
A13: Metode persediaan | B13: Perpetual | C13: metode | D13: Fixed | E13: HPP dicatat saat penjualan. | F13: Workbook
A14: Metode kartu persediaan | B14: FIFO | C14: metode | D14: Asumsi latihan | E14: Untuk modul kartu persediaan per SKU. | F14: Workbook
A15: Dasar pencatatan | B15: Accrual basis | C15: basis | D15: Fixed | E15: Akui hak/kewajiban saat terjadi. | F15: Workbook
A16: Mata uang | B16: Rupiah | C16: IDR | D16: Fixed | E16: Semua angka dalam Rp. | F16: Workbook

Sheet COA
A1: CHART OF ACCOUNTS – PT SINAR NIAGA INDONESIA
A4: Kode Akun | B4: Nama Akun | C4: Kategori | D4: Saldo Normal | E4: Kelompok Laporan
A5: 1-001 | B5: Bank | C5: Aset | D5: Debit | E5: Posisi Keuangan - Aset Lancar
A6: 1-002 | B6: Kas Kecil | C6: Aset | D6: Debit | E6: Posisi Keuangan - Aset Lancar
A7: 1-003 | B7: Piutang Usaha | C7: Aset | D7: Debit | E7: Posisi Keuangan - Aset Lancar
A8: 1-004 | B8: Piutang Karyawan | C8: Aset | D8: Debit | E8: Posisi Keuangan - Aset Lancar
A9: 1-005 | B9: Piutang Bunga | C9: Aset | D9: Debit | E9: Posisi Keuangan - Aset Lancar
A10: 1-006 | B10: Piutang Pendapatan | C10: Aset | D10: Debit | E10: Posisi Keuangan - Aset Lancar
A11: 1-007 | B11: Persediaan Barang Dagang | C11: Aset | D11: Debit | E11: Posisi Keuangan - Aset Lancar
A12: 1-008 | B12: PPN Masukan | C12: Aset | D12: Debit | E12: Posisi Keuangan - Aset Lancar
A13: 1-009 | B13: PPh 22 Dibayar di Muka | C13: Aset | D13: Debit | E13: Posisi Keuangan - Aset Lancar
A14: 1-010 | B14: PPh 23 Dibayar di Muka | C14: Aset | D14: Debit | E14: Posisi Keuangan - Aset Lancar
A15: 1-011 | B15: PPh Final Dibayar di Muka | C15: Aset | D15: Debit | E15: Posisi Keuangan - Aset Lancar
... A92: 2-021 | B92: PPN Keluaran | C92: Liabilitas | D92: Kredit | E92: Posisi Keuangan - Liabilitas Lancar

Sheet Data_Master
A1: DATA MASTER – SUPPLIER, CUSTOMER, SKU, DAN TERMS
A4: Supplier Code | B4: Supplier | C4: Payment Terms | D4: PPh/Pajak Case | E4: Contact / Note | F4: Column1 | G4: Customer Code | H4: Customer | I4: Credit Limit | J4: Terms | K4: Note
A5: SUP-A | B5: Supplier A | C5: 30 hari | D5: Pemasok barang dagang | E5: Supplier utama | G5: CUS-B | H5: Pelanggan B | I5: 300000000 | J5: 30 hari | K5: AR utama
A6: SUP-B | B6: Supplier B | C6: 14 hari | D6: Pemasok barang dagang | E6: Rebate volume | G6: CUS-C | H6: Pelanggan C | I6: 100000000 | J6: DP | K6: Customer advance
A7: SUP-C | B7: PT Perkasa Office | C7: 30 hari | D7: Aset tetap | E7: Peralatan toko | G7: CUS-D | H7: Pelanggan D | I7: 350000000 | J7: 45 hari | K7: Volume rebate
A8: SUP-D | B8: PT Kantor Jaya | C8: 30 hari | D8: Aset tetap | E8: Peralatan kantor | G8: CUS-E | H8: Pelanggan E | I8: 100000000 | J8: 14 hari | K8: Early payment discount
A9: SUP-E | B9: Supplier E | C9: 30 hari | D9: Uang muka | E9: Skenario advance | G9: CUS-F | H9: Pelanggan F | I9: 150000000 | J9: 30 hari | K9: Partial collection
A10: SUP-F | B10: Supplier F | C10: Immediate | D10: Pembelian tunai | E10: Diskon pembelian | G10: CUS-G | H10: Pelanggan Umum | I10: 100000000 | J10: Cash | K10: Retail/cash sales
A11: SUP-G | B11: Supplier G | C11: 14 hari | D11: Pemasok barang dagang | E11: Transaksi akhir | G11: CUS-H | H11: Pelanggan H | I11: 100000000 | J11: 30 hari | K11: Aged AR practice
A12: SUP-H | B12: Toko ATK Nusantara | C12: 30 hari | D12: Perlengkapan | E12: Invoice ATK | G12: CUS-I | H12: Pelanggan I | I12: 100000000 | J12: 30 hari | K12: AR practice
A13: SUP-I | B13: PT Gudang Sentosa | C13: Bulanan | D13: Sewa gedung | E13: PPh Final 4(2)
A14: SUP-J | B14: Kantor Konsultan Prima | C14: 14 hari | D14: Jasa profesional | E14: PPh 23
A15: SUP-K | B15: PT Garda Aman | C15: 14 hari | D15: Jasa keamanan | E15: PPh 23
A17: SKU | B17: Nama Barang | C17: Unit | D17: Cost Awal | E17: Harga Jual | F17: Reorder Point | G17: Keterangan
A18: SKU-01 | B18: Printer Ink | C18: unit | D18: 2500000 | E18: 4000000 | F18: 10 | G18: Barang elektronik kantor
A19: SKU-02 | B19: Laptop Bisnis | C19: unit | D19: 7000000 | E19: 10000000 | F19: 5 | G19: Barang bernilai tinggi
A20: SKU-03 | B20: Kertas A4 | C20: rim | D20: 45000 | E20: 75000 | F20: 100 | G20: Fast moving
A21: SKU-04 | B21: Toner | C21: unit | D21: 1500000 | E21: 2400000 | F21: 20 | G21: Office consumable
A22: SKU-05 | B22: Monitor | C22: unit | D22: 1800000 | E22: 3000000 | F22: 10 | G22: Barang elektronik
A23: SKU-06 | B23: Keyboard | C23: unit | D23: 350000 | E23: 600000 | F23: 25 | G23: Office accessory
A24: SKU-07 | B24: Mouse | C24: unit | D24: 200000 | E24: 350000 | F24: 25 | G24: Office accessory
A25: SKU-08 | B25: Router | C25: unit | D25: 900000 | E25: 1500000 | F25: 15 | G25: Networking

Sheet Soal_dan_Jurnal
A1: LATIHAN 80 SOAL – JURNAL UMUM PERUSAHAAN DAGANG | BASIC → ADVANCED
A2: Isi kolom J:L untuk menjawab. H:I sudah disiapkan sebagai identitas baris. M:O memeriksa akun/debit/kredit terhadap Kunci_Jurnal_80. P menunjukkan status baris.
A3: No | B3: Tanggal | C3: Tingkat / Jenis | D3: Soal | E3: Tambahan / Fakta Penting | F3: Nominal (Rp) | G3: Petunjuk | H3: No2 | I3: Tanggal2 | J3: Akun Jawaban | K3: Debit Jawaban | L3: Kredit Jawaban | M3: Cek Akun | N3: Cek Debit | O3: Cek Kredit
A4: 1 | B4: 46388 | C4: Mudah / Setoran modal | D4: Pemegang saham menyetor modal tunai Rp1.500.000.000 ke rekening bank perusahaan. | E4: Setoran penuh; tidak ada biaya penerbitan saham. | F4: 1500000000 | G4: Debit Bank; kredit Modal Saham. | H4: 1 | I4: 46388 | J4: bank | K4: 1500000000 | L4: 0 | M4: =IF(Table3[[#This Row],[Akun Jawaban]]="","",IF(Table3[[#This Row],[Akun Jawaban]]=Table4[[#This Row],[Akun]],"Benar","salah")) -> Benar | N4: =IF(Table3[[#This Row],[Debit Jawaban]]="","",IF(Table3[[#This Row],[Debit Jawaban]]=Table4[[#This Row],[Debit (Rp)]],"Benar","salah")) -> Benar | O4: =IF(Table3[[#This Row],[Kredit Jawaban]]="","",IF(Table3[[#This Row],[Kredit Jawaban]]=Table4[[#This Row],[Kredit (Rp)]],"Benar","salah")) -> Benar
G5: Debit Bank; kredit Modal Saham. | H5: 1 | I5: 46388 | J5: modal saham | K5: 0 | L5: 1500000000 | M5: =IF(Table3[[#This Row],[Akun Jawaban]]="","",IF(Table3[[#This Row],[Akun Jawaban]]=Table4[[#This Row],[Akun]],"Benar","salah")) -> Benar | N5: =IF(Table3[[#This Row],[Debit Jawaban]]="","",IF(Table3[[#This Row],[Debit Jawaban]]=Table4[[#This Row],[Debit (Rp)]],"Benar","salah")) -> Benar | O5: =IF(Table3[[#This Row],[Kredit Jawaban]]="","",IF(Table3[[#This Row],[Kredit Jawaban]]=Table4[[#This Row],[Kredit (Rp)]],"Benar","salah")) -> Benar
A6: 2 | B6: 46388 | C6: Mudah / Transfer kas kecil | D6: Perusahaan memindahkan Rp20.000.000 dari bank ke kas kecil. | E6: Hanya perpindahan antar akun kas. | F6: 20000000 | G6: Debit Kas Kecil; kredit Bank. | H6: 2 | I6: 46388 | J6: kas kecil | K6: 20000000 | M6: =IF(Table3[[#This Row],[Akun Jawaban]]="","",IF(Table3[[#This Row],[Akun Jawaban]]=Table4[[#This Row],[Akun]],"Benar","salah")) -> Benar | N6: =IF(Table3[[#This Row],[Debit Jawaban]]="","",IF(Table3[[#This Row],[Debit Jawaban]]=Table4[[#This Row],[Debit (Rp)]],"Benar","salah")) -> Benar | O6: =IF(Table3[[#This Row],[Kredit Jawaban]]="","",IF(Table3[[#This Row],[Kredit Jawaban]]=Table4[[#This Row],[Kredit (Rp)]],"Benar","salah"))
G7: Debit Kas Kecil; kredit Bank. | H7: 2 | I7: 46388 | J7: bank | L7: 20000000 | M7: =IF(Table3[[#This Row],[Akun Jawaban]]="","",IF(Table3[[#This Row],[Akun Jawaban]]=Table4[[#This Row],[Akun]],"Benar","salah")) -> Benar | N7: =IF(Table3[[#This Row],[Debit Jawaban]]="","",IF(Table3[[#This Row],[Debit Jawaban]]=Table4[[#This Row],[Debit (Rp)]],"Benar","salah")) | O7: =IF(Table3[[#This Row],[Kredit Jawaban]]="","",IF(Table3[[#This Row],[Kredit Jawaban]]=Table4[[#This Row],[Kredit (Rp)]],"Benar","salah")) -> Benar
A8: 3 | B8: 46389 | C8: Mudah / Pembelian aset tunai | D8: Perusahaan membeli peralatan toko Rp60.000.000 sebelum PPN. PPN latihan efektif 11%. | E8: Dibayar melalui bank; peralatan siap digunakan. | F8: 60000000 | G8: Debit Peralatan Toko, PPN Masukan; kredit Bank. | H8: 3 | I8: 46389 | J8: peralatan toko | K8: 60000000 | M8: =IF(Table3[[#This Row],[Akun Jawaban]]="","",IF(Table3[[#This Row],[Akun Jawaban]]=Table4[[#This Row],[Akun]],"Benar","salah")) -> Benar | N8: =IF(Table3[[#This Row],[Debit Jawaban]]="","",IF(Table3[[#This Row],[Debit Jawaban]]=Table4[[#This Row],[Debit (Rp)]],"Benar","salah")) -> Benar | O8: =IF(Table3[[#This Row],[Kredit Jawaban]]="","",IF(Table3[[#This Row],[Kredit Jawaban]]=Table4[[#This Row],[Kredit (Rp)]],"Benar","salah"))
G9: Debit Peralatan Toko, PPN Masukan; kredit Bank. | H9: 3 | I9: 46389 | J9: ppn masukan | K9: =11%*60000000 -> 6600000 | M9: =IF(Table3[[#This Row],[Akun Jawaban]]="","",IF(Table3[[#This Row],[Akun Jawaban]]=Table4[[#This Row],[Akun]],"Benar","salah")) -> Benar | N9: =IF(Table3[[#This Row],[Debit Jawaban]]="","",IF(Table3[[#This Row],[Debit Jawaban]]=Table4[[#This Row],[Debit (Rp)]],"Benar","salah")) -> Benar | O9: =IF(Table3[[#This Row],[Kredit Jawaban]]="","",IF(Table3[[#This Row],[Kredit Jawaban]]=Table4[[#This Row],[Kredit (Rp)]],"Benar","salah"))
H10: 3 | I10: 46389 | J10: bank | L10: =SUM(K8:K9) -> 66600000 | M10: =IF(Table3[[#This Row],[Akun Jawaban]]="","",IF(Table3[[#This Row],[Akun Jawaban]]=Table4[[#This Row],[Akun]],"Benar","salah")) -> Benar | N10: =IF(Table3[[#This Row],[Debit Jawaban]]="","",IF(Table3[[#This Row],[Debit Jawaban]]=Table4[[#This Row],[Debit (Rp)]],"Benar","salah")) | O10: =IF(Table3[[#This Row],[Kredit Jawaban]]="","",IF(Table3[[#This Row],[Kredit Jawaban]]=Table4[[#This Row],[Kredit (Rp)]],"Benar","salah")) -> Benar
A11: 4 | B11: 46390 | C11: Mudah / Pembelian aset kredit | D11: Perusahaan membeli peralatan kantor Rp40.000.000 sebelum PPN. PPN latihan efektif 11%. | E11: Satu invoice; belum dibayar. | F11: 40000000 | G11: Debit Peralatan Kantor, PPN Masukan; kredit Utang Usaha. | H11: 4 | I11: 46390 | J11: peralatan kantor | K11: 40000000 | M11: =IF(Table3[[#This Row],[Akun Jawaban]]="","",IF(Table3[[#This Row],[Akun Jawaban]]=Table4[[#This Row],[Akun]],"Benar","salah")) -> Benar | N11: =IF(Table3[[#This Row],[Debit Jawaban]]="","",IF(Table3[[#This Row],[Debit Jawaban]]=Table4[[#This Row],[Debit (Rp)]],"Benar","salah")) -> Benar | O11: =IF(Table3[[#This Row],[Kredit Jawaban]]="","",IF(Table3[[#This Row],[Kredit Jawaban]]=Table4[[#This Row],[Kredit (Rp)]],"Benar","salah"))
G12: Debit Peralatan Kantor, PPN Masukan; kredit Utang Usaha. | H12: 4 | I12: 46390 | J12: ppn masukan | K12: =11%*40000000 -> 4400000 | M12: =IF(Table3[[#This Row],[Akun Jawaban]]="","",IF(Table3[[#This Row],[Akun Jawaban]]=Table4[[#This Row],[Akun]],"Benar","salah")) -> Benar | N12: =IF(Table3[[#This Row],[Debit Jawaban]]="","",IF(Table3[[#This Row],[Debit Jawaban]]=Table4[[#This Row],[Debit (Rp)]],"Benar","salah")) -> Benar | O12: =IF(Table3[[#This Row],[Kredit Jawaban]]="","",IF(Table3[[#This Row],[Kredit Jawaban]]=Table4[[#This Row],[Kredit (Rp)]],"Benar","salah"))
H13: 4 | I13: 46390 | J13: utang usaha | L13: =SUM(K11:K12) -> 44400000 | M13: =IF(Table3[[#This Row],[Akun Jawaban]]="","",IF(Table3[[#This Row],[Akun Jawaban]]=Table4[[#This Row],[Akun]],"Benar","salah")) -> Benar | N13: =IF(Table3[[#This Row],[Debit Jawaban]]="","",IF(Table3[[#This Row],[Debit Jawaban]]=Table4[[#This Row],[Debit (Rp)]],"Benar","salah")) | O13: =IF(Table3[[#This Row],[Kredit Jawaban]]="","",IF(Table3[[#This Row],[Kredit Jawaban]]=Table4[[#This Row],[Kredit (Rp)]],"Benar","salah")) -> Benar
A14: 5 | B14: 46390 | C14: Mudah / Pembelian persediaan kredit | D14: Perusahaan membeli persediaan dari Supplier A secara kredit Rp250.000.000 sebelum PPN. | E14: PPN latihan efektif 11%; satu invoice; belum dibayar. | F14: 250000000 | G14: Debit Persediaan, PPN Masukan; kredit Utang Usaha. | H14: 5 | I14: 46390 | J14: persediaan barang dagang | K14: 250000000 | M14: =IF(Table3[[#This Row],[Akun Jawaban]]="","",IF(Table3[[#This Row],[Akun Jawaban]]=Table4[[#This Row],[Akun]],"Benar","salah")) -> Benar | N14: =IF(Table3[[#This Row],[Debit Jawaban]]="","",IF(Table3[[#This Row],[Debit Jawaban]]=Table4[[#This Row],[Debit (Rp)]],"Benar","salah")) -> Benar | O14: =IF(Table3[[#This Row],[Kredit Jawaban]]="","",IF(Table3[[#This Row],[Kredit Jawaban]]=Table4[[#This Row],[Kredit (Rp)]],"Benar","salah"))
G15: Debit Persediaan, PPN Masukan; kredit Utang Usaha. | H15: 5 | I15: 46390 | J15: ppn masukan | K15: =11%*250000000 -> 27500000 | M15: =IF(Table3[[#This Row],[Akun Jawaban]]="","",IF(Table3[[#This Row],[Akun Jawaban]]=Table4[[#This Row],[Akun]],"Benar","salah")) -> Benar | N15: =IF(Table3[[#This Row],[Debit Jawaban]]="","",IF(Table3[[#This Row],[Debit Jawaban]]=Table4[[#This Row],[Debit (Rp)]],"Benar","salah")) -> Benar | O15: =IF(Table3[[#This Row],[Kredit Jawaban]]="","",IF(Table3[[#This Row],[Kredit Jawaban]]=Table4[[#This Row],[Kredit (Rp)]],"Benar","salah"))
H16: 5 | I16: 46390 | J16: utang usaha | L16: =SUM(K14:K15) -> 277500000 | M16: =IF(Table3[[#This Row],[Akun Jawaban]]="","",IF(Table3[[#This Row],[Akun Jawaban]]=Table4[[#This Row],[Akun]],"Benar","salah")) -> Benar | N16: =IF(Table3[[#This Row],[Debit Jawaban]]="","",IF(Table3[[#This Row],[Debit Jawaban]]=Table4[[#This Row],[Debit (Rp)]],"Benar","salah")) | O16: =IF(Table3[[#This Row],[Kredit Jawaban]]="","",IF(Table3[[#This Row],[Kredit Jawaban]]=Table4[[#This Row],[Kredit (Rp)]],"Benar","salah")) -> Benar
A17: 6 | B17: 46391 | C17: Mudah / Pembelian persediaan tunai | D17: Perusahaan membeli persediaan Rp100.000.000 sebelum PPN dari Supplier B secara kredit. | E17: PPN latihan efektif 11%; termin 14 hari. | F17: 100000000 | G17: Debit Persediaan, PPN Masukan; kredit Utang Usaha. | H17: 6 | I17: 46391 | J17: persediaan barang dagang | K17: 100000000 | M17: =IF(Table3[[#This Row],[Akun Jawaban]]="","",IF(Table3[[#This Row],[Akun Jawaban]]=Table4[[#This Row],[Akun]],"Benar","salah")) -> Benar | N17: =IF(Table3[[#This Row],[Debit Jawaban]]="","",IF(Table3[[#This Row],[Debit Jawaban]]=Table4[[#This Row],[Debit (Rp)]],"Benar","salah")) -> Benar | O17: =IF(Table3[[#This Row],[Kredit Jawaban]]="","",IF(Table3[[#This Row],[Kredit Jawaban]]=Table4[[#This Row],[Kredit (Rp)]],"Benar","salah"))
G18: Debit Persediaan, PPN Masukan; kredit Utang Usaha. | H18: 6 | I18: 46391 | J18: ppn masukan | K18: =11%*100000000 -> 11000000 | M18: =IF(Table3[[#This Row],[Akun Jawaban]]="","",IF(Table3[[#This Row],[Akun Jawaban]]=Table4[[#This Row],[Akun]],"Benar","salah")) -> Benar | N18: =IF(Table3[[#This Row],[Debit Jawaban]]="","",IF(Table3[[#This Row],[Debit Jawaban]]=Table4[[#This Row],[Debit (Rp)]],"Benar","salah")) -> Benar | O18: =IF(Table3[[#This Row],[Kredit Jawaban]]="","",IF(Table3[[#This Row],[Kredit Jawaban]]=Table4[[#This Row],[Kredit (Rp)]],"Benar","salah"))
H19: 6 | I19: 46391 | J19: utang usaha | L19: =SUM(K17:K18) -> 111000000 | M19: =IF(Table3[[#This Row],[Akun Jawaban]]="","",IF(Table3[[#This Row],[Akun Jawaban]]=Table4[[#This Row],[Akun]],"Benar","salah")) -> Benar | N19: =IF(Table3[[#This Row],[Debit Jawaban]]="","",IF(Table3[[#This Row],[Debit Jawaban]]=Table4[[#This Row],[Debit (Rp)]],"Benar","salah")) | O19: =IF(Table3[[#This Row],[Kredit Jawaban]]="","",IF(Table3[[#This Row],[Kredit Jawaban]]=Table4[[#This Row],[Kredit (Rp)]],"Benar","salah")) -> Benar
A20: 7 | B20: 46391 | C20: Mudah / Freight-in | D20: Perusahaan membayar ongkos angkut pembelian Rp4.000.000 melalui bank. Ongkos angkut menambah biaya perolehan persediaan. | E20: Sistem perpetual; freight-in dikapitalisasi. | F20: 4000000 | G20: Debit Persediaan; kredit Bank. | H20: 7 | I20: 46391 | J20: persediaan barang dagang | K20: 4000000 | M20: =IF(Table3[[#This Row],[Akun Jawaban]]="","",IF(Table3[[#This Row],[Akun Jawaban]]=Table4[[#This Row],[Akun]],"Benar","salah")) -> Benar | N20: =IF(Table3[[#This Row],[Debit Jawaban]]="","",IF(Table3[[#This Row],[Debit Jawaban]]=Table4[[#This Row],[Debit (Rp)]],"Benar","salah")) -> Benar | O20: =IF(Table3[[#This Row],[Kredit Jawaban]]="","",IF(Table3[[#This Row],[Kredit Jawaban]]=Table4[[#This Row],[Kredit (Rp)]],"Benar","salah"))
G21: Debit Persediaan; kredit Bank. | H21: 7 | I21: 46391 | J21: bank | L21: 4000000 | M21: =IF(Table3[[#This Row],[Akun Jawaban]]="","",IF(Table3[[#This Row],[Akun Jawaban]]=Table4[[#This Row],[Akun]],"Benar","salah")) -> Benar | N21: =IF(Table3[[#This Row],[Debit Jawaban]]="","",IF(Table3[[#This Row],[Debit Jawaban]]=Table4[[#This Row],[Debit (Rp)]],"Benar","salah")) | O21: =IF(Table3[[#This Row],[Kredit Jawaban]]="","",IF(Table3[[#This Row],[Kredit Jawaban]]=Table4[[#This Row],[Kredit (Rp)]],"Benar","salah")) -> Benar
A22: 8 | B22: 46392 | C22: Mudah / Penjualan tunai | D22: Perusahaan menjual barang secara tunai Rp120.000.000 sebelum PPN. HPP Rp70.000.000. | E22: PPN latihan efektif 11%; perpetual. | F22: 120000000 | G22: Buat dua kelompok jurnal: penjualan + PPN dan HPP + persediaan. | H22: 8 | I22: 46392 | J22: bank | K22: =SUM(L23:L24) -> 133200000 | M22: =IF(Table3[[#This Row],[Akun Jawaban]]="","",IF(Table3[[#This Row],[Akun Jawaban]]=Table4[[#This Row],[Akun]],"Benar","salah")) -> Benar | N22: =IF(Table3[[#This Row],[Debit Jawaban]]="","",IF(Table3[[#This Row],[Debit Jawaban]]=Table4[[#This Row],[Debit (Rp)]],"Benar","salah")) -> Benar | O22: =IF(Table3[[#This Row],[Kredit Jawaban]]="","",IF(Table3[[#This Row],[Kredit Jawaban]]=Table4[[#This Row],[Kredit (Rp)]],"Benar","salah"))
G23: Buat dua kelompok jurnal: penjualan + PPN dan HPP + persediaan. | H23: 8 | I23: 46392 | J23: penjualan | L23: 120000000 | M23: =IF(Table3[[#This Row],[Akun Jawaban]]="","",IF(Table3[[#This Row],[Akun Jawaban]]=Table4[[#This Row],[Akun]],"Benar","salah")) -> Benar | N23: =IF(Table3[[#This Row],[Debit Jawaban]]="","",IF(Table3[[#This Row],[Debit Jawaban]]=Table4[[#This Row],[Debit (Rp)]],"Benar","salah")) | O23: =IF(Table3[[#This Row],[Kredit Jawaban]]="","",IF(Table3[[#This Row],[Kredit Jawaban]]=Table4[[#This Row],[Kredit (Rp)]],"Benar","salah")) -> Benar
H24: 8 | I24: 46392 | J24: ppn keluaran | L24: =11%*120000000 -> 13200000 | M24: =IF(Table3[[#This Row],[Akun Jawaban]]="","",IF(Table3[[#This Row],[Akun Jawaban]]=Table4[[#This Row],[Akun]],"Benar","salah")) -> Benar | N24: =IF(Table3[[#This Row],[Debit Jawaban]]="","",IF(Table3[[#This Row],[Debit Jawaban]]=Table4[[#This Row],[Debit (Rp)]],"Benar","salah")) | O24: =IF(Table3[[#This Row],[Kredit Jawaban]]="","",IF(Table3[[#This Row],[Kredit Jawaban]]=Table4[[#This Row],[Kredit (Rp)]],"Benar","salah")) -> Benar
H25: 8 | I25: 46392 | J25: hpp | K25: 70000000 | M25: =IF(Table3[[#This Row],[Akun Jawaban]]="","",IF(Table3[[#This Row],[Akun Jawaban]]=Table4[[#This Row],[Akun]],"Benar","salah")) -> Benar | N25: =IF(Table3[[#This Row],[Debit Jawaban]]="","",IF(Table3[[#This Row],[Debit Jawaban]]=Table4[[#This Row],[Debit (Rp)]],"Benar","salah")) -> Benar | O25: =IF(Table3[[#This Row],[Kredit Jawaban]]="","",IF(Table3[[#This Row],[Kredit Jawaban]]=Table4[[#This Row],[Kredit (Rp)]],"Benar","salah"))
H26: 8 | I26: 46392 | J26: persediaan barang dagang | L26: 70000000 | M26: =IF(Table3[[#This Row],[Akun Jawaban]]="","",IF(Table3[[#This Row],[Akun Jawaban]]=Table4[[#This Row],[Akun]],"Benar","salah")) -> Benar | N26: =IF(Table3[[#This Row],[Debit Jawaban]]="","",IF(Table3[[#This Row],[Debit Jawaban]]=Table4[[#This Row],[Debit (Rp)]],"Benar","salah")) | O26: =IF(Table3[[#This Row],[Kredit Jawaban]]="","",IF(Table3[[#This Row],[Kredit Jawaban]]=Table4[[#This Row],[Kredit (Rp)]],"Benar","salah")) -> Benar
A27: 9 | B27: 46393 | C27: Mudah / Penjualan kredit | D27: Perusahaan menjual barang secara kredit kepada Pelanggan B Rp160.000.000 sebelum PPN. HPP Rp95.000.000. | E27: PPN latihan efektif 11%; termin 30 hari. | F27: 160000000 | G27: Debit Piutang; kredit Penjualan dan PPN Keluaran; lalu HPP dan Persediaan. | H27: 9 | I27: 46393 | J27: piutang usaha | K27: =SUM(L28:L29) -> 177600000 | M27: =IF(Table3[[#This Row],[Akun Jawaban]]="","",IF(Table3[[#This Row],[Akun Jawaban]]=Table4[[#This Row],[Akun]],"Benar","salah")) -> Benar | N27: =IF(Table3[[#This Row],[Debit Jawaban]]="","",IF(Table3[[#This Row],[Debit Jawaban]]=Table4[[#This Row],[Debit (Rp)]],"Benar","salah")) -> Benar | O27: =IF(Table3[[#This Row],[Kredit Jawaban]]="","",IF(Table3[[#This Row],[Kredit Jawaban]]=Table4[[#This Row],[Kredit (Rp)]],"Benar","salah"))
G28: Debit Piutang; kredit Penjualan dan PPN Keluaran; lalu HPP dan Persediaan. | H28: 9 | I28: 46393 | J28: penjualan | L28: 160000000 | M28: =IF(Table3[[#This Row],[Akun Jawaban]]="","",IF(Table3[[#This Row],[Akun Jawaban]]=Table4[[#This Row],[Akun]],"Benar","salah")) -> Benar | N28: =IF(Table3[[#This Row],[Debit Jawaban]]="","",IF(Table3[[#This Row],[Debit Jawaban]]=Table4[[#This Row],[Debit (Rp)]],"Benar","salah")) | O28: =IF(Table3[[#This Row],[Kredit Jawaban]]="","",IF(Table3[[#This Row],[Kredit Jawaban]]=Table4[[#This Row],[Kredit (Rp)]],"Benar","salah")) -> Benar
H29: 9 | I29: 46393 | J29: ppn keluaran | L29: =11%*L28 -> 17600000 | M29: =IF(Table3[[#This Row],[Akun Jawaban]]="","",IF(Table3[[#This Row],[Akun Jawaban]]=Table4[[#This Row],[Akun]],"Benar","salah")) -> Benar | N29: =IF(Table3[[#This Row],[Debit Jawaban]]="","",IF(Table3[[#This Row],[Debit Jawaban]]=Table4[[#This Row],[Debit (Rp)]],"Benar","salah")) | O29: =IF(Table3[[#This Row],[Kredit Jawaban]]="","",IF(Table3[[#This Row],[Kredit Jawaban]]=Table4[[#This Row],[Kredit (Rp)]],"Benar","salah")) -> Benar
H30: 9 | I30: 46393 | J30: hpp | K30: 95000000 | M30: =IF(Table3[[#This Row],[Akun Jawaban]]="","",IF(Table3[[#This Row],[Akun Jawaban]]=Table4[[#This Row],[Akun]],"Benar","salah")) -> Benar | N30: =IF(Table3[[#This Row],[Debit Jawaban]]="","",IF(Table3[[#This Row],[Debit Jawaban]]=Table4[[#This Row],[Debit (Rp)]],"Benar","salah")) -> Benar | O30: =IF(Table3[[#This Row],[Kredit Jawaban]]="","",IF(Table3[[#This Row],[Kredit Jawaban]]=Table4[[#This Row],[Kredit (Rp)]],"Benar","salah"))
H31: 9 | I31: 46393 | J31: persediaan barang dagang | L31: 95000000 | M31: =IF(Table3[[#This Row],[Akun Jawaban]]="","",IF(Table3[[#This Row],[Akun Jawaban]]=Table4[[#This Row],[Akun]],"Benar","salah")) -> Benar | N31: =IF(Table3[[#This Row],[Debit Jawaban]]="","",IF(Table3[[#This Row],[Debit Jawaban]]=Table4[[#This Row],[Debit (Rp)]],"Benar","salah")) | O31: =IF(Table3[[#This Row],[Kredit Jawaban]]="","",IF(Table3[[#This Row],[Kredit Jawaban]]=Table4[[#This Row],[Kredit (Rp)]],"Benar","salah")) -> Benar
A32: 10 | B32: 46394 | C32: Mudah / Penerimaan piutang | D32: Pelanggan B membayar piutang Rp80.000.000 melalui bank. | E32: Tidak ada potongan. | F32: 80000000 | G32: Debit Bank; kredit Piutang Usaha. | H32: 10 | I32: 46394 | J32: bank | K32: 80000000 | M32: =IF(Table3[[#This Row],[Akun Jawaban]]="","",IF(Table3[[#This Row],[Akun Jawaban]]=Table4[[#This Row],[Akun]],"Benar","salah")) -> Benar | N32: =IF(Table3[[#This Row],[Debit Jawaban]]="","",IF(Table3[[#This Row],[Debit Jawaban]]=Table4[[#This Row],[Debit (Rp)]],"Benar","salah")) -> Benar | O32: =IF(Table3[[#This Row],[Kredit Jawaban]]="","",IF(Table3[[#This Row],[Kredit Jawaban]]=Table4[[#This Row],[Kredit (Rp)]],"Benar","salah"))
G33: Debit Bank; kredit Piutang Usaha. | H33: 10 | I33: 46394 | J33: piutang usaha | L33: 80000000 | M33: =IF(Table3[[#This Row],[Akun Jawaban]]="","",IF(Table3[[#This Row],[Akun Jawaban]]=Table4[[#This Row],[Akun]],"Benar","salah")) -> Benar | N33: =IF(Table3[[#This Row],[Debit Jawaban]]="","",IF(Table3[[#This Row],[Debit Jawaban]]=Table4[[#This Row],[Debit (Rp)]],"Benar","salah")) | O33: =IF(Table3[[#This Row],[Kredit Jawaban]]="","",IF(Table3[[#This Row],[Kredit Jawaban]]=Table4[[#This Row],[Kredit (Rp)]],"Benar","salah")) -> Benar
A34: 11 | B34: 46395 | C34: Mudah / Pelunasan utang | D34: Perusahaan membayar Utang Usaha kepada Supplier A sebesar Rp100.000.000 melalui bank. | E34: Pelunasan sebagian. | F34: 100000000 | G34: Debit Utang Usaha; kredit Bank. | H34: 11 | I34: 46395 | J34: utang usaha | K34: 100000000 | M34: =IF(Table3[[#This Row],[Akun Jawaban]]="","",IF(Table3[[#This Row],[Akun Jawaban]]=Table4[[#This Row],[Akun]],"Benar","salah")) -> Benar | N34: =IF(Table3[[#This Row],[Debit Jawaban]]="","",IF(Table3[[#This Row],[Debit Jawaban]]=Table4[[#This Row],[Debit (Rp)]],"Benar","salah")) -> Benar | O34: =IF(Table3[[#This Row],[Kredit Jawaban]]="","",IF(Table3[[#This Row],[Kredit Jawaban]]=Table4[[#This Row],[Kredit (Rp)]],"Benar","salah"))
G35: Debit Utang Usaha; kredit Bank. | H35: 11 | I35: 46395 | J35: bank | L35: 100000000 | M35: =IF(Table3[[#This Row],[Akun Jawaban]]="","",IF(Table3[[#This Row],[Akun Jawaban]]=Table4[[#This Row],[Akun]],"Benar","salah")) -> Benar | N35: =IF(Table3[[#This Row],[Debit Jawaban]]="","",IF(Table3[[#This Row],[Debit Jawaban]]=Table4[[#This Row],[Debit (Rp)]],"Benar","salah")) | O35: =IF(Table3[[#This Row],[Kredit Jawaban]]="","",IF(Table3[[#This Row],[Kredit Jawaban]]=Table4[[#This Row],[Kredit (Rp)]],"Benar","salah")) -> Benar
A36: 12 | B36: 46395 | C36: Mudah / Uang muka pelanggan | D36: Pelanggan C membayar uang muka Rp44.440.000 melalui bank untuk pesanan barang yang akan dikirim kemudian. | E36: Uang muka dicatat sebagai liabilitas sampai barang diserahkan. | F36: 44440000 | G36: Debit Bank; kredit Uang Muka Pelanggan. | H36: 12 | I36: 46395 | J36: bank | K36: 44440000 | M36: =IF(Table3[[#This Row],[Akun Jawaban]]="","",IF(Table3[[#This Row],[Akun Jawaban]]=Table4[[#This Row],[Akun]],"Benar","salah")) -> Benar | N36: =IF(Table3[[#This Row],[Debit Jawaban]]="","",IF(Table3[[#This Row],[Debit Jawaban]]=Table4[[#This Row],[Debit (Rp)]],"Benar","salah")) -> Benar | O36: =IF(Table3[[#This Row],[Kredit Jawaban]]="","",IF(Table3[[#This Row],[Kredit Jawaban]]=Table4[[#This Row],[Kredit (Rp)]],"Benar","salah"))
G37: Debit Bank; kredit Uang Muka Pelanggan. | H37: 12 | I37: 46395 | J37: Uang Muka Pelanggan | L37: 44440000 | M37: =IF(Table3[[#This Row],[Akun Jawaban]]="","",IF(Table3[[#This Row],[Akun Jawaban]]=Table4[[#This Row],[Akun]],"Benar","salah")) -> Benar | N37: =IF(Table3[[#This Row],[Debit Jawaban]]="","",IF(Table3[[#This Row],[Debit Jawaban]]=Table4[[#This Row],[Debit (Rp)]],"Benar","salah")) | O37: =IF(Table3[[#This Row],[Kredit Jawaban]]="","",IF(Table3[[#This Row],[Kredit Jawaban]]=Table4[[#This Row],[Kredit (Rp)]],"Benar","salah")) -> Benar
A38: 13 | B38: 46396 | C38: Mudah / Retur pembelian | D38: Perusahaan mengembalikan barang kepada Supplier A senilai Rp15.000.000 sebelum PPN karena rusak. | E38: PPN 11% dibatalkan; retur mengurangi utang. | F38: 15000000 | G38: Debit Utang Usaha; kredit Persediaan dan PPN Masukan. | H38: 13 | I38: 46396 | J38: utang usaha | K38: =SUM(L39:L40) -> 16650000 | M38: =IF(Table3[[#This Row],[Akun Jawaban]]="","",IF(Table3[[#This Row],[Akun Jawaban]]=Table4[[#This Row],[Akun]],"Benar","salah")) -> Benar | N38: =IF(Table3[[#This Row],[Debit Jawaban]]="","",IF(Table3[[#This Row],[Debit Jawaban]]=Table4[[#This Row],[Debit (Rp)]],"Benar","salah")) -> Benar | O38: =IF(Table3[[#This Row],[Kredit Jawaban]]="","",IF(Table3[[#This Row],[Kredit Jawaban]]=Table4[[#This Row],[Kredit (Rp)]],"Benar","salah"))
G39: Debit Utang Usaha; kredit Persediaan dan PPN Masukan. | H39: 13 | I39: 46396 | J39: persediaan barang dagang | L39: 15000000 | M39: =IF(Table3[[#This Row],[Akun Jawaban]]="","",IF(Table3[[#This Row],[Akun Jawaban]]=Table4[[#This Row],[Akun]],"Benar","salah")) -> Benar | N39: =IF(Table3[[#This Row],[Debit Jawaban]]="","",IF(Table3[[#This Row],[Debit Jawaban]]=Table4[[#This Row],[Debit (Rp)]],"Benar","salah")) | O39: =IF(Table3[[#This Row],[Kredit Jawaban]]="","",IF(Table3[[#This Row],[Kredit Jawaban]]=Table4[[#This Row],[Kredit (Rp)]],"Benar","salah")) -> Benar
H40: 13 | I40: 46396 | J40: ppn masukan | L40: =11%*15000000 -> 1650000 | M40: =IF(Table3[[#This Row],[Akun Jawaban]]="","",IF(Table3[[#This Row],[Akun Jawaban]]=Table4[[#This Row],[Akun]],"Benar","salah")) -> Benar | N40: =IF(Table3[[#This Row],[Debit Jawaban]]="","",IF(Table3[[#This Row],[Debit Jawaban]]=Table4[[#This Row],[Debit (Rp)]],"Benar","salah")) | O40: =IF(Table3[[#This Row],[Kredit Jawaban]]="","",IF(Table3[[#This Row],[Kredit Jawaban]]=Table4[[#This Row],[Kredit (Rp)]],"Benar","salah")) -> Benar
...

Sheet Kunci_Jurnal_80
A1: KUNCI JURNAL UMUM – 80 SOAL | SUMBER UNTUK BUKU BESAR & REKAP
A2: Kunci ini adalah answer key pembanding. Kolom F:G adalah nominal jurnal; H = arus kas; I = tingkat; J = dokumen; K = catatan.
A3: No | B3: Tanggal | C3: Tingkat / Jenis | D3: Counterparty | E3: Akun | F3: Debit (Rp) | G3: Kredit (Rp) | H3: Arus Kas | I3: Tingkat | J3: Dokumen | K3: Catatan
A4: 1 | B4: 46388 | C4: Mudah / Setoran modal | D4: Pemegang Saham | E4: Bank | F4: 1500000000 | G4: 0 | H4: Pendanaan | I4: Mudah | J4: Bukti Setoran Saham
A5: 1 | B5: 46388 | C5: Mudah / Setoran modal | D5: Pemegang Saham | E5: Modal Saham | F5: 0 | G5: 1500000000 | I5: Mudah | J5: Bukti Setoran Saham
A6: 2 | B6: 46388 | C6: Mudah / Transfer kas kecil | D6: Internal | E6: Kas Kecil | F6: 20000000 | G6: 0 | H6: Investasi | I6: Mudah | J6: Bukti Transfer
A7: 2 | B7: 46388 | C7: Mudah / Transfer kas kecil | D7: Internal | E7: Bank | F7: 0 | G7: 20000000 | H7: Investasi | I7: Mudah | J7: Bukti Transfer
A8: 3 | B8: 46389 | C8: Mudah / Pembelian aset tunai | D8: PT Perkasa Office | E8: Peralatan Toko | F8: 60000000 | G8: 0 | H8: Investasi | I8: Mudah | J8: Invoice FA-001
A9: 3 | B9: 46389 | C9: Mudah / Pembelian aset tunai | D9: PT Perkasa Office | E9: PPN Masukan | F9: 6600000 | G9: 0 | H9: Operasi | I9: Mudah | J9: Faktur Pajak
A10: 3 | B10: 46389 | C10: Mudah / Pembelian aset tunai | D10: PT Perkasa Office | E10: Bank | F10: 0 | G10: 66600000 | H10: Investasi | I10: Mudah | J10: Bukti Bayar
A11: 4 | B11: 46390 | C11: Mudah / Pembelian aset kredit | D11: PT Kantor Jaya | E11: Peralatan Kantor | F11: 40000000 | G11: 0 | H11: Investasi | I11: Mudah | J11: Invoice FA-002
A12: 4 | B12: 46390 | C12: Mudah / Pembelian aset kredit | D12: PT Kantor Jaya | E12: PPN Masukan | F12: 4400000 | G12: 0 | H12: Operasi | I12: Mudah | J12: Faktur Pajak
A13: 4 | B13: 46390 | C13: Mudah / Pembelian aset kredit | D13: PT Kantor Jaya | E13: Utang Usaha | F13: 0 | G13: 44400000 | H13: Operasi | I13: Mudah | J13: Invoice FA-002
A14: 5 | B14: 46390 | C14: Mudah / Pembelian persediaan kredit | D14: Supplier A | E14: Persediaan Barang Dagang | F14: 250000000 | G14: 0 | H14: Operasi | I14: Mudah | J14: INV-A-001
A15: 5 | B15: 46390 | C15: Mudah / Pembelian persediaan kredit | D15: Supplier A | E15: PPN Masukan | F15: 27500000 | G15: 0 | H15: Operasi | I15: Mudah | J15: Faktur Pajak
A16: 5 | B16: 46390 | C16: Mudah / Pembelian persediaan kredit | D16: Supplier A | E16: Utang Usaha | F16: 0 | G16: 277500000 | H16: Operasi | I16: Mudah | J16: INV-A-001
A17: 6 | B17: 46391 | C17: Mudah / Pembelian persediaan tunai | D17: Supplier B | E17: Persediaan Barang Dagang | F17: 100000000 | G17: 0 | H17: Operasi | I17: Mudah | J17: INV-B-001
... A36: 12 | B36: 46395 | C36: Mudah / Uang muka pelanggan | D36: Pelanggan C | E36: Bank | F36: 44440000 | G36: 0 | H36: Operasi | I36: Mudah | J36: AR-DP-001
A37: 12 | B37: 46395 | C37: Mudah / Uang muka pelanggan | D37: Pelanggan C | E37: Uang Muka Pelanggan | F37: 0 | G37: 44440000 | I37: Mudah | J37: AR-DP-001
A38: 13 | B38: 46396 | C38: Mudah / Retur pembelian | D38: Supplier A | E38: Utang Usaha | F38: 16650000 | G38: 0 | H38: Operasi | I38: Mudah | J38: RT-AP-001
A39: 13 | B39: 46396 | C39: Mudah / Retur pembelian | D39: Supplier A | E39: Persediaan Barang Dagang | F39: 0 | G39: 15000000 | H39: Operasi | I39: Mudah | J39: Nota Retur
A40: 13 | B40: 46396 | C40: Mudah / Retur pembelian | D40: Supplier A | E40: PPN Masukan | F40: 0 | G40: 1650000 | H40: Operasi | I40: Mudah | J40: Nota Retur
A41: 14 | B41: 46397 | C41: Mudah / Retur penjualan | D41: Pelanggan B | E41: Retur Penjualan | F41: 10000000 | G41: 0 | H41: Operasi | I41: Mudah | J41: RT-AR-001
A42: 14 | B42: 46397 | C42: Mudah / Retur penjualan | D42: Pelanggan B | E42: PPN Keluaran | F42: 1100000 | G42: 0 | H42: Operasi | I42: Mudah | J42: Nota Retur
A43: 14 | B43: 46397 | C43: Mudah / Retur penjualan | D43: Pelanggan B | E43: Piutang Usaha | F43: 0 | G43: 11100000 | H43: Operasi | I43: Mudah | J43: Nota Retur
A44: 14 | B44: 46397 | C44: Mudah / Retur penjualan | D44: Pelanggan B | E44: Persediaan Barang Dagang | F44: 6000000 | G44: 0 | H44: Operasi | I44: Mudah | J44: Kartu Persediaan
A45: 14 | B45: 46397 | C45: Mudah / Retur penjualan | D45: Pelanggan B | E45: HPP | F45: 0 | G45: 6000000 | H45: Operasi | I45: Mudah | J45: Kartu Persediaan
A46: 15 | B46: 46397 | C46: Mudah / Freight-out | D46: Ekspedisi | E46: Beban Pengiriman Penjualan | F46: 2500000 | G46: 0 | H46: Operasi | I46: Mudah | J46: FO-001
A47: 15 | B47: 46397 | C47: Mudah / Freight-out | D47: Ekspedisi | E47: Bank | F47: 0 | G47: 2500000 | H47: Operasi | I47: Mudah | J47: Bukti Bayar
A48: 16 | B48: 46398 | C48: Mudah / Iklan dibayar di muka | D48: Media Nusantara | E48: Iklan Dibayar di Muka | F48: 12000000 | G48: 0 | H48: Operasi | I48: Mudah | J48: ADV-001
A49: 16 | B49: 46398 | C49: Mudah / Iklan dibayar di muka | D49: Media Nusantara | E49: Bank | F49: 0 | G49: 12000000 | H49: Operasi | I49: Mudah | J49: Bukti Bayar
... A111: 37 | B111: 46409 | C111: Menengah / Pengembalian dana pelanggan | D111: Pelanggan C | E111: Uang Muka Pelanggan | F111: 6700000 | G111: 0 | H111: Operasi | I111: Menengah | J111: CM-REF-001
A112: 37 | B112: 46409 | C112: Menengah / Pengembalian dana pelanggan | D112: Pelanggan C | E112: Bank | F112: 0 | G112: 6700000 | I112: Menengah | J112: CM-REF-001
A113: 38 | B113: 46410 | C113: Menengah / Cek pelanggan ditolak | D113: Pelanggan B | E113: Piutang Usaha | F113: 3000000 | G113: 0 | H113: Operasi | I113: Menengah | J113: NSF-001
A114: 38 | B114: 46410 | C114: Menengah / Cek pelanggan ditolak | D114: Pelanggan B | E114: Bank | F114: 0 | G114: 3000000 | H114: Operasi | I114: Menengah | J114: Bank Advice
A115: 39 | B115: 46410 | C115: Menengah / Penerimaan piutang | D115: Pelanggan B | E115: Bank | F115: 50000000 | G115: 0 | H115: Operasi | I115: Menengah | J115: BT-AR-003
A116: 39 | B116: 46410 | C116: Menengah / Penerimaan piutang | D116: Pelanggan B | E116: Piutang Usaha | F116: 0 | G116: 50000000 | H116: Operasi | I116: Menengah | J116: BT-AR-003
A117: 40 | B117: 46411 | C117: Sulit / Impor persediaan + bea + PPN + PPh22 | D117: Direktorat Bea Cukai | E117: Persediaan Barang Dagang | F117: 105000000 | G117: 0 | H117: Operasi | I117: Sulit | J117: IMP-001
A118: 40 | B118: 46411 | C118: Sulit / Impor persediaan + bea + PPN + PPh22 | D118: Direktorat Bea Cukai | E118: PPN Masukan | F118: 11550000 | G118: 0 | H118: Operasi | I118: Sulit | J118: IMP-001
A119: 40 | B119: 46411 | C119: Sulit / Impor persediaan + bea + PPN + PPh22 | D119: Direktorat Bea Cukai | E119: PPh 22 Dibayar di Muka | F119: 2625000 | G119: 0 | H119: Operasi | I119: Sulit | J119: IMP-001
...

Sheet Buku_Besar
A1: BUKU BESAR RINGKAS – SALDO AWAL + JURNAL UMUM + PENYESUAIAN + PENUTUP
A2: Identitas | E2: Saldo Awal | G2: Jurnal Umum | I2: Penyesuaian | K2: Saldo Sebelum Penutup | M2: Jurnal Penutup | O2: Saldo Akhir
A3: Kode Akun | B3: Nama Akun | C3: Kategori | D3: Saldo Normal | E3: Debit Awal | F3: Kredit Awal | G3: Debit JU | H3: Kredit JU | I3: Debit Penyesuaian | J3: Kredit Penyesuaian | K3: Saldo Debit | L3: Saldo Kredit | M3: Debit Penutup | N3: Kredit Penutup | O3: Saldo Debit Akhir | P3: Saldo Kredit Akhir
A4: 1-001 | B4: Bank | C4: Aset | D4: Debit | E4: =SUMIF(Saldo_Awal!$B$4:$B$91,$B4,Saldo_Awal!$C$4:$C$91) -> 100000000 | F4: =SUMIF(Saldo_Awal!$B$4:$B$91,$B4,Saldo_Awal!$D$4:$D$91) -> 0 | G4: =SUMIF(Kunci_Jurnal_80!$E$4:$E$230,$B4,Kunci_Jurnal_80!$F$4:$F$230) -> 2468414000 | H4: =SUMIF(Kunci_Jurnal_80!$E$4:$E$230,$B4,Kunci_Jurnal_80!$G$4:$G$230) -> 1164987000 | I4: =SUMIF(Kunci_Penyesuaian!$D$4:$D$65,$B4,Kunci_Penyesuaian!$E$4:$E$65) -> 0 | J4: =SUMIF(Kunci_Penyesuaian!$D$4:$D$65,$B4,Kunci_Penyesuaian!$F$4:$F$65) -> 0 | K4: =IF(E4+G4+I4-F4-H4-J4>0,E4+G4+I4-F4-H4-J4,0) -> 1403427000 | L4: =IF(F4+H4+J4-E4-G4-I4>0,F4+H4+J4-E4-G4-I4,0) -> 0 | M4: =SUMIF(Jurnal_Penutup!$D$5:$D$82,$B4,Jurnal_Penutup!$E$5:$E$82) -> 0 | N4: =SUMIF(Jurnal_Penutup!$D$5:$D$82,$B4,Jurnal_Penutup!$F$5:$F$82) -> 0 | O4: =IF(K4+M4-L4-N4>0,K4+M4-L4-N4,0) -> 1403427000 | P4: =IF(L4+N4-K4-M4>0,L4+N4-K4-M4,0) -> 0
A5: 1-002 | B5: Kas Kecil | C5: Aset | D5: Debit | E5: =SUMIF(Saldo_Awal!$B$4:$B$91,$B5,Saldo_Awal!$C$4:$C$91) -> 10000000 | F5: =SUMIF(Saldo_Awal!$B$4:$B$91,$B5,Saldo_Awal!$D$4:$D$91) -> 0 | G5: =SUMIF(Kunci_Jurnal_80!$E$4:$E$230,$B5,Kunci_Jurnal_80!$F$4:$F$230) -> 30150000 | H5: =SUMIF(Kunci_Jurnal_80!$E$4:$E$230,$B5,Kunci_Jurnal_80!$G$4:$G$230) -> 2300000 | I5: =SUMIF(Kunci_Penyesuaian!$D$4:$D$65,$B5,Kunci_Penyesuaian!$E$4:$E$65) -> 0 | J5: =SUMIF(Kunci_Penyesuaian!$D$4:$D$65,$B5,Kunci_Penyesuaian!$F$4:$F$65) -> 0 | K5: =IF(E5+G5+I5-F5-H5-J5>0,E5+G5+I5-F5-H5-J5,0) -> 37850000 | L5: =IF(F5+H5+J5-E5-G5-I5>0,F5+H5+J5-E5-G5-I5,0) -> 0 | M5: =SUMIF(Jurnal_Penutup!$D$5:$D$82,$B5,Jurnal_Penutup!$E$5:$E$82) -> 0 | N5: =SUMIF(Jurnal_Penutup!$D$5:$D$82,$B5,Jurnal_Penutup!$F$5:$F$82) -> 0 | O5: =IF(K5+M5-L5-N5>0,K5+M5-L5-N5,0) -> 37850000 | P5: =IF(L5+N5-K5-M5>0,L5+N5-K5-M5,0) -> 0
A6: 1-003 | B6: Piutang Usaha | C6: Aset | D6: Debit | E6: =SUMIF(Saldo_Awal!$B$4:$B$91,$B6,Saldo_Awal!$C$4:$C$91) -> 60000000 | F6: =SUMIF(Saldo_Awal!$B$4:$B$91,$B6,Saldo_Awal!$D$4:$D$91) -> 0 | G6: =SUMIF(Kunci_Jurnal_80!$E$4:$E$230,$B6,Kunci_Jurnal_80!$F$4:$F$230) -> 483630000 | H6: =SUMIF(Kunci_Jurnal_80!$E$4:$E$230,$B6,Kunci_Jurnal_80!$G$4:$G$230) -> 425490000 | I6: =SUMIF(Kunci_Penyesuaian!$D$4:$D$65,$B6,Kunci_Penyesuaian!$E$4:$E$65) -> 0 | J6: =SUMIF(Kunci_Penyesuaian!$D$4:$D$65,$B6,Kunci_Penyesuaian!$F$4:$F$65) -> 2000000 | K6: =IF(E6+G6+I6-F6-H6-J6>0,E6+G6+I6-F6-H6-J6,0) -> 116140000 | L6: =IF(F6+H6+J6-E6-G6-I6>0,F6+H6+J6-E6-G6-I6,0) -> 0 | M6: =SUMIF(Jurnal_Penutup!$D$5:$D$82,$B6,Jurnal_Penutup!$E$5:$E$82) -> 0 | N6: =SUMIF(Jurnal_Penutup!$D$5:$D$82,$B6,Jurnal_Penutup!$F$5:$F$82) -> 0 | O6: =IF(K6+M6-L6-N6>0,K6+M6-L6-N6,0) -> 116140000 | P6: =IF(L6+N6-K6-M6>0,L6+N6-K6-M6,0) -> 0
A7: 1-004 | B7: Piutang Karyawan | C7: Aset | D7: Debit | E7: =SUMIF(Saldo_Awal!$B$4:$B$91,$B7,Saldo_Awal!$C$4:$C$91) -> 0 | F7: =SUMIF(Saldo_Awal!$B$4:$B$91,$B7,Saldo_Awal!$D$4:$D$91) -> 0 | G7: =SUMIF(Kunci_Jurnal_80!$E$4:$E$230,$B7,Kunci_Jurnal_80!$F$4:$F$230) -> 5000000 | H7: =SUMIF(Kunci_Jurnal_80!$E$4:$E$230,$B7,Kunci_Jurnal_80!$G$4:$G$230) -> 2000000 | I7: =SUMIF(Kunci_Penyesuaian!$D$4:$D$65,$B7,Kunci_Penyesuaian!$E$4:$E$65) -> 0 | J7: =SUMIF(Kunci_Penyesuaian!$D$4:$D$65,$B7,Kunci_Penyesuaian!$F$4:$F$65) -> 0 | K7: =IF(E7+G7+I7-F7-H7-J7>0,E7+G7+I7-F7-H7-J7,0) -> 3000000 | L7: =IF(F7+H7+J7-E7-G7-I7>0,F7+H7+J7-E7-G7-I7,0) -> 0 | M7: =SUMIF(Jurnal_Penutup!$D$5:$D$82,$B7,Jurnal_Penutup!$E$5:$E$82) -> 0 | N7: =SUMIF(Jurnal_Penutup!$D$5:$D$82,$B7,Jurnal_Penutup!$F$5:$F$82) -> 0 | O7: =IF(K7+M7-L7-N7>0,K7+M7-L7-N7,0) -> 3000000 | P7: =IF(L7+N7-K7-M7>0,L7+N7-K7-M7,0) -> 0
A8: 1-005 | B8: Piutang Bunga | C8: Aset | D8: Debit | E8: =SUMIF(Saldo_Awal!$B$4:$B$91,$B8,Saldo_Awal!$C$4:$C$91) -> 0 | F8: =SUMIF(Saldo_Awal!$B$4:$B$91,$B8,Saldo_Awal!$D$4:$D$91) -> 0 | G8: =SUMIF(Kunci_Jurnal_80!$E$4:$E$230,$B8,Kunci_Jurnal_80!$F$4:$F$230) -> 0 | H8: =SUMIF(Kunci_Jurnal_80!$E$4:$E$230,$B8,Kunci_Jurnal_80!$G$4:$G$230) -> 0 | I8: =SUMIF(Kunci_Penyesuaian!$D$4:$D$65,$B8,Kunci_Penyesuaian!$E$4:$E$65) -> 700000 | J8: =SUMIF(Kunci_Penyesuaian!$D$4:$D$65,$B8,Kunci_Penyesuaian!$F$4:$F$65) -> 0 | K8: =IF(E8+G8+I8-F8-H8-J8>0,E8+G8+I8-F8-H8-J8,0) -> 700000 | L8: =IF(F8+H8+J8-E8-G8-I8>0,F8+H8+J8-E8-G8-I8,0) -> 0 | M8: =SUMIF(Jurnal_Penutup!$D$5:$D$82,$B8,Jurnal_Penutup!$E$5:$E$82) -> 0 | N8: =SUMIF(Jurnal_Penutup!$D$5:$D$82,$B8,Jurnal_Penutup!$F$5:$F$82) -> 0 | O8: =IF(K8+M8-L8-N8>0,K8+M8-L8-N8,0) -> 700000 | P8: =IF(L8+N8-K8-M8>0,L8+N8-K8-M8,0) -> 0
A9: 1-006 | B9: Piutang Pendapatan | C9: Aset | D9: Debit | E9: =SUMIF(Saldo_Awal!$B$4:$B$91,$B9,Saldo_Awal!$C$4:$C$91) -> 0 | F9: =SUMIF(Saldo_Awal!$B$4:$B$91,$B9,Saldo_Awal!$D$4:$D$91) -> 0 | G9: =SUMIF(Kunci_Jurnal_80!$E$4:$E$230,$B9,Kunci_Jurnal_80!$F$4:$F$230) -> 0 | H9: =SUMIF(Kunci_Jurnal_80!$E$4:$E$230,$B9,Kunci_Jurnal_80!$G$4:$G$230) -> 0 | I9: =SUMIF(Kunci_Penyesuaian!$D$4:$D$65,$B9,Kunci_Penyesuaian!$E$4:$E$65) -> 0 | J9: =SUMIF(Kunci_Penyesuaian!$D$4:$D$65,$B9,Kunci_Penyesuaian!$F$4:$F$65) -> 0 | K9: =IF(E9+G9+I9-F9-H9-J9>0,E9+G9+I9-F9-H9-J9,0) -> 0 | L9: =IF(F9+H9+J9-E9-G9-I9>0,F9+H9+J9-E9-G9-I9,0) -> 0 | M9: =SUMIF(Jurnal_Penutup!$D$5:$D$82,$B9,Jurnal_Penutup!$E$5:$E$82) -> 0 | N9: =SUMIF(Jurnal_Penutup!$D$5:$D$82,$B9,Jurnal_Penutup!$F$5:$F$82) -> 0 | O9: =IF(K9+M9-L9-N9>0,K9+M9-L9-N9,0) -> 0 | P9: =IF(L9+N9-K9-M9>0,L9+N9-K9-M9,0) -> 0
A10: 1-007 | B10: Persediaan Barang Dagang | C10: Aset | D10: Debit | E10: =SUMIF(Saldo_Awal!$B$4:$B$91,$B10,Saldo_Awal!$C$4:$C$91) -> 120000000 | F10: =SUMIF(Saldo_Awal!$B$4:$B$91,$B10,Saldo_Awal!$D$4:$D$91) -> 0 | G10: =SUMIF(Kunci_Jurnal_80!$E$4:$E$230,$B10,Kunci_Jurnal_80!$F$4:$F$230) -> 574000000 | H10: =SUMIF(Kunci_Jurnal_80!$E$4:$E$230,$B10,Kunci_Jurnal_80!$G$4:$G$230) -> 436300000 | I10: =SUMIF(Kunci_Penyesuaian!$D$4:$D$65,$B10,Kunci_Penyesuaian!$E$4:$E$65) -> 0 | J10: =SUMIF(Kunci_Penyesuaian!$D$4:$D$65,$B10,Kunci_Penyesuaian!$F$4:$F$65) -> 5900000 | K10: =IF(E10+G10+I10-F10-H10-J10>0,E10+G10+I10-F10-H10-J10,0) -> 251800000 | L10: =IF(F10+H10+J10-E10-G10-I10>0,F10+H10+J10-E10-G10-I10,0) -> 0 | M10: =SUMIF(Jurnal_Penutup!$D$5:$D$82,$B10,Jurnal_Penutup!$E$5:$E$82) -> 0 | N10: =SUMIF(Jurnal_Penutup!$D$5:$D$82,$B10,Jurnal_Penutup!$F$5:$F$82) -> 0 | O10: =IF(K10+M10-L10-N10>0,K10+M10-L10-N10,0) -> 251800000 | P10: =IF(L10+N10-K10-M10>0,L10+N10-K10-M10,0) -> 0
A11: 1-008 | B11: PPN Masukan | C11: Aset | D11: Debit | E11: =SUMIF(Saldo_Awal!$B$4:$B$91,$B11,Saldo_Awal!$C$4:$C$91) -> 0 | F11: =SUMIF(Saldo_Awal!$B$4:$B$91,$B11,Saldo_Awal!$D$4:$D$91) -> 0 | G11: =SUMIF(Kunci_Jurnal_80!$E$4:$E$230,$B11,Kunci_Jurnal_80!$F$4:$F$230) -> 103125000 | H11: =SUMIF(Kunci_Jurnal_80!$E$4:$E$230,$B11,Kunci_Jurnal_80!$G$4:$G$230) -> 2013000 | I11: =SUMIF(Kunci_Penyesuaian!$D$4:$D$65,$B11,Kunci_Penyesuaian!$E$4:$E$65) -> 0 | J11: =SUMIF(Kunci_Penyesuaian!$D$4:$D$65,$B11,Kunci_Penyesuaian!$F$4:$F$65) -> 74954000 | K11: =IF(E11+G11+I11-F11-H11-J11>0,E11+G11+I11-F11-H11-J11,0) -> 26158000 | L11: =IF(F11+H11+J11-E11-G11-I11>0,F11+H11+J11-E11-G11-I11,0) -> 0 | M11: =SUMIF(Jurnal_Penutup!$D$5:$D$82,$B11,Jurnal_Penutup!$E$5:$E$82) -> 0 | N11: =SUMIF(Jurnal_Penutup!$D$5:$D$82,$B11,Jurnal_Penutup!$F$5:$F$82) -> 0 | O11: =IF(K11+M11-L11-N11>0,K11+M11-L11-N11,0) -> 26158000 | P11: =IF(L11+N11-K11-M11>0,L11+N11-K11-M11,0) -> 0
A12: 1-009 | B12: PPh 22 Dibayar di Muka | C12: Aset | D12: Debit | E12: =SUMIF(Saldo_Awal!$B$4:$B$91,$B12,Saldo_Awal!$C$4:$C$91) -> 0 | F12: =SUMIF(Saldo_Awal!$B$4:$B$91,$B12,Saldo_Awal!$D$4:$D$91) -> 0 | G12: =SUMIF(Kunci_Jurnal_80!$E$4:$E$230,$B12,Kunci_Jurnal_80!$F$4:$F$230) -> 2625000 | H12: =SUMIF(Kunci_Jurnal_80!$E$4:$E$230,$B12,Kunci_Jurnal_80!$G$4:$G$230) -> 0 | I12: =SUMIF(Kunci_Penyesuaian!$D$4:$D$65,$B12,Kunci_Penyesuaian!$E$4:$E$65) -> 0 | J12: =SUMIF(Kunci_Penyesuaian!$D$4:$D$65,$B12,Kunci_Penyesuaian!$F$4:$F$65) -> 0 | K12: =IF(E12+G12+I12-F12-H12-J12>0,E12+G12+I12-F12-H12-J12,0) -> 2625000 | L12: =IF(F12+H12+J12-E12-G12-I12>0,F12+H12+J12-E12-G12-I12,0) -> 0 | M12: =SUMIF(Jurnal_Penutup!$D$5:$D$82,$B12,Jurnal_Penutup!$E$5:$E$82) -> 0 | N12: =SUMIF(Jurnal_Penutup!$D$5:$D$82,$B12,Jurnal_Penutup!$F$5:$F$82) -> 0 | O12: =IF(K12+M12-L12-N12>0,K12+M12-L12-N12,0) -> 2625000 | P12: =IF(L12+N12-K12-M12>0,L12+N12-K12-M12,0) -> 0
A13: 1-010 | B13: PPh 23 Dibayar di Muka | C13: Aset | D13: Debit | E13: =SUMIF(Saldo_Awal!$B$4:$B$91,$B13,Saldo_Awal!$C$4:$C$91) -> 0 | F13: =SUMIF(Saldo_Awal!$B$4:$B$91,$B13,Saldo_Awal!$D$4:$D$91) -> 0 | G13: =SUMIF(Kunci_Jurnal_80!$E$4:$E$230,$B13,Kunci_Jurnal_80!$F$4:$F$230) -> 0 | H13: =SUMIF(Kunci_Jurnal_80!$E$4:$E$230,$B13,Kunci_Jurnal_80!$G$4:$G$230) -> 0 | I13: =SUMIF(Kunci_Penyesuaian!$D$4:$D$65,$B13,Kunci_Penyesuaian!$E$4:$E$65) -> 0 | J13: =SUMIF(Kunci_Penyesuaian!$D$4:$D$65,$B13,Kunci_Penyesuaian!$F$4:$F$65) -> 0 | K13: =IF(E13+G13+I13-F13-H13-J13>0,E13+G13+I13-F13-H13-J13,0) -> 0 | L13: =IF(F13+H13+J13-E13-G13-I13>0,F13+H13+J13-E13-G13-I13,0) -> 0 | M13: =SUMIF(Jurnal_Penutup!$D$5:$D$82,$B13,Jurnal_Penutup!$E$5:$E$82) -> 0 | N13: =SUMIF(Jurnal_Penutup!$D$5:$D$82,$B13,Jurnal_Penutup!$F$5:$F$82) -> 0 | O13: =IF(K13+M13-L13-N13>0,K13+M13-L13-N13,0) -> 0 | P13: =IF(L13+N13-K13-M13>0,L13+N13-K13-M13,0) -> 0
A14: 1-011 | B14: PPh Final Dibayar di Muka | C14: Aset | D14: Debit | E14: =SUMIF(Saldo_Awal!$B$4:$B$91,$B14,Saldo_Awal!$C$4:$C$91) -> 0 | F14: =SUMIF(Saldo_Awal!$B$4:$B$91,$B14,Saldo_Awal!$D$4:$D$91) -> 0 | G14: =SUMIF(Kunci_Jurnal_80!$E$4:$E$230,$B14,Kunci_Jurnal_80!$F$4:$F$230) -> 0 | H14: =SUMIF(Kunci_Jurnal_80!$E$4:$E$230,$B14,Kunci_Jurnal_80!$G$4:$G$230) -> 0 | I14: =SUMIF(Kunci_Penyesuaian!$D$4:$D$65,$B14,Kunci_Penyesuaian!$E$4:$E$65) -> 0 | J14: =SUMIF(Kunci_Penyesuaian!$D$4:$D$65,$B14,Kunci_Penyesuaian!$F$4:$F$65) -> 0 | K14: =IF(E14+G14+I14-F14-H14-J14>0,E14+G14+I14-F14-H14-J14,0) -> 0 | L14: =IF(F14+H14+J14-E14-G14-I14>0,F14+H14+J14-E14-G14-I14,0) -> 0 | M14: =SUMIF(Jurnal_Penutup!$D$5:$D$82,$B14,Jurnal_Penutup!$E$5:$E$82) -> 0 | N14: =SUMIF(Jurnal_Penutup!$D$5:$D$82,$B14,Jurnal_Penutup!$F$5:$F$82) -> 0 | O14: =IF(K14+M14-L14-N14>0,K14+M14-L14-N14,0) -> 0 | P14: =IF(L14+N14-K14-M14>0,L14+N14-K14-M14,0) -> 0
A15: 1-012 | B15: Sewa Dibayar di Muka | C15: Aset | D15: Debit | E15: =SUMIF(Saldo_Awal!$B$4:$B$91,$B15,Saldo_Awal!$C$4:$C$91) -> 6000000 | F15: =SUMIF(Saldo_Awal!$B$4:$B$91,$B15,Saldo_Awal!$D$4:$D$91) -> 0 | G15: =SUMIF(Kunci_Jurnal_80!$E$4:$E$230,$B15,Kunci_Jurnal_80!$F$4:$F$230) -> 18000000 | H15: =SUMIF(Kunci_Jurnal_80!$E$4:$E$230,$B15,Kunci_Jurnal_80!$G$4:$G$230) -> 0 | I15: =SUMIF(Kunci_Penyesuaian!$D$4:$D$65,$B15,Kunci_Penyesuaian!$E$4:$E$65) -> 0 | J15: =SUMIF(Kunci_Penyesuaian!$D$4:$D$65,$B15,Kunci_Penyesuaian!$F$4:$F$65) -> 6000000 | K15: =IF(E15+G15+I15-F15-H15-J15>0,E15+G15+I15-F15-H15-J15,0) -> 18000000 | L15: =IF(F15+H15+J15-E15-G15-I15>0,F15+H15+J15-E15-G15-I15,0) -> 0 | M15: =SUMIF(Jurnal_Penutup!$D$5:$D$82,$B15,Jurnal_Penutup!$E$5:$E$82) -> 0 | N15: =SUMIF(Jurnal_Penutup!$D$5:$D$82,$B15,Jurnal_Penutup!$F$5:$F$82) -> 0 | O15: =IF(K15+M15-L15-N15>0,K15+M15-L15-N15,0) -> 18000000 | P15: =IF(L15+N15-K15-M15>0,L15+N15-K15-M15,0) -> 0
... A91: 2-021 | B91: PPN Keluaran | C91: Liabilitas | D91: Kredit | E91: =SUMIF(Saldo_Awal!$B$4:$B$91,$B91,Saldo_Awal!$C$4:$C$91) -> 0 | F91: =SUMIF(Saldo_Awal!$B$4:$B$91,$B91,Saldo_Awal!$D$4:$D$91) -> 0 | G91: =SUMIF(Kunci_Jurnal_80!$E$4:$E$230,$B91,Kunci_Jurnal_80!$F$4:$F$230) -> 3256000 | H91: =SUMIF(Kunci_Jurnal_80!$E$4:$E$230,$B91,Kunci_Jurnal_80!$G$4:$G$230) -> 77770000 | I91: =SUMIF(Kunci_Penyesuaian!$D$4:$D$65,$B91,Kunci_Penyesuaian!$E$4:$E$65) -> 74954000 | J91: =SUMIF(Kunci_Penyesuaian!$D$4:$D$65,$B91,Kunci_Penyesuaian!$F$4:$F$65) -> 440000 | K91: =IF(E91+G91+I91-F91-H91-J91>0,E91+G91+I91-F91-H91-J91,0) -> 0 | L91: =IF(F91+H91+J91-E91-G91-I91>0,F91+H91+J91-E91-G91-I91,0) -> 0 | M91: =SUMIF(Jurnal_Penutup!$D$5:$D$82,$B91,Jurnal_Penutup!$E$5:$E$82) -> 0 | N91: =SUMIF(Jurnal_Penutup!$D$5:$D$82,$B91,Jurnal_Penutup!$F$5:$F$82) -> 0 | O91: =IF(K91+M91-L91-N91>0,K91+M91-L91-N91,0) -> 0 | P91: =IF(L91+N91-K91-M91>0,L91+N91-K91-M91,0) -> 0
A92: TOTAL | E92: =SUM(E4:E91) -> 569000000 | F92: =SUM(F4:F91) -> 569000000 | G92: =SUM(G4:G91) -> 5183570000 | H92: =SUM(H4:H91) -> 5183570000 | I92: =SUM(I4:I91) -> 147294000 | J92: =SUM(J4:J91) -> 147294000 | K92: =SUM(K4:K91) -> 3097950000 | L92: =SUM(L4:L91) -> 3097950000 | ... P92: =SUM(P4:P91) -> 2514400000

Sheet Rekap_AP
A1: REKAP ACCOUNTS PAYABLE (AP) – SUBLEDGER & AGING
A3: Supplier | B3: Opening | C3: Invoice / Pembelian Kredit | D3: Retur | E3: Pembayaran | F3: Diskon | G3: Saldo Akhir | H3: Current 0-30 | I3: 31-60 | J3: Dokumen Utama
A4: Supplier A | B4: 0 | C4: 277500000 | D4: 16650000 | E4: 255800000 | F4: 2400000 | G4: =B4+C4-D4-E4-F4 -> 2650000 | H4: 2650000 | I4: 0 | J4: INV-A-001 / RT-AP-001 / PAY-A-001/003
A5: Supplier B | B5: 0 | C5: 111000000 | D5: 0 | E5: 90000000 | F5: 0 | G5: =B5+C5-D5-E5-F5 -> 21000000 | H5: 21000000 | I5: 0 | J5: INV-B-001 / PAY-B-001 / REB-001
A6: Supplier G | B6: 70000000 | C6: 0 | D6: 0 | E6: 0 | F6: 0 | G6: =B6+C6-D6-E6-F6 -> 70000000 | H6: 0 | I6: 70000000 | J6: Opening AP 31-Dec-2026
A7: Supplier Pemerintah | B7: 0 | C7: 54750000 | D7: 0 | E7: 0 | F7: 0 | G7: =B7+C7-D7-E7-F7 -> 54750000 | H7: 54750000 | I7: 0 | J7: PPH22-001
A8: PT Kantor Jaya | B8: 0 | C8: 44400000 | D8: 0 | E8: 44400000 | F8: 0 | G8: =B8+C8-D8-E8-F8 -> 0 | H8: 0 | I8: 0 | J8: FA-002 / PAY-FA-001
A9: Toko ATK Nusantara | B9: 0 | C9: 3330000 | D9: 0 | E9: 3330000 | F9: 0 | G9: =B9+C9-D9-E9-F9 -> 0 | H9: 0 | I9: 0 | J9: ATK-002 / PAY-ATK-001
A11: TOTAL SUBLEDGER | G11: =SUM(G4:G9) -> 148400000 | H11: =SUM(H4:H9) -> 78400000 | I11: =SUM(I4:I9) -> 70000000

Sheet Rekap_AR
A1: REKAP ACCOUNTS RECEIVABLE (AR) – SUBLEDGER & AGING
A3: Customer | B3: Opening | C3: Invoice Penjualan Kredit | D3: Retur / Rebate | E3: NSF / Pembalikan | F3: Penerimaan | G3: Diskon | H3: Penghapusan | I3: Saldo Akhir | J3: Current 0-30 | K3: 31-60 | L3: Dokumen Utama
A4: Pelanggan B | B4: 0 | C4: 177600000 | D4: 11100000 | E4: 3000000 | F4: 163300000 | G4: 0 | H4: 0 | I4: =B4+C4-D4+E4-F4-G4-H4 -> 6200000 | J4: 6200000 | K4: 0 | L4: INV-C-001 / RT-AR-001 / NSF-001 / AR-DSC-001
A5: Pelanggan D | B5: 0 | C5: 233100000 | D5: 21090000 | E5: 0 | F5: 190000000 | G5: 0 | H5: 0 | I5: =B5+C5-D5+E5-F5-G5-H5 -> 22010000 | J5: 22010000 | K5: 0 | L5: INV-D-001 / RT-AR-002 / REB-AR-001
A6: Pelanggan F | B6: 0 | C6: 99900000 | D6: 0 | E6: 0 | F6: 69970000 | G6: 0 | H6: 0 | I6: =B6+C6-D6+E6-F6-G6-H6 -> 29930000 | J6: 29930000 | K6: 0 | L6: INV-F-001 / AR-REC-003
A7: Pelanggan H | B7: 60000000 | C7: 0 | D7: 0 | E7: 0 | F7: 0 | G7: 0 | H7: 2000000 | I7: =B7+C7-D7+E7-F7-G7-H7 -> 58000000 | J7: 0 | K7: 58000000 | L7: Opening AR / Write-off adjustment
A8: TOTAL SUBLEDGER | I8: =SUM(I4:I7) -> 116140000 | J8: =SUM(J4:J7) -> 58140000 | K8: =SUM(K4:K7) -> 58000000

Sheet Inventory_Kartu
A1: KARTU PERSEDIAAN – PERPETUAL FIFO (MODUL LATIHAN)
A2: Gunakan master SKU pada Data_Master. Contoh di bawah memakai unit & harga pokok yang eksplisit agar FIFO dapat dipelajari langkah demi langkah.
A3: Tanggal | B3: SKU | C3: Dokumen | D3: Masuk Qty | E3: Harga Satuan | F3: Masuk Nilai | G3: Keluar Qty | H3: HPP Keluar | I3: Saldo Qty | J3: Saldo Nilai
A4: 46389 | B4: SKU-01 | C4: PUR-001 | D4: 20 | E4: 2500000 | F4: =IF(D4="","",D4*E4) -> 50000000 | I4: =IF(D4="",0,D4)-IF(G4="",0,G4) -> 20 | J4: =IF(F4="",0,F4)-IF(H4="",0,H4) -> 50000000
A5: 46392 | B5: SKU-01 | C5: SAL-001 | F5: =IF(D5="","",D5*E5) | G5: 8 | H5: =8*2500000 -> 20000000 | I5: =I4+IF(D5="",0,D5)-IF(G5="",0,G5) -> 12 | J5: =J4+IF(F5="",0,F5)-IF(H5="",0,H5) -> 30000000
A6: 46395 | B6: SKU-01 | C6: PUR-002 | D6: 10 | E6: 2600000 | F6: =IF(D6="","",D6*E6) -> 26000000 | I6: =I5+IF(D6="",0,D6)-IF(G6="",0,G6) -> 22 | J6: =J5+IF(F6="",0,F6)-IF(H6="",0,H6) -> 56000000
A7: 46399 | B7: SKU-01 | C7: SAL-002 | F7: =IF(D7="","",D7*E7) | G7: 12 | I7: =I6+IF(D7="",0,D7)-IF(G7="",0,G7) -> 10 | J7: =J6+IF(F7="",0,F7)-IF(H7="",0,H7) -> 56000000
A8: 46402 | B8: SKU-01 | C8: SAL-003 | F8: =IF(D8="","",D8*E8) | G8: 5 | H8: =10*2500000+2*2600000 -> 30200000 | I8: =I7+IF(D8="",0,D8)-IF(G8="",0,G8) -> 5 | J8: =J7+IF(F8="",0,F8)-IF(H8="",0,H8) -> 25800000
A9: 46390 | B9: SKU-03 | C9: PUR-003 | D9: 100 | E9: 45000 | F9: =IF(D9="","",D9*E9) -> 4500000 | H9: =5*2600000 -> 13000000 | I9: =I8+IF(D9="",0,D9)-IF(G9="",0,G9) -> 105 | J9: =J8+IF(F9="",0,F9)-IF(H9="",0,H9) -> 17300000
A10: 46397 | B10: SKU-03 | C10: PUR-004 | D10: 50 | E10: 47000 | F10: =IF(D10="","",D10*E10) -> 2350000 | I10: =I9+IF(D10="",0,D10)-IF(G10="",0,G10) -> 155 | J10: =J9+IF(F10="",0,F10)-IF(H10="",0,H10) -> 19650000
A11: 46403 | B11: SKU-03 | C11: SAL-004 | F11: =IF(D11="","",D11*E11) | G11: 120 | H11: =100*45000+20*47000 -> 5440000 | I11: =I10+IF(D11="",0,D11)-IF(G11="",0,G11) -> 35 | J11: =J10+IF(F11="",0,F11)-IF(H11="",0,H11) -> 14210000
A12: 46407 | B12: SKU-03 | C12: PUR-005 | D12: 80 | E12: 48000 | F12: =IF(D12="","",D12*E12) -> 3840000 | I12: =I11+IF(D12="",0,D12)-IF(G12="",0,G12) -> 115 | J12: =J11+IF(F12="",0,F12)-IF(H12="",0,H12) -> 18050000
A13: 46412 | B13: SKU-03 | C13: SAL-005 | F13: =IF(D13="","",D13*E13) | G13: 50 | H13: =50*47000 -> 2350000 | I13: =I12+IF(D13="",0,D13)-IF(G13="",0,G13) -> 65 | J13: =J12+IF(F13="",0,F13)-IF(H13="",0,H13) -> 15700000

Sheet Payroll
A1: PAYROLL JANUARI 2027 – SIMULASI GAJI, PPh 21, BPJS & JURNAL
A3: NIK | B3: Nama | C3: Gaji Pokok | D3: Tunjangan/OT | E3: Bruto | F3: PPh21 (Latihan) | G3: BPJS Pegawai | H3: Take Home Pay | I3: BPJS Pemberi Kerja | J3: Beban Perusahaan | K3: Jurnal Ringkas
A4: E001 | B4: Andi | C4: 5000000 | D4: 0 | E4: =C4+D4 -> 5000000 | F4: =F4 -> 0 | G4: =G4 -> 0 | H4: =E4-F4-G4 -> 5000000 | I4: =E4*8% -> 400000 | J4: =E4+I4 -> 5400000 | K4: =IF(ROW()=4,"Dr Beban Gaji / Cr PPh21, BPJS, Bank","") -> Dr Beban Gaji / Cr PPh21, BPJS, Bank
A5: E002 | B5: Budi | C5: 4500000 | D5: 0 | E5: =C5+D5 -> 4500000 | F5: =F5 -> 0 | G5: =G5 -> 0 | H5: =E5-F5-G5 -> 4500000 | I5: =E5*8% -> 360000 | J5: =E5+I5 -> 4860000 | K5: =IF(ROW()=4,"Dr Beban Gaji / Cr PPh21, BPJS, Bank","")
A6: E003 | B6: Citra | C6: 4000000 | D6: 0 | E6: =C6+D6 -> 4000000 | F6: =F6 -> 0 | G6: =G6 -> 0 | H6: =E6-F6-G6 -> 4000000 | I6: =E6*8% -> 320000 | J6: =E6+I6 -> 4320000 | K6: =IF(ROW()=4,"Dr Beban Gaji / Cr PPh21, BPJS, Bank","")
A7: E004 | B7: Deni | C7: 3500000 | D7: 0 | E7: =C7+D7 -> 3500000 | F7: =F7 -> 0 | G7: =G7 -> 0 | H7: =E7-F7-G7 -> 3500000 | I7: =E7*8% -> 280000 | J7: =E7+I7 -> 3780000 | K7: =IF(ROW()=4,"Dr Beban Gaji / Cr PPh21, BPJS, Bank","")
A8: E005 | B8: Eka | C8: 4000000 | D8: 0 | E8: =C8+D8 -> 4000000 | F8: =F8 -> 0 | G8: =G8 -> 0 | H8: =E8-F8-G8 -> 4000000 | I8: =E8*8% -> 320000 | J8: =E8+I8 -> 4320000 | K8: =IF(ROW()=4,"Dr Beban Gaji / Cr PPh21, BPJS, Bank","")
A9: E006 | B9: Fina | C9: 4000000 | D9: 2000000 | E9: =C9+D9 -> 6000000 | F9: =F9 -> 0 | G9: =G9 -> 0 | H9: =E9-F9-G9 -> 6000000 | I9: =E9*8% -> 480000 | J9: =E9+I9 -> 6480000 | K9: =IF(ROW()=4,"Dr Beban Gaji / Cr PPh21, BPJS, Bank","")
A11: TOTAL | C11: =SUM(C4:C9) -> 25000000 | E11: =SUM(E4:E9) -> 27000000 | F11: =SUM(F4:F9) -> 0 | G11: =SUM(G4:G9) -> 0 | H11: =SUM(H4:H9) -> 27000000 | I11: =SUM(I4:I9) -> 2160000 | J11: =SUM(J4:J9) -> 29160000
A13: Jurnal payroll | B13: Debit Beban Gaji = Bruto | C13: Kredit Utang PPh21 = PPh21 | D13: Kredit Utang BPJS = BPJS pegawai | E13: Kredit Bank = Take Home Pay | F13: Jurnal pemberi kerja | G13: Debit Beban BPJS = BPJS employer | H13: Kredit Utang BPJS = BPJS employer

